Workbook

Sheet Plan1

Sheet BM MORRO DA CRUZ - VERTICAL
A1: APOIO PARA CRONOGRAMA FF | E1: BM - PLANILHA DE MEDIÇÃO - ORÇAMENTOS PARCIAIS | T1: CONTRATO: | V1: ANKARA | Z1: LEV.
T2: 10239 / | U2: 2026 | Z2: REDES
E3: OBRA: | R3: DATA BASE - ORÇAMENTO: | T3: ORIGINAL - P0 (CAESB) - PV | V3: CUSTO ANKARA P/ PROPOSTA - CUSTO LINEAR | X3: CUSTO ANKARA (ESTUDADO) - PS (REFERÊNCIA P/ COMPRAS) | Z3: PERÍODO:
E4: IMPLANTAÇÃO DE REDES DE DISTRIBUIÇÃO NO MORRO DA CRUZ, SÃO SEBASTIÃO/DF | R4: 01/2025 | Z4: REV01 - 13/10/2026
A5: SEQUÊNCIA | B5: CÓD. CRON. FF | C5: DESCRIÇÃO DO ORÇAMENTO | D5: ITEM - BM VERTICAL | E5: ITEM - BM | F5: DESCRIÇÃO | G5: PRESSÃO | H5: RESINA | I5: TIPO_CONEXÃO | J5: SOLDA | K5: DIÂMETRO | L5: MATERIAL | M5: GRUPO | N5: GRUPO ORÇAMENTO ANKARA | O5: CÓDIGO CAESB | P5: CLASSIFICAÇÃO | Q5: DESCRIÇÃO SUMÁRIA | R5: UNID. | S5: QUANT. | T5: VALOR UNITÁRIO | U5: TOTAL | V5: VALOR UNITÁRIO | W5: TOTAL | X5: VALOR UNITÁRIO | Y5: TOTAL | Z5: QUANT. | AA5: TOTAL
A6: 1 | C6: CANTEIRO DE OBRAS - MATERIAL + SERVIÇO | Q6: CANTEIRO DE OBRAS - MATERIAL + SERVIÇO | U6: =SUM(U7,U26,U68,U73,U76) -> 1166828
A7: 1 | E7: 1 | O7: 03 | Q7: MATERIAL | U7: =SUM(U8,U10,U12,U14,U16,U19,U21,U23) -> 81448.72
A8: 1 | E8: 1.1 | O8: 01730 | Q8: ADMINISTRAÇÃO LOCAL | U8: =SUM(U9:U9) -> 28416.96
A9: 1 | B9: 1.1 | C9: CANTEIRO - MATERIAL | D9: =B9&"_"&E9 -> 1.1_1.1.1 | E9: 1.1.1 | F9: RECURSOS MATERIAIS PARA ADMINISTRAÇÃO LOCAL | G9: N/A | H9: N/A | I9: N/A | J9: N/A | K9: N/A | L9: N/A | M9: CANTEIRO | N9: OUTROS | O9: 0173003001001 | P9: MATERIAL | Q9: RECURSOS MATERIAIS PARA ADMINISTRAÇÃO LOCAL (MATERIAIS DE CONSUMO, ÁGUA, ENERGIA ELÉTRICA E COMUNICAÇÃO) - TIPO 2 | R9: MES | S9: 18 | T9: 1578.72 | U9: =ROUND(T9*$S9,2) -> 28416.96
A10: 1 | E10: 1.2 | O10: 01741 | Q10: CONSERVAÇÃO E LIMPEZA | U10: =SUM(U11:U11) -> 16736.7
A11: 1 | B11: 1.1 | C11: CANTEIRO - MATERIAL | D11: =B11&"_"&E11 -> 1.1_1.2.2 | E11: 1.2.2 | F11: TAXA DISPOSIÇÃO FINAL RCC - SEGREGADOS | G11: N/A | H11: N/A | I11: N/A | J11: N/A | K11: N/A | L11: N/A | M11: CANTEIRO/REDES/CAIXAS/INTERLIGAÇÃO | N11: DESCARTE | O11: 0174103006002 | P11: MATERIAL | Q11: TAXA PARA DISPOSIÇÃO FINAL DE RESÍDUOS DA CONSTRUÇÃO CIVIL SEGREGADOS, CONFORME RESOLUÇÃO ADASA N° 45/2024, A PARTIR DE 01/01/2025. | R11: T | S11: 977.04 | T11: 17.13 | U11: =ROUND(T11*$S11,2) -> 16736.7
A12: 1 | E12: 1.6 | O12: 10180 | Q12: COBERTURAS | U12: =SUM(U13:U13) -> 5200
A13: 1 | B13: 1.1 | C13: CANTEIRO - MATERIAL | D13: =B13&"_"&E13 -> 1.1_1.6.1 | E13: 1.6.1 | F13: TENDA PIRAMIDAL 3,00 X 3,00 M COM FECHAMENTOS LATERAIS | G13: N/A | H13: N/A | I13: TENDA | J13: N/A | K13: 3,00X3,00 | L13: LONA PVC | M13: CANTEIRO | N13: CANTEIRO | O13: 1018003001001 | P13: MATERIAL | Q13: TENDA PIRAMIDAL 3,00 X 3,00 M COM FECHAMENTOS LATERAIS | R13: UN | S13: 2 | T13: 2600 | U13: =ROUND(T13*$S13,2) -> 5200
A14: 1 | E14: 1.7 | O14: 12510 | Q14: MÓVEIS PARA ESCRITÓRIO | U14: =SUM(U15:U15) -> 8892.18
A15: 1 | B15: 1.1 | C15: CANTEIRO - MATERIAL | D15: =B15&"_"&E15 -> 1.1_1.7.1 | E15: 1.7.1 | F15: INFRAESTRUTURA BÁSICA PARA FISCALIZAÇÃO | G15: N/A | H15: N/A | I15: N/A | J15: N/A | K15: N/A | L15: N/A | M15: CANTEIRO | N15: CANTEIRO | O15: 1251003008004 | P15: MATERIAL | Q15: INFRAESTRUTURA BÁSICA PARA FISCALIZAÇÃO INCLUINDO NO MÍNIMO OS ITENS A SEGUIR: MÓVEIS E EQUIPAMENTOS (DUAS MESAS, QUATRO CADEIRAS, UM PURIFICADOR DE ÁGUA, UM APARELHO DE AR CONDICIONADO 7500 BTUS, UM NOTEBOOK INTEL CORE I7, 12GB, SSD 256GB, TELA COM RESOLUÇÃO MÍNIMA 1920X1080P, WINDOWS 10 OU VERSÕES SUPERIORES, COM PACOTE MICROSOFT OFFICE 360 E ACESSO À INTERNET). | R15: MES | S15: 18 | T15: 494.01 | U15: =ROUND(T15*$S15,2) -> 8892.18
A16: 1 | E16: 1.11 | O16: 15120 | Q16: PRODUTOS ESPECIAIS PARA TUBULAÇÕES | U16: =SUM(U17:U18) -> 250.59
A17: 1 | B17: 1.1 | C17: CANTEIRO - MATERIAL | D17: =B17&"_"&E17 -> 1.1_1.11.1 | E17: 1.11.1 | F17: CAIXA DE PROTEÇÃO PARA 01 HIDRÔMETRO - PADRÃO CAESB | G17: N/A | H17: N/A | I17: CAIXA PROTEÇÃO | J17: N/A | K17: 50X40 | L17: PLÁSTICO | M17: CANTEIRO | N17: CX HIDRÔMETRO | O17: 1512003007001 | P17: MATERIAL | Q17: CAIXA DE PROTEÇÃO PARA 01 HIDRÔMETRO - PADRÃO CAESB | R17: UN | S17: 1 | T17: 129.9 | U17: =ROUND(T17*$S17,2) -> 129.9
A18: 1 | B18: 1.1 | C18: CANTEIRO - MATERIAL | D18: =B18&"_"&E18 -> 1.1_1.11.2 | E18: 1.11.2 | F18: HIDRÔMETRO UNIJATO COM CORPO EM COBRE | G18: N/A | H18: N/A | I18: HIDRÔMETRO | J18: N/A | K18: 3/4" | L18: COBRE | M18: CANTEIRO/LIGAÇÕES | N18: OUTROS | O18: 1512003001034 | P18: MATERIAL | Q18: HIDRÔMETRO UNIJATO COM CORPO EM COBRE (CLASSE: B / DIÂMETRO NOMINAL: 3/4" OU 20 MM / VAZÃO MÁXIMA: 1,5 M³/H / COMPRIMENTO: 115 MM) | R18: UN | S18: 1 | T18: 120.69 | U18: =ROUND(T18*$S18,2) -> 120.69
A19: 1 | E19: 1.13 | O19: 15143 | Q19: TUBOS E CONEXÕES DE PVC - ÁGUA FRIA (ROSCÁVEL) | U19: =SUM(U20:U20) -> 39.56
A20: 1 | B20: 1.1 | C20: CANTEIRO - MATERIAL | D20: =B20&"_"&E20 -> 1.1_1.13.1 | E20: 1.13.1 | F20: ADAPTADOR DE PVC BRANCO ROSCÁVEL COM ANEL PARA CAIXA D'ÁGUA | G20: N/A | H20: N/A | I20: ADAPTADOR | J20: N/A | K20: 1.1/2" | L20: PVC | M20: CANTEIRO | N20: OUTROS | O20: 1514303022006 | P20: MATERIAL | Q20: ADAPTADOR DE PVC BRANCO ROSCÁVEL COM ANEL PARA CAIXA D'ÁGUA (DIÂMETRO DA SEÇÃO: 1 1/2 ") | R20: UN | S20: 1 | T20: 39.56 | U20: =ROUND(T20*$S20,2) -> 39.56
A21: 1 | E21: 1.14 | O21: 15146 | Q21: TUBOS E CONEXÕES DE POLIETILENO DE ALTA DENSIDADE | U21: =SUM(U22:U22) -> 255.9
A22: 1 | B22: 1.1 | C22: CANTEIRO - MATERIAL | D22: =B22&"_"&E22 -> 1.1_1.14.77 | E22: 1.14.77 | F22: TUBO | G22: PN10 | H22: PE100 | I22: TUBO | J22: TERMOFUSÃO | K22: 63 | L22: PEAD | M22: CANTEIRO/HIDROMECÂNICO | N22: TUBO PEAD | O22: 1514603006037 | P22: MATERIAL | Q22: TUBO DE POLIETILENO DE ALTA DENSIDADE (CLASSE DE PRESSÃO: 10 KGF/CM² / DIÂMETRO EXTERNO NOMINAL: 63 MM / TIPO DE RESINA: PE100) | R22: M | S22: 15 | T22: 17.06 | U22: =ROUND(T22*$S22,2) -> 255.9
A23: 1 | E23: 1.18 | O23: 89001 | Q23: INSUMOS COMPLEMENTARES | U23: =SUM(U24:U25) -> 21656.83
A24: 1 | B24: 1.1 | C24: CANTEIRO - MATERIAL | D24: =B24&"_"&E24 -> 1.1_1.18.5 | E24: 1.18.5 | F24: FOSSA SÉPTICA SEM FILTRO - 15 A 30 CONTRIBUINTES | G24: N/A | H24: N/A | I24: FOSSA | J24: N/A | K24: 5500 | L24: PEAD | M24: CANTEIRO | N24: OUTROS | O24: 8900103001SI39363 | P24: MATERIAL | Q24: FOSSA SEPTICA, SEM FILTRO, EM POLIETILENO DE ALTA DENSIDADE (PEAD), PARA 15 A 30 CONTRIBUINTES, CILINDRICA, COM TAMPA, CAPACIDADE APROXIMADA DE *5500* LITROS (NBR 7229) | R24: UN | S24: 1 | T24: 6307.51 | U24: =ROUND(T24*$S24,2) -> 6307.51
A25: 1 | B25: 1.1 | C25: CANTEIRO - MATERIAL | D25: =B25&"_"&E25 -> 1.1_1.18.8 | E25: 1.18.8 | F25: PILAR QUADRADO NAO APARELHADO 20 X 20 CM | G25: N/A | H25: N/A | I25: PILAR | J25: N/A | K25: 20X20 | L25: MADEIRA | M25: CANTEIRO | N25: CANTEIRO | O25: 8900103001SI35276 | P25: MATERIAL | Q25: PILAR QUADRADO NAO APARELHADO *20 X 20* CM, EM MACARANDUBA/MASSARANDUBA, ANGELIM OU EQUIVALENTE DA REGIAO - BRUTA | R25: M | S25: 84 | T25: 182.73 | U25: =ROUND(T25*$S25,2) -> 15349.32
A26: 1 | E26: 5 | O26: 08 | Q26: SERVICOS COMPOSTOS - CONSTRUÇÃO EM GERAL | U26: =SUM(U27,U30,U37,U40,U42,U45,U50,U53,U57,U62,U66) -> 524433.87
A27: 1 | E27: 5.1 | O27: 80005 | Q27: CANTEIRO DE OBRAS | U27: =SUM(U28:U29) -> 72155.72
A28: 1 | B28: 1.2 | C28: CANTEIRO - SERVIÇO | D28: =B28&"_"&E28 -> 1.2_5.1.1 | E28: 5.1.1 | O28: 8000508010SI105115 | P28: SERVIÇO | Q28: INSTALAÇÃO E DESINSTALAÇÃO MECANIZADA DE CONTÊINER OU MÓDULO HABITÁVEL DE USOS DIVERSOS. AF_03/2024 | R28: UN | S28: 18 | T28: 130.92 | U28: =ROUND(T28*$S28,2) -> 2356.56
A29: 1 | B29: 1.2 | C29: CANTEIRO - SERVIÇO | D29: =B29&"_"&E29 -> 1.2_5.1.2 | E29: 5.1.2 | O29: 8000508010SI98459 | P29: SERVIÇO | Q29: TAPUME COM TELHA METÁLICA. AF_03/2024 | R29: M2 | S29: 772.2 | T29: 90.39 | U29: =ROUND(T29*$S29,2) -> 69799.16
A30: 1 | E30: 5.4 | O30: 80020 | Q30: MOVIMENTO DE TERRA | U30: =SUM(U31:U36) -> 102098.25
A31: 1 | B31: 1.2 | C31: CANTEIRO - SERVIÇO | D31: =B31&"_"&E31 -> 1.2_5.4.4 | E31: 5.4.4 | O31: 8002008099SI100983 | P31: SERVIÇO | Q31: CARGA, MANOBRA E DESCARGA DE ENTULHO EM CAMINHÃO BASCULANTE 14 M³ - CARGA COM ESCAVADEIRA HIDRÁULICA (CAÇAMBA DE 0,80 M³ / 111 HP) E DESCARGA LIVRE (UNIDADE: M3). AF_07/2020 | R31: M3 | S31: 697.88 | T31: 9.16 | U31: =ROUND(T31*$S31,2) -> 6392.58
A32: 1 | B32: 1.2 | C32: CANTEIRO - SERVIÇO | D32: =B32&"_"&E32 -> 1.2_5.4.6 | E32: 5.4.6 | O32: 8002008099SI100997 | P32: SERVIÇO | Q32: CARGA, MANOBRA E DESCARGA DE ENTULHO EM CAMINHÃO BASCULANTE 6 M³ - CARGA COM ESCAVADEIRA HIDRÁULICA (CAÇAMBA DE 0,80 M³ / 111 HP) E DESCARGA LIVRE (UNIDADE: T). AF_07/2020 | R32: T | S32: 3489.42 | T32: 6.35 | U32: =ROUND(T32*$S32,2) -> 22157.82
A33: 1 | B33: 1.2 | C33: CANTEIRO - SERVIÇO | D33: =B33&"_"&E33 -> 1.2_5.4.17 | E33: 5.4.17 | O33: 8002008050SI93382 | P33: SERVIÇO | Q33: REATERRO MANUAL DE VALAS, COM COMPACTADOR DE SOLOS DE PERCUSSÃO. AF_08/2023 | R33: M3 | S33: 6.45 | T33: 27.15 | U33: =ROUND(T33*$S33,2) -> 175.12
A34: 1 | B34: 1.2 | C34: CANTEIRO - SERVIÇO | D34: =B34&"_"&E34 -> 1.2_5.4.22 | E34: 5.4.22 | O34: 8002008099SI93593 | P34: SERVIÇO | Q34: TRANSPORTE COM CAMINHÃO BASCULANTE DE 14 M³, EM VIA URBANA PAVIMENTADA, ADICIONAL PARA DMT EXCEDENTE A 30 KM (UNIDADE: M3XKM). AF_07/2020 | R34: M3XKM | S34: 19122.02 | T34: 0.89 | U34: =ROUND(T34*$S34,2) -> 17018.6
A35: 1 | B35: 1.2 | C35: CANTEIRO - SERVIÇO | D35: =B35&"_"&E35 -> 1.2_5.4.23 | E35: 5.4.23 | O35: 8002008099SI95876 | P35: SERVIÇO | Q35: TRANSPORTE COM CAMINHÃO BASCULANTE DE 14 M³, EM VIA URBANA PAVIMENTADA, DMT ATÉ 30 KM (UNIDADE: M3XKM). AF_07/2020 | R35: M3XKM | S35: 20936.52 | T35: 2.19 | U35: =ROUND(T35*$S35,2) -> 45850.98
A36: 1 | B36: 1.2 | C36: CANTEIRO - SERVIÇO | D36: =B36&"_"&E36 -> 1.2_5.4.25 | E36: 5.4.25 | O36: 8002008099SI97914 | P36: SERVIÇO | Q36: TRANSPORTE COM CAMINHÃO BASCULANTE DE 6 M³, EM VIA URBANA PAVIMENTADA, DMT ATÉ 30 KM (UNIDADE: M3XKM). AF_07/2020 | R36: M3XKM | S36: 3489.42 | T36: 3.01 | U36: =ROUND(T36*$S36,2) -> 10503.15
A37: 1 | E37: 5.7 | O37: 80040 | Q37: FUNDAÇÕES E ESTRUTURAS | U37: =SUM(U38:U39) -> 181101.8
A38: 1 | B38: 1.2 | C38: CANTEIRO - SERVIÇO | D38: =B38&"_"&E38 -> 1.2_5.7.10 | E38: 5.7.10 | O38: 8004008028SI103075 | P38: SERVIÇO | Q38: EXECUÇÃO DE PISO DE CONCRETO, COM ACABAMENTO SUPERFICIAL, ESPESSURA DE 15 CM, FCK = 30 MPA, COM USO DE FORMAS EM MADEIRA SERRADA. AF_09/2021 | R38: M2 | S38: 640 | T38: 223.43 | U38: =ROUND(T38*$S38,2) -> 142995.2
A39: 1 | B39: 1.2 | C39: CANTEIRO - SERVIÇO | D39: =B39&"_"&E39 -> 1.2_5.7.14 | E39: 5.7.14 | O39: 8004008020SI96624 | P39: SERVIÇO | Q39: LASTRO COM MATERIAL GRANULAR (PEDRA BRITADA N.2), APLICADO EM PISOS OU LAJES SOBRE SOLO, ESPESSURA DE *10 CM*. AF_01/2024 | R39: M3 | S39: 126.6 | T39: 301 | U39: =ROUND(T39*$S39,2) -> 38106.6
A40: 1 | E40: 5.8 | O40: 80045 | Q40: ASSENTAMENTO | U40: =SUM(U41:U41) -> 11.7
...

Sheet REDE
A1: RASTREABILIDADE DE REDES - GERAL | BI1: CONTRATO: | BK1: DATA:
BI2: 10239/2026 | BK2: 46308
A3: OBRA: | BK3: ELAB. POR:
A4: IMPLANTAÇÃO DE REDES DE DISTRIBUIÇÃO NO MORRO DA CRUZ, SÃO SEBASTIÃO/DF | BK4: ANKARA ENGENHARIA
A5: ITEM | B5: GOOGLE LINK | C5: DESCRIÇÃO | D5: PRESSÃO | E5: RESINA | F5: TIPO_CONEXÃO | G5: SOLDA | H5: DIÂMETRO | I5: MATERIAL | J5: GRUPO | K5: LOCAL | L5: UNID. | M5: DISTÂNCIA | N5: METODOLOGIA | O5: ACABAMENTO | P5: FINALIDADE | Q5: CATEGORIA | R5: PONTO | S5: CLASSIFICAÇÃO EXECUTIVA | T5: Nº DESENHO | U5: PRANCHA | V5: REVISÃO | W5: DATA REVISÃO | X5: DELIMITIAÇÃO | Y5: CONJUNTO | Z5: LOTE | AA5: DIST. CANTEIRO | AB5: OBSERVAÇÕES | AC5: CÓDIGO BM | AD5: AGRUPAMENTO | AE5: RECOB. | AF5: PROF. | AG5: LARG. | AH5: LASTRO | AI5: VOL. TUBO | AJ5: (H)-ENVOLTÓRIA | AK5: DIST. BOTA FORA | AL5: LOCAÇÃO C/ NOTA | AM5: CADASTRO | AN5: FURO SOND. | AO5: TAPUME DESC. MÓVEL | AP5: VOL. TOTAL ESC. | AQ5: LASTRO2 | AR5: ATERRO AREIA | AS5: REATERRO | AT5: ESCAV. EXT. ROCHA | AU5: ESCAV. MAN. 1ª CAT. <1,50 | AV5: ESCAV. MAN. 1ª CAT. >1,50<3,00 | AW5: ESCAV. MEC. 1ª CAT. <1,50 | AX5: ESCAV. MEC. 1ª CAT. >1,50<3,00 | AY5: ESCAV. MEC. 2ª CAT. <1,50 | AZ5: ESCAV. MEC. 2ª CAT. >1,50<3,00 | BA5: ESGOT. VALA | BB5: CARGA | BC5: CARGA DE ROCHA | BD5: ESC. PONTALETE >=1,25 M <1,5 M | BE5: ESC. DESCONTÍNUO >=1,5 M <3,0 M | BF5: ESC. CONTÍNUO MISTO >=3,0 M | BG5: TRANSPORTE A GRANEL | BH5: PLACA SINALIZAÇÃO | BI5: SINALIZAÇÃO NOTURNA | BJ5: PASSADIÇO - CHAPA DE AÇO (VEÍCULOS) | BK5: PASSADIÇO - TÁBUAS (PEDESTRE) | BL5: APOIO AGRUPAMENTO BLOCO | BM5: EQUIPE | BN5: TIPO | BO5: PB | BP5: NÓ INICIAL | BQ5: NÓ FINAL | BR5: HANDLE CAD | BS5: COORD. E (UTM) INÍCIO | BT5: COORD. N (UTM) INÍCIO | BU5: COORD. E (UTM) FIM | BV5: COORD. N (UTM) FIM | BW5: LATITUDE (MEIO) | BX5: LONGITUDE (MEIO) | BY5: ROTA - PONTO DE REFERÊNCIA
A6: =IF(C6<>"",ROW(A1),"") -> 1 | B6: =HYPERLINK("https://www.google.com/maps/dir/-15.917302,-47.760003/-15.9087023,-47.7685795/data=!4m3!4m2!3e0!5i0") -> https://www.google.com/maps/dir/-15.917302,-47.760003/-15.9087023,-47.7685795/data=!4m3!4m2!3e0!5i0 | C6: TUBO PEAD | D6: PN10 | E6: PE100 | F6: TUBO PEAD | G6: ELETROFUSÃO | H6: 63 | I6: PEAD | J6: REDES | K6: Zona01 | L6: M | M6: =76.55 -> 76.55 | N6: VCA | O6: VIA | P6: REDE | Q6: LINEAR | R6: Zona01_PB01_Rede_TR001 | S6: TERCIÁRIA | T6: A.RED.SSB-D014.V03.T01.002/037 | U6: =RIGHT(T6,7) -> 002/037 | V6: REVISÃO 08 | W6: 45882 | X6: ST BAIRRO RESID VITÓRIA | Z6: S/DEFINIÇÃO | AA6: 1.6 | AB6: TRECHO DE Zona01_PB01_Rede_NÓ1.8 A Zona01_PB01_Rede_NÓ2.7 | AC6: 5.8.44 | AD6: =CONCATENATE($C6,$I6,$H6,$N6,$J6,$K6) -> TUBO PEADPEAD63VCAREDESZona01 | AE6: =IFERROR(INDEX(APOIO_REDES!$A:$W,MATCH($C6&$I6&$H6&$N6&$O6,APOIO_REDES!$W:$W,0),MATCH(AE$5,APOIO_REDES!$5:$5,0)),0) -> 1.2 | AF6: =IFERROR(INDEX(APOIO_REDES!$A:$W,MATCH($C6&$I6&$H6&$N6&$O6,APOIO_REDES!$W:$W,0),MATCH(AF$5,APOIO_REDES!$5:$5,0)),0) -> 1.363 | AG6: =IFERROR(INDEX(APOIO_REDES!$A:$W,MATCH($C6&$I6&$H6&$N6&$O6,APOIO_REDES!$W:$W,0),MATCH(AG$5,APOIO_REDES!$5:$5,0)),0) -> 0.65 | AH6: =IFERROR(INDEX(APOIO_REDES!$A:$W,MATCH($C6&$I6&$H6&$N6&$O6,APOIO_REDES!$W:$W,0),MATCH(AH$5,APOIO_REDES!$5:$5,0)),0) -> 0.1 | AI6: =IFERROR(IF($H6<>"",(((($H6/1000)/2)^2)*PI()*$M6),0),0) -> 0.23862513 | AJ6: =IFERROR(IF(AND($H6<>"",$I6="FoFo",OR($N6="MND",$N6="VCA"),$Q6="LINEAR"),0,IF(AND($H6<>"",$I6="PEAD",$N6="VCA",$Q6="LINEAR"),($H6/1000)+0.3,IF(AND($H6<>"",$I6="PEAD",$N6="MND",$Q6="EMBOQUE"),0,IF(AND($H6<>"",$I6="PVC",$N6="VCA",$Q6="LINEAR"),($H6/1000)+0.2,IF(AND($H6<>"",$I6="PVC",$N6="MND",$Q6="EMBOQUE"),0,IF(AND($H6<>"",$I6="PEAD",$N6="VCA",$Q6="PREDIAL"),0,0)))))),0) -> 0.363 | AK6: =IF(AA6<>"",AA6,0) -> 1.6 | AL6: =IF(AND($N6="MND",$Q6="EMBOQUE"),$M6,IF(AND($N6="VCA",$Q6="LINEAR"),$M6,IF(AND($N6="VCA",$Q6="PREDIAL"),0,0))) -> 76.55 | AM6: =IF(AND($N6="MND",$Q6="EMBOQUE"),$M6,IF(AND($N6="VCA",$Q6="LINEAR"),$M6,IF(AND($N6="VCA",$Q6="PREDIAL"),0,0))) -> 76.55 | AN6: =ROUND(IF(AND($N6="VCA",$M6<>"",$Q6="LINEAR"),$M6/100,IF(AND($N6="MND",$M6>100,$Q6="EMBOQUE"),$M6/100,0)),0) -> 1 | AO6: =IF(AND($N6="MND",$Q6="EMBOQUE"),$AN6*2*2,IF(AND($N6="VCA",$Q6="LINEAR"),$M6*2,IF(AND($N6="VCA",$Q6="PREDIAL"),0,0))) -> 153.1 | AP6: =IFERROR($M6*$AF6*$AG6,0) -> 67.819473 | AQ6: =IFERROR(IF(AND($N6="VCA",$AH6>0),$M6*$AG6*$AH6,0),0) -> 4.97575 | AR6: =IFERROR(IF(AND($N6="VCA",$AJ6>0),($M6*$AG6*$AJ6)-$AI6,0),0) -> 17.823347 | AS6: =IFERROR(IF(AND($N6="VCA",$AP6>0),$AP6-$AI6-$AQ6-$AR6,0),0) -> 44.78175 | AT6: =IFERROR(IF($N6="VCA",INDEX(APOIO_REDES!$A:$W,MATCH($C6&$I6&$H6&$N6&$O6,APOIO_REDES!$W:$W,0),MATCH(AT$5,APOIO_REDES!$5:$5,0)),0)*$AP6,0) -> 0.73789593 | AU6: =IFERROR(IF($N6="VCA",INDEX(APOIO_REDES!$A:$W,MATCH($C6&$I6&$H6&$N6&$O6,APOIO_REDES!$W:$W,0),MATCH(AU$5,APOIO_REDES!$5:$5,0)),0)*$AP6,0) -> 0.58926371 | AV6: =IFERROR(IF($N6="VCA",INDEX(APOIO_REDES!$A:$W,MATCH($C6&$I6&$H6&$N6&$O6,APOIO_REDES!$W:$W,0),MATCH(AV$5,APOIO_REDES!$5:$5,0)),0)*$AP6,0) -> 0.081549471 | AW6: =IFERROR(IF($N6="VCA",INDEX(APOIO_REDES!$A:$W,MATCH($C6&$I6&$H6&$N6&$O6,APOIO_REDES!$W:$W,0),MATCH(AW$5,APOIO_REDES!$5:$5,0)),0)*$AP6,0) -> 46.551811 | AX6: =IFERROR(IF($N6="VCA",INDEX(APOIO_REDES!$A:$W,MATCH($C6&$I6&$H6&$N6&$O6,APOIO_REDES!$W:$W,0),MATCH(AX$5,APOIO_REDES!$5:$5,0)),0)*$AP6,0) -> 6.4426381 | AY6: =IFERROR(IF($N6="VCA",INDEX(APOIO_REDES!$A:$W,MATCH($C6&$I6&$H6&$N6&$O6,APOIO_REDES!$W:$W,0),MATCH(AY$5,APOIO_REDES!$5:$5,0)),0)*$AP6,0) -> 11.785267 | AZ6: =IFERROR(IF($N6="VCA",INDEX(APOIO_REDES!$A:$W,MATCH($C6&$I6&$H6&$N6&$O6,APOIO_REDES!$W:$W,0),MATCH(AZ$5,APOIO_REDES!$5:$5,0)),0)*$AP6,0) -> 1.6310469 | BA6: =IFERROR(IF(AND($N6="VCA",$Q6="LINEAR"),INDEX(APOIO_REDES!$A:$W,MATCH($C6&$I6&$H6&$N6&$O6,APOIO_REDES!$W:$W,0),MATCH(BA$5,APOIO_REDES!$5:$5,0)),IF(AND($N6="MND",$Q6="EMBOQUE"),INDEX(APOIO_REDES!$A:$W,MATCH($C6&$I6&$H6&$N6&$O6,APOIO_REDES!$W:$W,0),MATCH(BA$5,APOIO_REDES!$5:$5,0)),0))*$M6/10,0) -> 6.1697369 | BB6: =IFERROR(IF($N6="VCA",INDEX(APOIO_REDES!$A:$W,MATCH($C6&$I6&$H6&$N6&$O6,APOIO_REDES!$W:$W,0),MATCH(BB$5,APOIO_REDES!$5:$5,0)),0)*($AI6+$AQ6+$AR6),0) -> 22.787065 | BC6: =IFERROR(IF($N6="VCA",INDEX(APOIO_REDES!$A:$W,MATCH($C6&$I6&$H6&$N6&$O6,APOIO_REDES!$W:$W,0),MATCH(BC$5,APOIO_REDES!$5:$5,0)),0)*($AI6+$AQ6+$AR6),0) -> 0.25065724 | BD6: =IF(AND($N6="VCA",$AF6>=1.25,$AF6<1.5),$M6*$AF6*2,0) -> 208.6753 | BE6: =IF(AND($N6="VCA",$AF6>=1.5,$AF6<3),$M6*$AF6*2,0) -> 0 | BF6: =IF(AND($N6="VCA",$AF6>=3),$M6*$AF6*2,0) -> 0 | BG6: =($BB6+$BC6)*$AK6 -> 36.860356 | BH6: =IF(AND($M6<>"",$N6="VCA",$Q6="LINEAR"),($M6*2)/100,IF(AND($M6<>"",$N6="MND",$Q6="EMBOQUE"),($AN6*2)/100,0)) -> 1.531 | BI6: =IF(AND($M6<>"",$N6="VCA",$Q6="LINEAR"),$M6,IF(AND($M6<>"",$N6="MND",$Q6="EMBOQUE"),$AN6*2,0)) -> 76.55 | BJ6: =IF(AND($M6<>"",$N6="VCA",$Q6="LINEAR"),($M6*6.8)/100,IF(AND($M6<>"",$N6="MND",$Q6="EMBOQUE"),($AN6*2*6.8)/100,0)) -> 5.2054 | BK6: =IF(AND($M6<>"",$N6="VCA",$Q6="LINEAR"),($M6*2.5)/50,IF(AND($M6<>"",$N6="MND",$Q6="EMBOQUE"),($AN6*2*2.5)/50,0)) -> 3.8275 | BL6: =K6&J6 -> Zona01REDES | BM6: EQUIPE ZONA 01 | BN6: Rede | BO6: PB01 | BP6: Zona01_PB01_Rede_NÓ1.8 | BQ6: Zona01_PB01_Rede_NÓ2.7 | BR6: 5FD12 | BS6: 203552.49 | BT6: 8239199.1 | BU6: 203492.05 | BV6: 8239246.1 | BW6: -15.908486 | BX6: -47.768858 | BY6: Zona01_PB01_Rede_NÓ1.8
A7: =IF(C7<>"",ROW(A2),"") -> 2 | B7: =HYPERLINK("https://www.google.com/maps/dir/-15.917302,-47.760003/-15.9082709,-47.7691377/data=!4m3!4m2!3e0!5i0") -> https://www.google.com/maps/dir/-15.917302,-47.760003/-15.9082709,-47.7691377/data=!4m3!4m2!3e0!5i0 | C7: TUBO PEAD | D7: PN10 | E7: PE100 | F7: TUBO PEAD | G7: ELETROFUSÃO | H7: 63 | I7: PEAD | J7: REDES | K7: Zona01 | L7: M | M7: =75.07 -> 75.07 | N7: VCA | O7: VIA | P7: REDE | Q7: LINEAR | R7: Zona01_PB01_Rede_TR002 | S7: TERCIÁRIA | T7: A.RED.SSB-D014.V03.T01.002/037 | U7: =RIGHT(T7,7) -> 002/037 | V7: REVISÃO 08 | W7: 45882 | X7: ST BAIRRO RESID VITÓRIA | Z7: S/DEFINIÇÃO | AA7: 1.7 | AB7: TRECHO DE Zona01_PB01_Rede_NÓ2.7 A Zona01_PB01_Rede_DF-33 | AC7: 5.8.44 | AD7: =CONCATENATE($C7,$I7,$H7,$N7,$J7,$K7) -> TUBO PEADPEAD63VCAREDESZona01 | AE7: =IFERROR(INDEX(APOIO_REDES!$A:$W,MATCH($C7&$I7&$H7&$N7&$O7,APOIO_REDES!$W:$W,0),MATCH(AE$5,APOIO_REDES!$5:$5,0)),0) -> 1.2 | AF7: =IFERROR(INDEX(APOIO_REDES!$A:$W,MATCH($C7&$I7&$H7&$N7&$O7,APOIO_REDES!$W:$W,0),MATCH(AF$5,APOIO_REDES!$5:$5,0)),0) -> 1.363 | AG7: =IFERROR(INDEX(APOIO_REDES!$A:$W,MATCH($C7&$I7&$H7&$N7&$O7,APOIO_REDES!$W:$W,0),MATCH(AG$5,APOIO_REDES!$5:$5,0)),0) -> 0.65 | AH7: =IFERROR(INDEX(APOIO_REDES!$A:$W,MATCH($C7&$I7&$H7&$N7&$O7,APOIO_REDES!$W:$W,0),MATCH(AH$5,APOIO_REDES!$5:$5,0)),0) -> 0.1 | AI7: =IFERROR(IF($H7<>"",(((($H7/1000)/2)^2)*PI()*$M7),0),0) -> 0.23401161 | AJ7: =IFERROR(IF(AND($H7<>"",$I7="FoFo",OR($N7="MND",$N7="VCA"),$Q7="LINEAR"),0,IF(AND($H7<>"",$I7="PEAD",$N7="VCA",$Q7="LINEAR"),($H7/1000)+0.3,IF(AND($H7<>"",$I7="PEAD",$N7="MND",$Q7="EMBOQUE"),0,IF(AND($H7<>"",$I7="PVC",$N7="VCA",$Q7="LINEAR"),($H7/1000)+0.2,IF(AND($H7<>"",$I7="PVC",$N7="MND",$Q7="EMBOQUE"),0,IF(AND($H7<>"",$I7="PEAD",$N7="VCA",$Q7="PREDIAL"),0,0)))))),0) -> 0.363 | AK7: =IF(AA7<>"",AA7,0) -> 1.7 | AL7: =IF(AND($N7="MND",$Q7="EMBOQUE"),$M7,IF(AND($N7="VCA",$Q7="LINEAR"),$M7,IF(AND($N7="VCA",$Q7="PREDIAL"),0,0))) -> 75.07 | AM7: =IF(AND($N7="MND",$Q7="EMBOQUE"),$M7,IF(AND($N7="VCA",$Q7="LINEAR"),$M7,IF(AND($N7="VCA",$Q7="PREDIAL"),0,0))) -> 75.07 | AN7: =ROUND(IF(AND($N7="VCA",$M7<>"",$Q7="LINEAR"),$M7/100,IF(AND($N7="MND",$M7>100,$Q7="EMBOQUE"),$M7/100,0)),0) -> 1 | AO7: =IF(AND($N7="MND",$Q7="EMBOQUE"),$AN7*2*2,IF(AND($N7="VCA",$Q7="LINEAR"),$M7*2,IF(AND($N7="VCA",$Q7="PREDIAL"),0,0))) -> 150.14 | AP7: =IFERROR($M7*$AF7*$AG7,0) -> 66.508267 | AQ7: =IFERROR(IF(AND($N7="VCA",$AH7>0),$M7*$AG7*$AH7,0),0) -> 4.87955 | AR7: =IFERROR(IF(AND($N7="VCA",$AJ7>0),($M7*$AG7*$AJ7)-$AI7,0),0) -> 17.478755 | AS7: =IFERROR(IF(AND($N7="VCA",$AP7>0),$AP7-$AI7-$AQ7-$AR7,0),0) -> 43.91595 | AT7: =IFERROR(IF($N7="VCA",INDEX(APOIO_REDES!$A:$W,MATCH($C7&$I7&$H7&$N7&$O7,APOIO_REDES!$W:$W,0),MATCH(AT$5,APOIO_REDES!$5:$5,0)),0)*$AP7,0) -> 0.72362962 | AU7: =IFERROR(IF($N7="VCA",INDEX(APOIO_REDES!$A:$W,MATCH($C7&$I7&$H7&$N7&$O7,APOIO_REDES!$W:$W,0),MATCH(AU$5,APOIO_REDES!$5:$5,0)),0)*$AP7,0) -> 0.57787102 | AV7: =IFERROR(IF($N7="VCA",INDEX(APOIO_REDES!$A:$W,MATCH($C7&$I7&$H7&$N7&$O7,APOIO_REDES!$W:$W,0),MATCH(AV$5,APOIO_REDES!$5:$5,0)),0)*$AP7,0) -> 0.079972813 | AW7: =IFERROR(IF($N7="VCA",INDEX(APOIO_REDES!$A:$W,MATCH($C7&$I7&$H7&$N7&$O7,APOIO_REDES!$W:$W,0),MATCH(AW$5,APOIO_REDES!$5:$5,0)),0)*$AP7,0) -> 45.651789 | AX7: =IFERROR(IF($N7="VCA",INDEX(APOIO_REDES!$A:$W,MATCH($C7&$I7&$H7&$N7&$O7,APOIO_REDES!$W:$W,0),MATCH(AX$5,APOIO_REDES!$5:$5,0)),0)*$AP7,0) -> 6.3180776 | AY7: =IFERROR(IF($N7="VCA",INDEX(APOIO_REDES!$A:$W,MATCH($C7&$I7&$H7&$N7&$O7,APOIO_REDES!$W:$W,0),MATCH(AY$5,APOIO_REDES!$5:$5,0)),0)*$AP7,0) -> 11.557413 | AZ7: =IFERROR(IF($N7="VCA",INDEX(APOIO_REDES!$A:$W,MATCH($C7&$I7&$H7&$N7&$O7,APOIO_REDES!$W:$W,0),MATCH(AZ$5,APOIO_REDES!$5:$5,0)),0)*$AP7,0) -> 1.5995126 | BA7: =IFERROR(IF(AND($N7="VCA",$Q7="LINEAR"),INDEX(APOIO_REDES!$A:$W,MATCH($C7&$I7&$H7&$N7&$O7,APOIO_REDES!$W:$W,0),MATCH(BA$5,APOIO_REDES!$5:$5,0)),IF(AND($N7="MND",$Q7="EMBOQUE"),INDEX(APOIO_REDES!$A:$W,MATCH($C7&$I7&$H7&$N7&$O7,APOIO_REDES!$W:$W,0),MATCH(BA$5,APOIO_REDES!$5:$5,0)),0))*$M7/10,0) -> 6.0504526 | BB7: =IFERROR(IF($N7="VCA",INDEX(APOIO_REDES!$A:$W,MATCH($C7&$I7&$H7&$N7&$O7,APOIO_REDES!$W:$W,0),MATCH(BB$5,APOIO_REDES!$5:$5,0)),0)*($AI7+$AQ7+$AR7),0) -> 22.346505 | BC7: =IFERROR(IF($N7="VCA",INDEX(APOIO_REDES!$A:$W,MATCH($C7&$I7&$H7&$N7&$O7,APOIO_REDES!$W:$W,0),MATCH(BC$5,APOIO_REDES!$5:$5,0)),0)*($AI7+$AQ7+$AR7),0) -> 0.24581109 | BD7: =IF(AND($N7="VCA",$AF7>=1.25,$AF7<1.5),$M7*$AF7*2,0) -> 204.64082 | BE7: =IF(AND($N7="VCA",$AF7>=1.5,$AF7<3),$M7*$AF7*2,0) -> 0 | BF7: =IF(AND($N7="VCA",$AF7>=3),$M7*$AF7*2,0) -> 0 | BG7: =($BB7+$BC7)*$AK7 -> 38.406938 | BH7: =IF(AND($M7<>"",$N7="VCA",$Q7="LINEAR"),($M7*2)/100,IF(AND($M7<>"",$N7="MND",$Q7="EMBOQUE"),($AN7*2)/100,0)) -> 1.5014 | BI7: =IF(AND($M7<>"",$N7="VCA",$Q7="LINEAR"),$M7,IF(AND($M7<>"",$N7="MND",$Q7="EMBOQUE"),$AN7*2,0)) -> 75.07 | BJ7: =IF(AND($M7<>"",$N7="VCA",$Q7="LINEAR"),($M7*6.8)/100,IF(AND($M7<>"",$N7="MND",$Q7="EMBOQUE"),($AN7*2*6.8)/100,0)) -> 5.10476 | BK7: =IF(AND($M7<>"",$N7="VCA",$Q7="LINEAR"),($M7*2.5)/50,IF(AND($M7<>"",$N7="MND",$Q7="EMBOQUE"),($AN7*2*2.5)/50,0)) -> 3.7535 | BL7: =K7&J7 -> Zona01REDES | BM7: EQUIPE ZONA 01 | BN7: Rede | BO7: PB01 | BP7: Zona01_PB01_Rede_NÓ2.7 | BQ7: Zona01_PB01_Rede_DF-33 | BR7: 5FD12 | BS7: 203492.05 | BT7: 8239246.1 | BU7: 203438.2 | BV7: 8239193.8 | BW7: -15.908504 | BX7: -47.769392 | BY7: Zona01_PB01_Rede_NÓ2.7
A8: =IF(C8<>"",ROW(A3),"") -> 3 | B8: =HYPERLINK("https://www.google.com/maps/dir/-15.917302,-47.760003/-15.9087206,-47.7685562/data=!4m3!4m2!3e0!5i0") -> https://www.google.com/maps/dir/-15.917302,-47.760003/-15.9087206,-47.7685562/data=!4m3!4m2!3e0!5i0 | C8: TUBO PEAD | D8: PN10 | E8: PE100 | F8: TUBO PEAD | G8: ELETROFUSÃO | H8: 63 | I8: PEAD | J8: REDES | K8: Zona01 | L8: M | M8: =3.22 -> 3.22 | N8: VCA | O8: VIA | P8: REDE | Q8: LINEAR | R8: Zona01_PB01_Rede_TR003 | S8: TERCIÁRIA | T8: A.RED.SSB-D014.V03.T01.002/037 | U8: =RIGHT(T8,7) -> 002/037 | V8: REVISÃO 08 | W8: 45882 | X8: ST BAIRRO RESID VITÓRIA | Z8: S/DEFINIÇÃO | AA8: 1.6 | AB8: TRECHO DE Zona01_PB01_Rede_NÓ1.9 A Zona01_PB01_Rede_NÓ1.8 | AC8: 5.8.44 | AD8: =CONCATENATE($C8,$I8,$H8,$N8,$J8,$K8) -> TUBO PEADPEAD63VCAREDESZona01 | AE8: =IFERROR(INDEX(APOIO_REDES!$A:$W,MATCH($C8&$I8&$H8&$N8&$O8,APOIO_REDES!$W:$W,0),MATCH(AE$5,APOIO_REDES!$5:$5,0)),0) -> 1.2 | AF8: =IFERROR(INDEX(APOIO_REDES!$A:$W,MATCH($C8&$I8&$H8&$N8&$O8,APOIO_REDES!$W:$W,0),MATCH(AF$5,APOIO_REDES!$5:$5,0)),0) -> 1.363 | AG8: =IFERROR(INDEX(APOIO_REDES!$A:$W,MATCH($C8&$I8&$H8&$N8&$O8,APOIO_REDES!$W:$W,0),MATCH(AG$5,APOIO_REDES!$5:$5,0)),0) -> 0.65 | AH8: =IFERROR(INDEX(APOIO_REDES!$A:$W,MATCH($C8&$I8&$H8&$N8&$O8,APOIO_REDES!$W:$W,0),MATCH(AH$5,APOIO_REDES!$5:$5,0)),0) -> 0.1 | AI8: =IFERROR(IF($H8<>"",(((($H8/1000)/2)^2)*PI()*$M8),0),0) -> 0.01003753 | AJ8: =IFERROR(IF(AND($H8<>"",$I8="FoFo",OR($N8="MND",$N8="VCA"),$Q8="LINEAR"),0,IF(AND($H8<>"",$I8="PEAD",$N8="VCA",$Q8="LINEAR"),($H8/1000)+0.3,IF(AND($H8<>"",$I8="PEAD",$N8="MND",$Q8="EMBOQUE"),0,IF(AND($H8<>"",$I8="PVC",$N8="VCA",$Q8="LINEAR"),($H8/1000)+0.2,IF(AND($H8<>"",$I8="PVC",$N8="MND",$Q8="EMBOQUE"),0,IF(AND($H8<>"",$I8="PEAD",$N8="VCA",$Q8="PREDIAL"),0,0)))))),0) -> 0.363 | AK8: =IF(AA8<>"",AA8,0) -> 1.6 | AL8: =IF(AND($N8="MND",$Q8="EMBOQUE"),$M8,IF(AND($N8="VCA",$Q8="LINEAR"),$M8,IF(AND($N8="VCA",$Q8="PREDIAL"),0,0))) -> 3.22 | AM8: =IF(AND($N8="MND",$Q8="EMBOQUE"),$M8,IF(AND($N8="VCA",$Q8="LINEAR"),$M8,IF(AND($N8="VCA",$Q8="PREDIAL"),0,0))) -> 3.22 | AN8: =ROUND(IF(AND($N8="VCA",$M8<>"",$Q8="LINEAR"),$M8/100,IF(AND($N8="MND",$M8>100,$Q8="EMBOQUE"),$M8/100,0)),0) -> 0 | AO8: =IF(AND($N8="MND",$Q8="EMBOQUE"),$AN8*2*2,IF(AND($N8="VCA",$Q8="LINEAR"),$M8*2,IF(AND($N8="VCA",$Q8="PREDIAL"),0,0))) -> 6.44 | AP8: =IFERROR($M8*$AF8*$AG8,0) -> 2.852759 | AQ8: =IFERROR(IF(AND($N8="VCA",$AH8>0),$M8*$AG8*$AH8,0),0) -> 0.2093 | AR8: =IFERROR(IF(AND($N8="VCA",$AJ8>0),($M8*$AG8*$AJ8)-$AI8,0),0) -> 0.74972147 | AS8: =IFERROR(IF(AND($N8="VCA",$AP8>0),$AP8-$AI8-$AQ8-$AR8,0),0) -> 1.8837 | AT8: =IFERROR(IF($N8="VCA",INDEX(APOIO_REDES!$A:$W,MATCH($C8&$I8&$H8&$N8&$O8,APOIO_REDES!$W:$W,0),MATCH(AT$5,APOIO_REDES!$5:$5,0)),0)*$AP8,0) -> 0.031038862 | AU8: =IFERROR(IF($N8="VCA",INDEX(APOIO_REDES!$A:$W,MATCH($C8&$I8&$H8&$N8&$O8,APOIO_REDES!$W:$W,0),MATCH(AU$5,APOIO_REDES!$5:$5,0)),0)*$AP8,0) -> 0.024786795 | AV8: =IFERROR(IF($N8="VCA",INDEX(APOIO_REDES!$A:$W,MATCH($C8&$I8&$H8&$N8&$O8,APOIO_REDES!$W:$W,0),MATCH(AV$5,APOIO_REDES!$5:$5,0)),0)*$AP8,0) -> 0.0034302978 | AW8: =IFERROR(IF($N8="VCA",INDEX(APOIO_REDES!$A:$W,MATCH($C8&$I8&$H8&$N8&$O8,APOIO_REDES!$W:$W,0),MATCH(AW$5,APOIO_REDES!$5:$5,0)),0)*$AP8,0) -> 1.9581559 | AX8: =IFERROR(IF($N8="VCA",INDEX(APOIO_REDES!$A:$W,MATCH($C8&$I8&$H8&$N8&$O8,APOIO_REDES!$W:$W,0),MATCH(AX$5,APOIO_REDES!$5:$5,0)),0)*$AP8,0) -> 0.2710032 | AY8: =IFERROR(IF($N8="VCA",INDEX(APOIO_REDES!$A:$W,MATCH($C8&$I8&$H8&$N8&$O8,APOIO_REDES!$W:$W,0),MATCH(AY$5,APOIO_REDES!$5:$5,0)),0)*$AP8,0) -> 0.49573559 | AZ8: =IFERROR(IF($N8="VCA",INDEX(APOIO_REDES!$A:$W,MATCH($C8&$I8&$H8&$N8&$O8,APOIO_REDES!$W:$W,0),MATCH(AZ$5,APOIO_REDES!$5:$5,0)),0)*$AP8,0) -> 0.068608373 | BA8: =IFERROR(IF(AND($N8="VCA",$Q8="LINEAR"),INDEX(APOIO_REDES!$A:$W,MATCH($C8&$I8&$H8&$N8&$O8,APOIO_REDES!$W:$W,0),MATCH(BA$5,APOIO_REDES!$5:$5,0)),IF(AND($N8="MND",$Q8="EMBOQUE"),INDEX(APOIO_REDES!$A:$W,MATCH($C8&$I8&$H8&$N8&$O8,APOIO_REDES!$W:$W,0),MATCH(BA$5,APOIO_REDES!$5:$5,0)),0))*$M8/10,0) -> 0.25952388 | BB8: =IFERROR(IF($N8="VCA",INDEX(APOIO_REDES!$A:$W,MATCH($C8&$I8&$H8&$N8&$O8,APOIO_REDES!$W:$W,0),MATCH(BB$5,APOIO_REDES!$5:$5,0)),0)*($AI8+$AQ8+$AR8),0) -> 0.95851535 | BC8: =IFERROR(IF($N8="VCA",INDEX(APOIO_REDES!$A:$W,MATCH($C8&$I8&$H8&$N8&$O8,APOIO_REDES!$W:$W,0),MATCH(BC$5,APOIO_REDES!$5:$5,0)),0)*($AI8+$AQ8+$AR8),0) -> 0.010543649 | BD8: =IF(AND($N8="VCA",$AF8>=1.25,$AF8<1.5),$M8*$AF8*2,0) -> 8.77772 | BE8: =IF(AND($N8="VCA",$AF8>=1.5,$AF8<3),$M8*$AF8*2,0) -> 0 | BF8: =IF(AND($N8="VCA",$AF8>=3),$M8*$AF8*2,0) -> 0 | BG8: =($BB8+$BC8)*$AK8 -> 1.5504944 | BH8: =IF(AND($M8<>"",$N8="VCA",$Q8="LINEAR"),($M8*2)/100,IF(AND($M8<>"",$N8="MND",$Q8="EMBOQUE"),($AN8*2)/100,0)) -> 0.0644 | BI8: =IF(AND($M8<>"",$N8="VCA",$Q8="LINEAR"),$M8,IF(AND($M8<>"",$N8="MND",$Q8="EMBOQUE"),$AN8*2,0)) -> 3.22 | BJ8: =IF(AND($M8<>"",$N8="VCA",$Q8="LINEAR"),($M8*6.8)/100,IF(AND($M8<>"",$N8="MND",$Q8="EMBOQUE"),($AN8*2*6.8)/100,0)) -> 0.21896 | BK8: =IF(AND($M8<>"",$N8="VCA",$Q8="LINEAR"),($M8*2.5)/50,IF(AND($M8<>"",$N8="MND",$Q8="EMBOQUE"),($AN8*2*2.5)/50,0)) -> 0.161 | BL8: =K8&J8 -> Zona01REDES | BM8: EQUIPE ZONA 01 | BN8: Rede | BO8: PB01 | BP8: Zona01_PB01_Rede_NÓ1.9 | BQ8: Zona01_PB01_Rede_NÓ1.8 | BR8: 5FD12 | BS8: 203555.02 | BT8: 8239197.1 | BU8: 203552.49 | BV8: 8239199.1 | BW8: -15.908712 | BX8: -47.768568 | BY8: Zona01_PB01_Rede_NÓ1.9
A9: =IF(C9<>"",ROW(A4),"") -> 4 | B9: =HYPERLINK("https://www.google.com/maps/dir/-15.917302,-47.760003/-15.9088783,-47.7683558/data=!4m3!4m2!3e0!5i0") -> https://www.google.com/maps/dir/-15.917302,-47.760003/-15.9088783,-47.7683558/data=!4m3!4m2!3e0!5i0 | C9: TUBO PEAD | D9: PN10 | E9: PE100 | F9: TUBO PEAD | G9: ELETROFUSÃO | H9: 63 | I9: PEAD | J9: REDES | K9: Zona01 | L9: M | M9: =27.68 -> 27.68 | N9: VCA | O9: VIA | P9: REDE | Q9: LINEAR | R9: Zona01_PB01_Rede_TR004 | S9: TERCIÁRIA | T9: A.RED.SSB-D014.V03.T01.002/037 | U9: =RIGHT(T9,7) -> 002/037 | V9: REVISÃO 08 | W9: 45882 | X9: ST BAIRRO RESID VITÓRIA | Z9: S/DEFINIÇÃO | AA9: 1.6 | AB9: TRECHO DE Zona01_PB01_Rede_NÓ107.2 A Zona01_PB01_Rede_NÓ1.9 | AC9: 5.8.44 | AD9: =CONCATENATE($C9,$I9,$H9,$N9,$J9,$K9) -> TUBO PEADPEAD63VCAREDESZona01 | AE9: =IFERROR(INDEX(APOIO_REDES!$A:$W,MATCH($C9&$I9&$H9&$N9&$O9,APOIO_REDES!$W:$W,0),MATCH(AE$5,APOIO_REDES!$5:$5,0)),0) -> 1.2 | AF9: =IFERROR(INDEX(APOIO_REDES!$A:$W,MATCH($C9&$I9&$H9&$N9&$O9,APOIO_REDES!$W:$W,0),MATCH(AF$5,APOIO_REDES!$5:$5,0)),0) -> 1.363 | AG9: =IFERROR(INDEX(APOIO_REDES!$A:$W,MATCH($C9&$I9&$H9&$N9&$O9,APOIO_REDES!$W:$W,0),MATCH(AG$5,APOIO_REDES!$5:$5,0)),0) -> 0.65 | AH9: =IFERROR(INDEX(APOIO_REDES!$A:$W,MATCH($C9&$I9&$H9&$N9&$O9,APOIO_REDES!$W:$W,0),MATCH(AH$5,APOIO_REDES!$5:$5,0)),0) -> 0.1 | AI9: =IFERROR(IF($H9<>"",(((($H9/1000)/2)^2)*PI()*$M9),0),0) -> 0.08628535 | AJ9: =IFERROR(IF(AND($H9<>"",$I9="FoFo",OR($N9="MND",$N9="VCA"),$Q9="LINEAR"),0,IF(AND($H9<>"",$I9="PEAD",$N9="VCA",$Q9="LINEAR"),($H9/1000)+0.3,IF(AND($H9<>"",$I9="PEAD",$N9="MND",$Q9="EMBOQUE"),0,IF(AND($H9<>"",$I9="PVC",$N9="VCA",$Q9="LINEAR"),($H9/1000)+0.2,IF(AND($H9<>"",$I9="PVC",$N9="MND",$Q9="EMBOQUE"),0,IF(AND($H9<>"",$I9="PEAD",$N9="VCA",$Q9="PREDIAL"),0,0)))))),0) -> 0.363 | AK9: =IF(AA9<>"",AA9,0) -> 1.6 | AL9: =IF(AND($N9="MND",$Q9="EMBOQUE"),$M9,IF(AND($N9="VCA",$Q9="LINEAR"),$M9,IF(AND($N9="VCA",$Q9="PREDIAL"),0,0))) -> 27.68 | AM9: =IF(AND($N9="MND",$Q9="EMBOQUE"),$M9,IF(AND($N9="VCA",$Q9="LINEAR"),$M9,IF(AND($N9="VCA",$Q9="PREDIAL"),0,0))) -> 27.68 | AN9: =ROUND(IF(AND($N9="VCA",$M9<>"",$Q9="LINEAR"),$M9/100,IF(AND($N9="MND",$M9>100,$Q9="EMBOQUE"),$M9/100,0)),0) -> 0 | AO9: =IF(AND($N9="MND",$Q9="EMBOQUE"),$AN9*2*2,IF(AND($N9="VCA",$Q9="LINEAR"),$M9*2,IF(AND($N9="VCA",$Q9="PREDIAL"),0,0))) -> 55.36 | AP9: =IFERROR($M9*$AF9*$AG9,0) -> 24.523096 | AQ9: =IFERROR(IF(AND($N9="VCA",$AH9>0),$M9*$AG9*$AH9,0),0) -> 1.7992 | AR9: =IFERROR(IF(AND($N9="VCA",$AJ9>0),($M9*$AG9*$AJ9)-$AI9,0),0) -> 6.4448106 | AS9: =IFERROR(IF(AND($N9="VCA",$AP9>0),$AP9-$AI9-$AQ9-$AR9,0),0) -> 16.1928 | AT9: =IFERROR(IF($N9="VCA",INDEX(APOIO_REDES!$A:$W,MATCH($C9&$I9&$H9&$N9&$O9,APOIO_REDES!$W:$W,0),MATCH(AT$5,APOIO_REDES!$5:$5,0)),0)*$AP9,0) -> 0.26681854 | AU9: =IFERROR(IF($N9="VCA",INDEX(APOIO_REDES!$A:$W,MATCH($C9&$I9&$H9&$N9&$O9,APOIO_REDES!$W:$W,0),MATCH(AU$5,APOIO_REDES!$5:$5,0)),0)*$AP9,0) -> 0.21307406 | AV9: =IFERROR(IF($N9="VCA",INDEX(APOIO_REDES!$A:$W,MATCH($C9&$I9&$H9&$N9&$O9,APOIO_REDES!$W:$W,0),MATCH(AV$5,APOIO_REDES!$5:$5,0)),0)*$AP9,0) -> 0.029487777 | AW9: =IFERROR(IF($N9="VCA",INDEX(APOIO_REDES!$A:$W,MATCH($C9&$I9&$H9&$N9&$O9,APOIO_REDES!$W:$W,0),MATCH(AW$5,APOIO_REDES!$5:$5,0)),0)*$AP9,0) -> 16.832843 | AX9: =IFERROR(IF($N9="VCA",INDEX(APOIO_REDES!$A:$W,MATCH($C9&$I9&$H9&$N9&$O9,APOIO_REDES!$W:$W,0),MATCH(AX$5,APOIO_REDES!$5:$5,0)),0)*$AP9,0) -> 2.3296175 | AY9: =IFERROR(IF($N9="VCA",INDEX(APOIO_REDES!$A:$W,MATCH($C9&$I9&$H9&$N9&$O9,APOIO_REDES!$W:$W,0),MATCH(AY$5,APOIO_REDES!$5:$5,0)),0)*$AP9,0) -> 4.2614786 | AZ9: =IFERROR(IF($N9="VCA",INDEX(APOIO_REDES!$A:$W,MATCH($C9&$I9&$H9&$N9&$O9,APOIO_REDES!$W:$W,0),MATCH(AZ$5,APOIO_REDES!$5:$5,0)),0)*$AP9,0) -> 0.58977633 | BA9: =IFERROR(IF(AND($N9="VCA",$Q9="LINEAR"),INDEX(APOIO_REDES!$A:$W,MATCH($C9&$I9&$H9&$N9&$O9,APOIO_REDES!$W:$W,0),MATCH(BA$5,APOIO_REDES!$5:$5,0)),IF(AND($N9="MND",$Q9="EMBOQUE"),INDEX(APOIO_REDES!$A:$W,MATCH($C9&$I9&$H9&$N9&$O9,APOIO_REDES!$W:$W,0),MATCH(BA$5,APOIO_REDES!$5:$5,0)),0))*$M9/10,0) -> 2.2309382 | BB9: =IFERROR(IF($N9="VCA",INDEX(APOIO_REDES!$A:$W,MATCH($C9&$I9&$H9&$N9&$O9,APOIO_REDES!$W:$W,0),MATCH(BB$5,APOIO_REDES!$5:$5,0)),0)*($AI9+$AQ9+$AR9),0) -> 8.2396599 | BC9: =IFERROR(IF($N9="VCA",INDEX(APOIO_REDES!$A:$W,MATCH($C9&$I9&$H9&$N9&$O9,APOIO_REDES!$W:$W,0),MATCH(BC$5,APOIO_REDES!$5:$5,0)),0)*($AI9+$AQ9+$AR9),0) -> 0.090636086 | BD9: =IF(AND($N9="VCA",$AF9>=1.25,$AF9<1.5),$M9*$AF9*2,0) -> 75.45568 | BE9: =IF(AND($N9="VCA",$AF9>=1.5,$AF9<3),$M9*$AF9*2,0) -> 0 | BF9: =IF(AND($N9="VCA",$AF9>=3),$M9*$AF9*2,0) -> 0 | BG9: =($BB9+$BC9)*$AK9 -> 13.328474 | BH9: =IF(AND($M9<>"",$N9="VCA",$Q9="LINEAR"),($M9*2)/100,IF(AND($M9<>"",$N9="MND",$Q9="EMBOQUE"),($AN9*2)/100,0)) -> 0.5536 | BI9: =IF(AND($M9<>"",$N9="VCA",$Q9="LINEAR"),$M9,IF(AND($M9<>"",$N9="MND",$Q9="EMBOQUE"),$AN9*2,0)) -> 27.68 | BJ9: =IF(AND($M9<>"",$N9="VCA",$Q9="LINEAR"),($M9*6.8)/100,IF(AND($M9<>"",$N9="MND",$Q9="EMBOQUE"),($AN9*2*6.8)/100,0)) -> 1.88224 | BK9: =IF(AND($M9<>"",$N9="VCA",$Q9="LINEAR"),($M9*2.5)/50,IF(AND($M9<>"",$N9="MND",$Q9="EMBOQUE"),($AN9*2*2.5)/50,0)) -> 1.384 | BL9: =K9&J9 -> Zona01REDES | BM9: EQUIPE ZONA 01 | BN9: Rede | BO9: PB01 | BP9: Zona01_PB01_Rede_NÓ107.2 | BQ9: Zona01_PB01_Rede_NÓ1.9 | BR9: 5FD12 | BS9: 203576.72 | BT9: 8239179.9 | BU9: 203555.02 | BV9: 8239197.1 | BW9: -15.9088 | BX9: -47.768456 | BY9: Zona01_PB01_Rede_NÓ107.2
A10: =IF(C10<>"",ROW(A5),"") -> 5 | B10: =HYPERLINK("https://www.google.com/maps/dir/-15.917302,-47.760003/-15.9087329,-47.7696502/data=!4m3!4m2!3e0!5i0") -> https://www.google.com/maps/dir/-15.917302,-47.760003/-15.9087329,-47.7696502/data=!4m3!4m2!3e0!5i0 | C10: TUBO PEAD | D10: PN10 | E10: PE100 | F10: TUBO PEAD | G10: ELETROFUSÃO | H10: 63 | I10: PEAD | J10: REDES | K10: Zona01 | L10: M | M10: =50.68 -> 50.68 | N10: VCA | O10: VIA | P10: REDE | Q10: LINEAR | R10: Zona01_PB01_Rede_TR005 | S10: TERCIÁRIA | T10: A.RED.SSB-D014.V03.T01.002/037 | U10: =RIGHT(T10,7) -> 002/037 | V10: REVISÃO 08 | W10: 45882 | X10: ST BAIRRO RESID VITÓRIA | Z10: S/DEFINIÇÃO | AA10: 1.8 | AB10: TRECHO DE Zona01_PB01_Rede_DF-33 A Zona01_PB01_Rede_NÓ1.5 | AC10: 5.8.44 | AD10: =CONCATENATE($C10,$I10,$H10,$N10,$J10,$K10) -> TUBO PEADPEAD63VCAREDESZona01 | AE10: =IFERROR(INDEX(APOIO_REDES!$A:$W,MATCH($C10&$I10&$H10&$N10&$O10,APOIO_REDES!$W:$W,0),MATCH(AE$5,APOIO_REDES!$5:$5,0)),0) -> 1.2 | AF10: =IFERROR(INDEX(APOIO_REDES!$A:$W,MATCH($C10&$I10&$H10&$N10&$O10,APOIO_REDES!$W:$W,0),MATCH(AF$5,APOIO_REDES!$5:$5,0)),0) -> 1.363 | AG10: =IFERROR(INDEX(APOIO_REDES!$A:$W,MATCH($C10&$I10&$H10&$N10&$O10,APOIO_REDES!$W:$W,0),MATCH(AG$5,APOIO_REDES!$5:$5,0)),0) -> 0.65 | AH10: =IFERROR(INDEX(APOIO_REDES!$A:$W,MATCH($C10&$I10&$H10&$N10&$O10,APOIO_REDES!$W:$W,0),MATCH(AH$5,APOIO_REDES!$5:$5,0)),0) -> 0.1 | AI10: =IFERROR(IF($H10<>"",(((($H10/1000)/2)^2)*PI()*$M10),0),0) -> 0.15798199 | AJ10: =IFERROR(IF(AND($H10<>"",$I10="FoFo",OR($N10="MND",$N10="VCA"),$Q10="LINEAR"),0,IF(AND($H10<>"",$I10="PEAD",$N10="VCA",$Q10="LINEAR"),($H10/1000)+0.3,IF(AND($H10<>"",$I10="PEAD",$N10="MND",$Q10="EMBOQUE"),0,IF(AND($H10<>"",$I10="PVC",$N10="VCA",$Q10="LINEAR"),($H10/1000)+0.2,IF(AND($H10<>"",$I10="PVC",$N10="MND",$Q10="EMBOQUE"),0,IF(AND($H10<>"",$I10="PEAD",$N10="VCA",$Q10="PREDIAL"),0,0)))))),0) -> 0.363 | AK10: =IF(AA10<>"",AA10,0) -> 1.8 | AL10: =IF(AND($N10="MND",$Q10="EMBOQUE"),$M10,IF(AND($N10="VCA",$Q10="LINEAR"),$M10,IF(AND($N10="VCA",$Q10="PREDIAL"),0,0))) -> 50.68 | AM10: =IF(AND($N10="MND",$Q10="EMBOQUE"),$M10,IF(AND($N10="VCA",$Q10="LINEAR"),$M10,IF(AND($N10="VCA",$Q10="PREDIAL"),0,0))) -> 50.68 | AN10: =ROUND(IF(AND($N10="VCA",$M10<>"",$Q10="LINEAR"),$M10/100,IF(AND($N10="MND",$M10>100,$Q10="EMBOQUE"),$M10/100,0)),0) -> 1 | AO10: =IF(AND($N10="MND",$Q10="EMBOQUE"),$AN10*2*2,IF(AND($N10="VCA",$Q10="LINEAR"),$M10*2,IF(AND($N10="VCA",$Q10="PREDIAL"),0,0))) -> 101.36 | AP10: =IFERROR($M10*$AF10*$AG10,0) -> 44.899946 | AQ10: =IFERROR(IF(AND($N10="VCA",$AH10>0),$M10*$AG10*$AH10,0),0) -> 3.2942 | AR10: =IFERROR(IF(AND($N10="VCA",$AJ10>0),($M10*$AG10*$AJ10)-$AI10,0),0) -> 11.799964 | AS10: =IFERROR(IF(AND($N10="VCA",$AP10>0),$AP10-$AI10-$AQ10-$AR10,0),0) -> 29.6478 | AT10: =IFERROR(IF($N10="VCA",INDEX(APOIO_REDES!$A:$W,MATCH($C10&$I10&$H10&$N10&$O10,APOIO_REDES!$W:$W,0),MATCH(AT$5,APOIO_REDES!$5:$5,0)),0)*$AP10,0) -> 0.4885247 | AU10: =IFERROR(IF($N10="VCA",INDEX(APOIO_REDES!$A:$W,MATCH($C10&$I10&$H10&$N10&$O10,APOIO_REDES!$W:$W,0),MATCH(AU$5,APOIO_REDES!$5:$5,0)),0)*$AP10,0) -> 0.3901226 | AV10: =IFERROR(IF($N10="VCA",INDEX(APOIO_REDES!$A:$W,MATCH($C10&$I10&$H10&$N10&$O10,APOIO_REDES!$W:$W,0),MATCH(AV$5,APOIO_REDES!$5:$5,0)),0)*$AP10,0) -> 0.053989905 | AW10: =IFERROR(IF($N10="VCA",INDEX(APOIO_REDES!$A:$W,MATCH($C10&$I10&$H10&$N10&$O10,APOIO_REDES!$W:$W,0),MATCH(AW$5,APOIO_REDES!$5:$5,0)),0)*$AP10,0) -> 30.819671 | AX10: =IFERROR(IF($N10="VCA",INDEX(APOIO_REDES!$A:$W,MATCH($C10&$I10&$H10&$N10&$O10,APOIO_REDES!$W:$W,0),MATCH(AX$5,APOIO_REDES!$5:$5,0)),0)*$AP10,0) -> 4.2653547 | AY10: =IFERROR(IF($N10="VCA",INDEX(APOIO_REDES!$A:$W,MATCH($C10&$I10&$H10&$N10&$O10,APOIO_REDES!$W:$W,0),MATCH(AY$5,APOIO_REDES!$5:$5,0)),0)*$AP10,0) -> 7.8024472 | AZ10: =IFERROR(IF($N10="VCA",INDEX(APOIO_REDES!$A:$W,MATCH($C10&$I10&$H10&$N10&$O10,APOIO_REDES!$W:$W,0),MATCH(AZ$5,APOIO_REDES!$5:$5,0)),0)*$AP10,0) -> 1.0798361 | BA10: =IFERROR(IF(AND($N10="VCA",$Q10="LINEAR"),INDEX(APOIO_REDES!$A:$W,MATCH($C10&$I10&$H10&$N10&$O10,APOIO_REDES!$W:$W,0),MATCH(BA$5,APOIO_REDES!$5:$5,0)),IF(AND($N10="MND",$Q10="EMBOQUE"),INDEX(APOIO_REDES!$A:$W,MATCH($C10&$I10&$H10&$N10&$O10,APOIO_REDES!$W:$W,0),MATCH(BA$5,APOIO_REDES!$5:$5,0)),0))*$M10/10,0) -> 4.0846802 | BB10: =IFERROR(IF($N10="VCA",INDEX(APOIO_REDES!$A:$W,MATCH($C10&$I10&$H10&$N10&$O10,APOIO_REDES!$W:$W,0),MATCH(BB$5,APOIO_REDES!$5:$5,0)),0)*($AI10+$AQ10+$AR10),0) -> 15.086198 | BC10: =IFERROR(IF($N10="VCA",INDEX(APOIO_REDES!$A:$W,MATCH($C10&$I10&$H10&$N10&$O10,APOIO_REDES!$W:$W,0),MATCH(BC$5,APOIO_REDES!$5:$5,0)),0)*($AI10+$AQ10+$AR10),0) -> 0.16594786 | BD10: =IF(AND($N10="VCA",$AF10>=1.25,$AF10<1.5),$M10*$AF10*2,0) -> 138.15368 | BE10: =IF(AND($N10="VCA",$AF10>=1.5,$AF10<3),$M10*$AF10*2,0) -> 0 | BF10: =IF(AND($N10="VCA",$AF10>=3),$M10*$AF10*2,0) -> 0 | BG10: =($BB10+$BC10)*$AK10 -> 27.453863 | BH10: =IF(AND($M10<>"",$N10="VCA",$Q10="LINEAR"),($M10*2)/100,IF(AND($M10<>"",$N10="MND",$Q10="EMBOQUE"),($AN10*2)/100,0)) -> 1.0136 | BI10: =IF(AND($M10<>"",$N10="VCA",$Q10="LINEAR"),$M10,IF(AND($M10<>"",$N10="MND",$Q10="EMBOQUE"),$AN10*2,0)) -> 50.68 | BJ10: =IF(AND($M10<>"",$N10="VCA",$Q10="LINEAR"),($M10*6.8)/100,IF(AND($M10<>"",$N10="MND",$Q10="EMBOQUE"),($AN10*2*6.8)/100,0)) -> 3.44624 | BK10: =IF(AND($M10<>"",$N10="VCA",$Q10="LINEAR"),($M10*2.5)/50,IF(AND($M10<>"",$N10="MND",$Q10="EMBOQUE"),($AN10*2*2.5)/50,0)) -> 2.534 | BL10: =K10&J10 -> Zona01REDES | BM10: EQUIPE ZONA 01 | BN10: Rede | BO10: PB01 | BP10: Zona01_PB01_Rede_DF-33 | BQ10: Zona01_PB01_Rede_NÓ1.5 | BR10: 5FD12 | BS10: 203438.2 | BT10: 8239193.8 | BU10: 203404.08 | BV10: 8239156.7 | BW10: -15.908912 | BX10: -47.769796 | BY10: Zona01_PB01_Rede_DF-33
A11: =IF(C11<>"",ROW(A6),"") -> 6 | B11: =HYPERLINK("https://www.google.com/maps/dir/-15.917302,-47.760003/-15.9087023,-47.7685795/data=!4m3!4m2!3e0!5i0") -> https://www.google.com/maps/dir/-15.917302,-47.760003/-15.9087023,-47.7685795/data=!4m3!4m2!3e0!5i0 | C11: TUBO PEAD | D11: PN10 | E11: PE100 | F11: TUBO PEAD | G11: ELETROFUSÃO | H11: 63 | I11: PEAD | J11: REDES | K11: Zona01 | L11: M | M11: =106.08+0.01 -> 106.09 | N11: VCA | O11: VIA | P11: REDE | Q11: LINEAR | R11: Zona01_PB01_Rede_TR006 | S11: TERCIÁRIA | T11: A.RED.SSB-D014.V03.T01.002/037 | U11: =RIGHT(T11,7) -> 002/037 | V11: REVISÃO 08 | W11: 45882 | X11: ST BAIRRO RESID VITÓRIA | Z11: S/DEFINIÇÃO | AA11: 1.6 | AB11: TRECHO DE Zona01_PB01_Rede_NÓ1.8 A Zona01_PB01_Rede_NÓ1.7; INCLUI 0,01 M DE TUBO DESENHADO NO PRÓPRIO NÓ (NÓ1.8: anel de ponta/toco) | AC11: 5.8.44 | AD11: =CONCATENATE($C11,$I11,$H11,$N11,$J11,$K11) -> TUBO PEADPEAD63VCAREDESZona01 | AE11: =IFERROR(INDEX(APOIO_REDES!$A:$W,MATCH($C11&$I11&$H11&$N11&$O11,APOIO_REDES!$W:$W,0),MATCH(AE$5,APOIO_REDES!$5:$5,0)),0) -> 1.2 | AF11: =IFERROR(INDEX(APOIO_REDES!$A:$W,MATCH($C11&$I11&$H11&$N11&$O11,APOIO_REDES!$W:$W,0),MATCH(AF$5,APOIO_REDES!$5:$5,0)),0) -> 1.363 | AG11: =IFERROR(INDEX(APOIO_REDES!$A:$W,MATCH($C11&$I11&$H11&$N11&$O11,APOIO_REDES!$W:$W,0),MATCH(AG$5,APOIO_REDES!$5:$5,0)),0) -> 0.65 | AH11: =IFERROR(INDEX(APOIO_REDES!$A:$W,MATCH($C11&$I11&$H11&$N11&$O11,APOIO_REDES!$W:$W,0),MATCH(AH$5,APOIO_REDES!$5:$5,0)),0) -> 0.1 | AI11: =IFERROR(IF($H11<>"",(((($H11/1000)/2)^2)*PI()*$M11),0),0) -> 0.33070855 | AJ11: =IFERROR(IF(AND($H11<>"",$I11="FoFo",OR($N11="MND",$N11="VCA"),$Q11="LINEAR"),0,IF(AND($H11<>"",$I11="PEAD",$N11="VCA",$Q11="LINEAR"),($H11/1000)+0.3,IF(AND($H11<>"",$I11="PEAD",$N11="MND",$Q11="EMBOQUE"),0,IF(AND($H11<>"",$I11="PVC",$N11="VCA",$Q11="LINEAR"),($H11/1000)+0.2,IF(AND($H11<>"",$I11="PVC",$N11="MND",$Q11="EMBOQUE"),0,IF(AND($H11<>"",$I11="PEAD",$N11="VCA",$Q11="PREDIAL"),0,0)))))),0) -> 0.363 | AK11: =IF(AA11<>"",AA11,0) -> 1.6 | AL11: =IF(AND($N11="MND",$Q11="EMBOQUE"),$M11,IF(AND($N11="VCA",$Q11="LINEAR"),$M11,IF(AND($N11="VCA",$Q11="PREDIAL"),0,0))) -> 106.09 | AM11: =IF(AND($N11="MND",$Q11="EMBOQUE"),$M11,IF(AND($N11="VCA",$Q11="LINEAR"),$M11,IF(AND($N11="VCA",$Q11="PREDIAL"),0,0))) -> 106.09 | AN11: =ROUND(IF(AND($N11="VCA",$M11<>"",$Q11="LINEAR"),$M11/100,IF(AND($N11="MND",$M11>100,$Q11="EMBOQUE"),$M11/100,0)),0) -> 1 | AO11: =IF(AND($N11="MND",$Q11="EMBOQUE"),$AN11*2*2,IF(AND($N11="VCA",$Q11="LINEAR"),$M11*2,IF(AND($N11="VCA",$Q11="PREDIAL"),0,0))) -> 212.18 | AP11: =IFERROR($M11*$AF11*$AG11,0) -> 93.990436 | AQ11: =IFERROR(IF(AND($N11="VCA",$AH11>0),$M11*$AG11*$AH11,0),0) -> 6.89585 | AR11: =IFERROR(IF(AND($N11="VCA",$AJ11>0),($M11*$AG11*$AJ11)-$AI11,0),0) -> 24.701227 | AS11: =IFERROR(IF(AND($N11="VCA",$AP11>0),$AP11-$AI11-$AQ11-$AR11,0),0) -> 62.06265 | AT11: =IFERROR(IF($N11="VCA",INDEX(APOIO_REDES!$A:$W,MATCH($C11&$I11&$H11&$N11&$O11,APOIO_REDES!$W:$W,0),MATCH(AT$5,APOIO_REDES!$5:$5,0)),0)*$AP11,0) -> 1.0226438 | AU11: =IFERROR(IF($N11="VCA",INDEX(APOIO_REDES!$A:$W,MATCH($C11&$I11&$H11&$N11&$O11,APOIO_REDES!$W:$W,0),MATCH(AU$5,APOIO_REDES!$5:$5,0)),0)*$AP11,0) -> 0.81665561 | AV11: =IFERROR(IF($N11="VCA",INDEX(APOIO_REDES!$A:$W,MATCH($C11&$I11&$H11&$N11&$O11,APOIO_REDES!$W:$W,0),MATCH(AV$5,APOIO_REDES!$5:$5,0)),0)*$AP11,0) -> 0.11301873 | AW11: =IFERROR(IF($N11="VCA",INDEX(APOIO_REDES!$A:$W,MATCH($C11&$I11&$H11&$N11&$O11,APOIO_REDES!$W:$W,0),MATCH(AW$5,APOIO_REDES!$5:$5,0)),0)*$AP11,0) -> 64.515763 | AX11: =IFERROR(IF($N11="VCA",INDEX(APOIO_REDES!$A:$W,MATCH($C11&$I11&$H11&$N11&$O11,APOIO_REDES!$W:$W,0),MATCH(AX$5,APOIO_REDES!$5:$5,0)),0)*$AP11,0) -> 8.9287979 | AY11: =IFERROR(IF($N11="VCA",INDEX(APOIO_REDES!$A:$W,MATCH($C11&$I11&$H11&$N11&$O11,APOIO_REDES!$W:$W,0),MATCH(AY$5,APOIO_REDES!$5:$5,0)),0)*$AP11,0) -> 16.333102 | AZ11: =IFERROR(IF($N11="VCA",INDEX(APOIO_REDES!$A:$W,MATCH($C11&$I11&$H11&$N11&$O11,APOIO_REDES!$W:$W,0),MATCH(AZ$5,APOIO_REDES!$5:$5,0)),0)*$AP11,0) -> 2.2604541 | BA11: =IFERROR(IF(AND($N11="VCA",$Q11="LINEAR"),INDEX(APOIO_REDES!$A:$W,MATCH($C11&$I11&$H11&$N11&$O11,APOIO_REDES!$W:$W,0),MATCH(BA$5,APOIO_REDES!$5:$5,0)),IF(AND($N11="MND",$Q11="EMBOQUE"),INDEX(APOIO_REDES!$A:$W,MATCH($C11&$I11&$H11&$N11&$O11,APOIO_REDES!$W:$W,0),MATCH(BA$5,APOIO_REDES!$5:$5,0)),0))*$M11/10,0) -> 8.5505864 | BB11: =IFERROR(IF($N11="VCA",INDEX(APOIO_REDES!$A:$W,MATCH($C11&$I11&$H11&$N11&$O11,APOIO_REDES!$W:$W,0),MATCH(BB$5,APOIO_REDES!$5:$5,0)),0)*($AI11+$AQ11+$AR11),0) -> 31.580402 | BC11: =IFERROR(IF($N11="VCA",INDEX(APOIO_REDES!$A:$W,MATCH($C11&$I11&$H11&$N11&$O11,APOIO_REDES!$W:$W,0),MATCH(BC$5,APOIO_REDES!$5:$5,0)),0)*($AI11+$AQ11+$AR11),0) -> 0.34738376 | BD11: =IF(AND($N11="VCA",$AF11>=1.25,$AF11<1.5),$M11*$AF11*2,0) -> 289.20134 | BE11: =IF(AND($N11="VCA",$AF11>=1.5,$AF11<3),$M11*$AF11*2,0) -> 0 | BF11: =IF(AND($N11="VCA",$AF11>=3),$M11*$AF11*2,0) -> 0 | BG11: =($BB11+$BC11)*$AK11 -> 51.084457 | BH11: =IF(AND($M11<>"",$N11="VCA",$Q11="LINEAR"),($M11*2)/100,IF(AND($M11<>"",$N11="MND",$Q11="EMBOQUE"),($AN11*2)/100,0)) -> 2.1218 | BI11: =IF(AND($M11<>"",$N11="VCA",$Q11="LINEAR"),$M11,IF(AND($M11<>"",$N11="MND",$Q11="EMBOQUE"),$AN11*2,0)) -> 106.09 | BJ11: =IF(AND($M11<>"",$N11="VCA",$Q11="LINEAR"),($M11*6.8)/100,IF(AND($M11<>"",$N11="MND",$Q11="EMBOQUE"),($AN11*2*6.8)/100,0)) -> 7.21412 | BK11: =IF(AND($M11<>"",$N11="VCA",$Q11="LINEAR"),($M11*2.5)/50,IF(AND($M11<>"",$N11="MND",$Q11="EMBOQUE"),($AN11*2*2.5)/50,0)) -> 5.3045 | BL11: =K11&J11 -> Zona01REDES | BM11: EQUIPE ZONA 01 | BN11: Rede | BO11: PB01 | BP11: Zona01_PB01_Rede_NÓ1.8 | BQ11: Zona01_PB01_Rede_NÓ1.7 | BR11: B4DF, B4E2 | BS11: 203552.49 | BT11: 8239199.1 | BU11: 203483.76 | BV11: 8239118.4 | BW11: -15.909063 | BX11: -47.768904 | BY11: Zona01_PB01_Rede_NÓ1.8
A12: =IF(C12<>"",ROW(A7),"") -> 7 | B12: =HYPERLINK("https://www.google.com/maps/dir/-15.917302,-47.760003/-15.9096325,-47.7693914/data=!4m3!4m2!3e0!5i0") -> https://www.google.com/maps/dir/-15.917302,-47.760003/-15.9096325,-47.7693914/data=!4m3!4m2!3e0!5i0 | C12: TUBO PEAD | D12: PN10 | E12: PE100 | F12: TUBO PEAD | G12: ELETROFUSÃO | H12: 63 | I12: PEAD | J12: REDES | K12: Zona01 | L12: M | M12: =135.24+0.06 -> 135.3 | N12: VCA | O12: VIA | P12: REDE | Q12: LINEAR | R12: Zona01_PB01_Rede_TR007 | S12: TERCIÁRIA | T12: A.RED.SSB-D014.V03.T01.002/037 | U12: =RIGHT(T12,7) -> 002/037 | V12: REVISÃO 08 | W12: 45882 | X12: ST BAIRRO RESID VITÓRIA | Z12: S/DEFINIÇÃO | AA12: 1.8 | AB12: TRECHO DE Zona01_PB01_Rede_NÓ63.1 A Zona01_PB01_Rede_NÓ1.9; INCLUI 0,06 M DE TUBO DESENHADO NO PRÓPRIO NÓ (NÓ1.9, NÓ63.1: anel de ponta/toco) | AC12: 5.8.44 | AD12: =CONCATENATE($C12,$I12,$H12,$N12,$J12,$K12) -> TUBO PEADPEAD63VCAREDESZona01 | AE12: =IFERROR(INDEX(APOIO_REDES!$A:$W,MATCH($C12&$I12&$H12&$N12&$O12,APOIO_REDES!$W:$W,0),MATCH(AE$5,APOIO_REDES!$5:$5,0)),0) -> 1.2 | AF12: =IFERROR(INDEX(APOIO_REDES!$A:$W,MATCH($C12&$I12&$H12&$N12&$O12,APOIO_REDES!$W:$W,0),MATCH(AF$5,APOIO_REDES!$5:$5,0)),0) -> 1.363 | AG12: =IFERROR(INDEX(APOIO_REDES!$A:$W,MATCH($C12&$I12&$H12&$N12&$O12,APOIO_REDES!$W:$W,0),MATCH(AG$5,APOIO_REDES!$5:$5,0)),0) -> 0.65 | AH12: =IFERROR(INDEX(APOIO_REDES!$A:$W,MATCH($C12&$I12&$H12&$N12&$O12,APOIO_REDES!$W:$W,0),MATCH(AH$5,APOIO_REDES!$5:$5,0)),0) -> 0.1 | AI12: =IFERROR(IF($H12<>"",(((($H12/1000)/2)^2)*PI()*$M12),0),0) -> 0.42176329 | AJ12: =IFERROR(IF(AND($H12<>"",$I12="FoFo",OR($N12="MND",$N12="VCA"),$Q12="LINEAR"),0,IF(AND($H12<>"",$I12="PEAD",$N12="VCA",$Q12="LINEAR"),($H12/1000)+0.3,IF(AND($H12<>"",$I12="PEAD",$N12="MND",$Q12="EMBOQUE"),0,IF(AND($H12<>"",$I12="PVC",$N12="VCA",$Q12="LINEAR"),($H12/1000)+0.2,IF(AND($H12<>"",$I12="PVC",$N12="MND",$Q12="EMBOQUE"),0,IF(AND($H12<>"",$I12="PEAD",$N12="VCA",$Q12="PREDIAL"),0,0)))))),0) -> 0.363 | AK12: =IF(AA12<>"",AA12,0) -> 1.8 | AL12: =IF(AND($N12="MND",$Q12="EMBOQUE"),$M12,IF(AND($N12="VCA",$Q12="LINEAR"),$M12,IF(AND($N12="VCA",$Q12="PREDIAL"),0,0))) -> 135.3 | AM12: =IF(AND($N12="MND",$Q12="EMBOQUE"),$M12,IF(AND($N12="VCA",$Q12="LINEAR"),$M12,IF(AND($N12="VCA",$Q12="PREDIAL"),0,0))) -> 135.3 | AN12: =ROUND(IF(AND($N12="VCA",$M12<>"",$Q12="LINEAR"),$M12/100,IF(AND($N12="MND",$M12>100,$Q12="EMBOQUE"),$M12/100,0)),0) -> 1 | AO12: =IF(AND($N12="MND",$Q12="EMBOQUE"),$AN12*2*2,IF(AND($N12="VCA",$Q12="LINEAR"),$M12*2,IF(AND($N12="VCA",$Q12="PREDIAL"),0,0))) -> 270.6 | AP12: =IFERROR($M12*$AF12*$AG12,0) -> 119.86903 | AQ12: =IFERROR(IF(AND($N12="VCA",$AH12>0),$M12*$AG12*$AH12,0),0) -> 8.7945 | AR12: =IFERROR(IF(AND($N12="VCA",$AJ12>0),($M12*$AG12*$AJ12)-$AI12,0),0) -> 31.502272 | AS12: =IFERROR(IF(AND($N12="VCA",$AP12>0),$AP12-$AI12-$AQ12-$AR12,0),0) -> 79.1505 | AT12: =IFERROR(IF($N12="VCA",INDEX(APOIO_REDES!$A:$W,MATCH($C12&$I12&$H12&$N12&$O12,APOIO_REDES!$W:$W,0),MATCH(AT$5,APOIO_REDES!$5:$5,0)),0)*$AP12,0) -> 1.3042106 | AU12: =IFERROR(IF($N12="VCA",INDEX(APOIO_REDES!$A:$W,MATCH($C12&$I12&$H12&$N12&$O12,APOIO_REDES!$W:$W,0),MATCH(AU$5,APOIO_REDES!$5:$5,0)),0)*$AP12,0) -> 1.0415072 | AV12: =IFERROR(IF($N12="VCA",INDEX(APOIO_REDES!$A:$W,MATCH($C12&$I12&$H12&$N12&$O12,APOIO_REDES!$W:$W,0),MATCH(AV$5,APOIO_REDES!$5:$5,0)),0)*$AP12,0) -> 0.14413643 | AW12: =IFERROR(IF($N12="VCA",INDEX(APOIO_REDES!$A:$W,MATCH($C12&$I12&$H12&$N12&$O12,APOIO_REDES!$W:$W,0),MATCH(AW$5,APOIO_REDES!$5:$5,0)),0)*$AP12,0) -> 82.279034 | AX12: =IFERROR(IF($N12="VCA",INDEX(APOIO_REDES!$A:$W,MATCH($C12&$I12&$H12&$N12&$O12,APOIO_REDES!$W:$W,0),MATCH(AX$5,APOIO_REDES!$5:$5,0)),0)*$AP12,0) -> 11.387184 | AY12: =IFERROR(IF($N12="VCA",INDEX(APOIO_REDES!$A:$W,MATCH($C12&$I12&$H12&$N12&$O12,APOIO_REDES!$W:$W,0),MATCH(AY$5,APOIO_REDES!$5:$5,0)),0)*$AP12,0) -> 20.830132 | AZ12: =IFERROR(IF($N12="VCA",INDEX(APOIO_REDES!$A:$W,MATCH($C12&$I12&$H12&$N12&$O12,APOIO_REDES!$W:$W,0),MATCH(AZ$5,APOIO_REDES!$5:$5,0)),0)*$AP12,0) -> 2.8828301 | BA12: =IFERROR(IF(AND($N12="VCA",$Q12="LINEAR"),INDEX(APOIO_REDES!$A:$W,MATCH($C12&$I12&$H12&$N12&$O12,APOIO_REDES!$W:$W,0),MATCH(BA$5,APOIO_REDES!$5:$5,0)),IF(AND($N12="MND",$Q12="EMBOQUE"),INDEX(APOIO_REDES!$A:$W,MATCH($C12&$I12&$H12&$N12&$O12,APOIO_REDES!$W:$W,0),MATCH(BA$5,APOIO_REDES!$5:$5,0)),0))*$M12/10,0) -> 10.904839 | BB12: =IFERROR(IF($N12="VCA",INDEX(APOIO_REDES!$A:$W,MATCH($C12&$I12&$H12&$N12&$O12,APOIO_REDES!$W:$W,0),MATCH(BB$5,APOIO_REDES!$5:$5,0)),0)*($AI12+$AQ12+$AR12),0) -> 40.275505 | BC12: =IFERROR(IF($N12="VCA",INDEX(APOIO_REDES!$A:$W,MATCH($C12&$I12&$H12&$N12&$O12,APOIO_REDES!$W:$W,0),MATCH(BC$5,APOIO_REDES!$5:$5,0)),0)*($AI12+$AQ12+$AR12),0) -> 0.44302971 | BD12: =IF(AND($N12="VCA",$AF12>=1.25,$AF12<1.5),$M12*$AF12*2,0) -> 368.8278 | BE12: =IF(AND($N12="VCA",$AF12>=1.5,$AF12<3),$M12*$AF12*2,0) -> 0 | BF12: =IF(AND($N12="VCA",$AF12>=3),$M12*$AF12*2,0) -> 0 | BG12: =($BB12+$BC12)*$AK12 -> 73.293363 | BH12: =IF(AND($M12<>"",$N12="VCA",$Q12="LINEAR"),($M12*2)/100,IF(AND($M12<>"",$N12="MND",$Q12="EMBOQUE"),($AN12*2)/100,0)) -> 2.706 | BI12: =IF(AND($M12<>"",$N12="VCA",$Q12="LINEAR"),$M12,IF(AND($M12<>"",$N12="MND",$Q12="EMBOQUE"),$AN12*2,0)) -> 135.3 | BJ12: =IF(AND($M12<>"",$N12="VCA",$Q12="LINEAR"),($M12*6.8)/100,IF(AND($M12<>"",$N12="MND",$Q12="EMBOQUE"),($AN12*2*6.8)/100,0)) -> 9.2004 | BK12: =IF(AND($M12<>"",$N12="VCA",$Q12="LINEAR"),($M12*2.5)/50,IF(AND($M12<>"",$N12="MND",$Q12="EMBOQUE"),($AN12*2*2.5)/50,0)) -> 6.765 | BL12: =K12&J12 -> Zona01REDES | BM12: EQUIPE ZONA 01 | BN12: Rede | BO12: PB01 | BP12: Zona01_PB01_Rede_NÓ63.1 | BQ12: Zona01_PB01_Rede_NÓ1.9 | BR12: B4E5, B4E8 | BS12: 203466.64 | BT12: 8239095.2 | BU12: 203555.02 | BV12: 8239197.1 | BW12: -15.909181 | BX12: -47.768968 | BY12: Zona01_PB01_Rede_NÓ63.1
A13: =IF(C13<>"",ROW(A8),"") -> 8 | B13: =HYPERLINK("https://www.google.com/maps/dir/-15.917302,-47.760003/-15.9090675,-47.7699696/data=!4m3!4m2!3e0!5i0") -> https://www.google.com/maps/dir/-15.917302,-47.760003/-15.9090675,-47.7699696/data=!4m3!4m2!3e0!5i0 | C13: TUBO PEAD | D13: PN10 | E13: PE100 | F13: TUBO PEAD | G13: ELETROFUSÃO | H13: 63 | I13: PEAD | J13: REDES | K13: Zona01 | L13: M | M13: =44.52 -> 44.52 | N13: VCA | O13: VIA | P13: REDE | Q13: LINEAR | R13: Zona01_PB01_Rede_TR008 | S13: TERCIÁRIA | T13: A.RED.SSB-D014.V03.T01.002/037 | U13: =RIGHT(T13,7) -> 002/037 | V13: REVISÃO 08 | W13: 45882 | X13: ST BAIRRO RESID VITÓRIA | Z13: S/DEFINIÇÃO | AA13: 1.8 | AB13: TRECHO DE Zona01_PB01_Rede_NÓ1.5 A Zona01_PB01_Rede_NÓ1.3 | AC13: 5.8.44 | AD13: =CONCATENATE($C13,$I13,$H13,$N13,$J13,$K13) -> TUBO PEADPEAD63VCAREDESZona01 | AE13: =IFERROR(INDEX(APOIO_REDES!$A:$W,MATCH($C13&$I13&$H13&$N13&$O13,APOIO_REDES!$W:$W,0),MATCH(AE$5,APOIO_REDES!$5:$5,0)),0) -> 1.2 | AF13: =IFERROR(INDEX(APOIO_REDES!$A:$W,MATCH($C13&$I13&$H13&$N13&$O13,APOIO_REDES!$W:$W,0),MATCH(AF$5,APOIO_REDES!$5:$5,0)),0) -> 1.363 | AG13: =IFERROR(INDEX(APOIO_REDES!$A:$W,MATCH($C13&$I13&$H13&$N13&$O13,APOIO_REDES!$W:$W,0),MATCH(AG$5,APOIO_REDES!$5:$5,0)),0) -> 0.65 | AH13: =IFERROR(INDEX(APOIO_REDES!$A:$W,MATCH($C13&$I13&$H13&$N13&$O13,APOIO_REDES!$W:$W,0),MATCH(AH$5,APOIO_REDES!$5:$5,0)),0) -> 0.1 | AI13: =IFERROR(IF($H13<>"",(((($H13/1000)/2)^2)*PI()*$M13),0),0) -> 0.13877976 | AJ13: =IFERROR(IF(AND($H13<>"",$I13="FoFo",OR($N13="MND",$N13="VCA"),$Q13="LINEAR"),0,IF(AND($H13<>"",$I13="PEAD",$N13="VCA",$Q13="LINEAR"),($H13/1000)+0.3,IF(AND($H13<>"",$I13="PEAD",$N13="MND",$Q13="EMBOQUE"),0,IF(AND($H13<>"",$I13="PVC",$N13="VCA",$Q13="LINEAR"),($H13/1000)+0.2,IF(AND($H13<>"",$I13="PVC",$N13="MND",$Q13="EMBOQUE"),0,IF(AND($H13<>"",$I13="PEAD",$N13="VCA",$Q13="PREDIAL"),0,0)))))),0) -> 0.363 | AK13: =IF(AA13<>"",AA13,0) -> 1.8 | AL13: =IF(AND($N13="MND",$Q13="EMBOQUE"),$M13,IF(AND($N13="VCA",$Q13="LINEAR"),$M13,IF(AND($N13="VCA",$Q13="PREDIAL"),0,0))) -> 44.52 | AM13: =IF(AND($N13="MND",$Q13="EMBOQUE"),$M13,IF(AND($N13="VCA",$Q13="LINEAR"),$M13,IF(AND($N13="VCA",$Q13="PREDIAL"),0,0))) -> 44.52 | AN13: =ROUND(IF(AND($N13="VCA",$M13<>"",$Q13="LINEAR"),$M13/100,IF(AND($N13="MND",$M13>100,$Q13="EMBOQUE"),$M13/100,0)),0) -> 0 | AO13: =IF(AND($N13="MND",$Q13="EMBOQUE"),$AN13*2*2,IF(AND($N13="VCA",$Q13="LINEAR"),$M13*2,IF(AND($N13="VCA",$Q13="PREDIAL"),0,0))) -> 89.04 | AP13: =IFERROR($M13*$AF13*$AG13,0) -> 39.442494 | AQ13: =IFERROR(IF(AND($N13="VCA",$AH13>0),$M13*$AG13*$AH13,0),0) -> 2.8938 | AR13: =IFERROR(IF(AND($N13="VCA",$AJ13>0),($M13*$AG13*$AJ13)-$AI13,0),0) -> 10.365714 | AS13: =IFERROR(IF(AND($N13="VCA",$AP13>0),$AP13-$AI13-$AQ13-$AR13,0),0) -> 26.0442 | AT13: =IFERROR(IF($N13="VCA",INDEX(APOIO_REDES!$A:$W,MATCH($C13&$I13&$H13&$N13&$O13,APOIO_REDES!$W:$W,0),MATCH(AT$5,APOIO_REDES!$5:$5,0)),0)*$AP13,0) -> 0.42914601 | AU13: =IFERROR(IF($N13="VCA",INDEX(APOIO_REDES!$A:$W,MATCH($C13&$I13&$H13&$N13&$O13,APOIO_REDES!$W:$W,0),MATCH(AU$5,APOIO_REDES!$5:$5,0)),0)*$AP13,0) -> 0.34270438 | AV13: =IFERROR(IF($N13="VCA",INDEX(APOIO_REDES!$A:$W,MATCH($C13&$I13&$H13&$N13&$O13,APOIO_REDES!$W:$W,0),MATCH(AV$5,APOIO_REDES!$5:$5,0)),0)*$AP13,0) -> 0.047427596 | AW13: =IFERROR(IF($N13="VCA",INDEX(APOIO_REDES!$A:$W,MATCH($C13&$I13&$H13&$N13&$O13,APOIO_REDES!$W:$W,0),MATCH(AW$5,APOIO_REDES!$5:$5,0)),0)*$AP13,0) -> 27.073633 | AX13: =IFERROR(IF($N13="VCA",INDEX(APOIO_REDES!$A:$W,MATCH($C13&$I13&$H13&$N13&$O13,APOIO_REDES!$W:$W,0),MATCH(AX$5,APOIO_REDES!$5:$5,0)),0)*$AP13,0) -> 3.7469138 | AY13: =IFERROR(IF($N13="VCA",INDEX(APOIO_REDES!$A:$W,MATCH($C13&$I13&$H13&$N13&$O13,APOIO_REDES!$W:$W,0),MATCH(AY$5,APOIO_REDES!$5:$5,0)),0)*$AP13,0) -> 6.8540834 | AZ13: =IFERROR(IF($N13="VCA",INDEX(APOIO_REDES!$A:$W,MATCH($C13&$I13&$H13&$N13&$O13,APOIO_REDES!$W:$W,0),MATCH(AZ$5,APOIO_REDES!$5:$5,0)),0)*$AP13,0) -> 0.94858534 | BA13: =IFERROR(IF(AND($N13="VCA",$Q13="LINEAR"),INDEX(APOIO_REDES!$A:$W,MATCH($C13&$I13&$H13&$N13&$O13,APOIO_REDES!$W:$W,0),MATCH(BA$5,APOIO_REDES!$5:$5,0)),IF(AND($N13="MND",$Q13="EMBOQUE"),INDEX(APOIO_REDES!$A:$W,MATCH($C13&$I13&$H13&$N13&$O13,APOIO_REDES!$W:$W,0),MATCH(BA$5,APOIO_REDES!$5:$5,0)),0))*$M13/10,0) -> 3.5881997 | BB13: =IFERROR(IF($N13="VCA",INDEX(APOIO_REDES!$A:$W,MATCH($C13&$I13&$H13&$N13&$O13,APOIO_REDES!$W:$W,0),MATCH(BB$5,APOIO_REDES!$5:$5,0)),0)*($AI13+$AQ13+$AR13),0) -> 13.252517 | BC13: =IFERROR(IF($N13="VCA",INDEX(APOIO_REDES!$A:$W,MATCH($C13&$I13&$H13&$N13&$O13,APOIO_REDES!$W:$W,0),MATCH(BC$5,APOIO_REDES!$5:$5,0)),0)*($AI13+$AQ13+$AR13),0) -> 0.1457774 | BD13: =IF(AND($N13="VCA",$AF13>=1.25,$AF13<1.5),$M13*$AF13*2,0) -> 121.36152 | BE13: =IF(AND($N13="VCA",$AF13>=1.5,$AF13<3),$M13*$AF13*2,0) -> 0 | BF13: =IF(AND($N13="VCA",$AF13>=3),$M13*$AF13*2,0) -> 0 | BG13: =($BB13+$BC13)*$AK13 -> 24.116929 | BH13: =IF(AND($M13<>"",$N13="VCA",$Q13="LINEAR"),($M13*2)/100,IF(AND($M13<>"",$N13="MND",$Q13="EMBOQUE"),($AN13*2)/100,0)) -> 0.8904 | BI13: =IF(AND($M13<>"",$N13="VCA",$Q13="LINEAR"),$M13,IF(AND($M13<>"",$N13="MND",$Q13="EMBOQUE"),$AN13*2,0)) -> 44.52 | BJ13: =IF(AND($M13<>"",$N13="VCA",$Q13="LINEAR"),($M13*6.8)/100,IF(AND($M13<>"",$N13="MND",$Q13="EMBOQUE"),($AN13*2*6.8)/100,0)) -> 3.02736 | BK13: =IF(AND($M13<>"",$N13="VCA",$Q13="LINEAR"),($M13*2.5)/50,IF(AND($M13<>"",$N13="MND",$Q13="EMBOQUE"),($AN13*2*2.5)/50,0)) -> 2.226 | BL13: =K13&J13 -> Zona01REDES | BM13: EQUIPE ZONA 01 | BN13: Rede | BO13: PB01 | BP13: Zona01_PB01_Rede_NÓ1.5 | BQ13: Zona01_PB01_Rede_NÓ1.3 | BR13: 5FD12 | BS13: 203404.08 | BT13: 8239156.7 | BU13: 203372.3 | BV13: 8239125.5 | BW13: -15.909206 | BX13: -47.77012 | BY13: Zona01_PB01_Rede_NÓ1.5
