Workbook

Sheet BM MORRO DA CRUZ
A1: BM - PLANILHA DE MEDIÇÃO - JUNTADA | P1: CONTRATO: | R1: MED. Nº.: | T1: MED. Nº.: | V1: MED. Nº.: | X1: MED. Nº.: | Z1: MED. Nº.: | AB1: MED. Nº.: | AD1: MED. Nº.: | AF1: MED. Nº.: | AH1: MED. Nº.: | AJ1: MED. Nº.: | AL1: MED. Nº.: | AN1: MED. Nº.: | AP1: MED. Nº.: | AR1: MED. Nº.: | AT1: MED. Nº.: | AV1: MED. Nº.: | AX1: MED. Nº.: | AZ1: MED. Nº.: | BB1: DATA:
P2: _____ / | Q2: 2026 | R2: ='BM MORRO DA CRUZ - VERTICAL'!V$2 -> 1ª MEDIÇÃO | T2: ='BM MORRO DA CRUZ - VERTICAL'!X$2 -> 2ª MEDIÇÃO | V2: ='BM MORRO DA CRUZ - VERTICAL'!Z$2 -> 3ª MEDIÇÃO | X2: ='BM MORRO DA CRUZ - VERTICAL'!AB$2 -> 4ª MEDIÇÃO | Z2: ='BM MORRO DA CRUZ - VERTICAL'!AD$2 -> 5ª MEDIÇÃO | AB2: ='BM MORRO DA CRUZ - VERTICAL'!AF$2 -> 6ª MEDIÇÃO | AD2: ='BM MORRO DA CRUZ - VERTICAL'!AH$2 -> 7ª MEDIÇÃO | AF2: ='BM MORRO DA CRUZ - VERTICAL'!AJ$2 -> 8ª MEDIÇÃO | AH2: ='BM MORRO DA CRUZ - VERTICAL'!AL$2 -> 9ª MEDIÇÃO | AJ2: ='BM MORRO DA CRUZ - VERTICAL'!AN$2 -> 10ª MEDIÇÃO | AL2: ='BM MORRO DA CRUZ - VERTICAL'!AP$2 -> 11ª MEDIÇÃO | AN2: ='BM MORRO DA CRUZ - VERTICAL'!AR$2 -> 12ª MEDIÇÃO | AP2: ='BM MORRO DA CRUZ - VERTICAL'!AT$2 -> 13ª MEDIÇÃO | AR2: ='BM MORRO DA CRUZ - VERTICAL'!AV$2 -> 14ª MEDIÇÃO | AT2: ='BM MORRO DA CRUZ - VERTICAL'!AX$2 -> 15ª MEDIÇÃO | AV2: ='BM MORRO DA CRUZ - VERTICAL'!AZ$2 -> 16ª MEDIÇÃO | AX2: ='BM MORRO DA CRUZ - VERTICAL'!BB$2 -> 17ª MEDIÇÃO | AZ2: ='BM MORRO DA CRUZ - VERTICAL'!BD$2 -> 18ª MEDIÇÃO | BB2: =IF('BM MORRO DA CRUZ - VERTICAL'!$BF$2="","",'BM MORRO DA CRUZ - VERTICAL'!$BF$2)
A3: OBRA: | N3: DATA BASE - ORÇAMENTO: | P3: ORIGINAL - P0 (CAESB) - PV | R3: PERÍODO: | T3: PERÍODO: | V3: PERÍODO: | X3: PERÍODO: | Z3: PERÍODO: | AB3: PERÍODO: | AD3: PERÍODO: | AF3: PERÍODO: | AH3: PERÍODO: | AJ3: PERÍODO: | AL3: PERÍODO: | AN3: PERÍODO: | AP3: PERÍODO: | AR3: PERÍODO: | AT3: PERÍODO: | AV3: PERÍODO: | AX3: PERÍODO: | AZ3: PERÍODO: | BB3: ELAB. POR: | BD3: STATUS DO CONTRATO
A4: IMPLANTAÇÃO DE REDES DE DISTRIBUIÇÃO NO MORRO DA CRUZ, SÃO SEBASTIÃO/DF - LC 014/2026 - JUNTADA 1426 (RED.SSB-D014) | N4: 01/2025 | R4: ='BM MORRO DA CRUZ - VERTICAL'!V$4 -> 01-10-26 A 31-10-26 | T4: ='BM MORRO DA CRUZ - VERTICAL'!X$4 -> 01-11-26 A 30-11-26 | V4: ='BM MORRO DA CRUZ - VERTICAL'!Z$4 -> 01-12-26 A 31-12-26 | X4: ='BM MORRO DA CRUZ - VERTICAL'!AB$4 -> 01-01-27 A 31-01-27 | Z4: ='BM MORRO DA CRUZ - VERTICAL'!AD$4 -> 01-02-27 A 28-02-27 | AB4: ='BM MORRO DA CRUZ - VERTICAL'!AF$4 -> 01-03-27 A 31-03-27 | AD4: ='BM MORRO DA CRUZ - VERTICAL'!AH$4 -> 01-04-27 A 30-04-27 | AF4: ='BM MORRO DA CRUZ - VERTICAL'!AJ$4 -> 01-05-27 A 31-05-27 | AH4: ='BM MORRO DA CRUZ - VERTICAL'!AL$4 -> 01-06-27 A 30-06-27 | AJ4: ='BM MORRO DA CRUZ - VERTICAL'!AN$4 -> 01-07-27 A 31-07-27 | AL4: ='BM MORRO DA CRUZ - VERTICAL'!AP$4 -> 01-08-27 A 31-08-27 | AN4: ='BM MORRO DA CRUZ - VERTICAL'!AR$4 -> 01-09-27 A 30-09-27 | AP4: ='BM MORRO DA CRUZ - VERTICAL'!AT$4 -> 01-10-27 A 31-10-27 | AR4: ='BM MORRO DA CRUZ - VERTICAL'!AV$4 -> 01-11-27 A 30-11-27 | AT4: ='BM MORRO DA CRUZ - VERTICAL'!AX$4 -> 01-12-27 A 31-12-27 | AV4: ='BM MORRO DA CRUZ - VERTICAL'!AZ$4 -> 01-01-28 A 31-01-28 | AX4: ='BM MORRO DA CRUZ - VERTICAL'!BB$4 -> 01-02-28 A 29-02-28 | AZ4: ='BM MORRO DA CRUZ - VERTICAL'!BD$4 -> 01-03-28 A 23-03-28 | BB4: ANKARA ENGENHARIA LTDA
A5: ITEM - BM | B5: DESCRIÇÃO | C5: PRESSÃO | D5: RESINA | E5: TIPO_CONEXÃO | F5: SOLDA | G5: DIÂMETRO | H5: MATERIAL | I5: GRUPO | J5: GRUPO ORÇAMENTO ANKARA | K5: CÓDIGO CAESB | L5: CLASSIFICAÇÃO | M5: DESCRIÇÃO | N5: UNID. | O5: QUANT. | P5: VALOR UNITÁRIO | Q5: TOTAL | R5: QUANT. | S5: TOTAL | T5: QUANT. | U5: TOTAL | V5: QUANT. | W5: TOTAL | X5: QUANT. | Y5: TOTAL | Z5: QUANT. | AA5: TOTAL | AB5: QUANT. | AC5: TOTAL | AD5: QUANT. | AE5: TOTAL | AF5: QUANT. | AG5: TOTAL | AH5: QUANT. | AI5: TOTAL | AJ5: QUANT. | AK5: TOTAL | AL5: QUANT. | AM5: TOTAL | AN5: QUANT. | AO5: TOTAL | AP5: QUANT. | AQ5: TOTAL | AR5: QUANT. | AS5: TOTAL | AT5: QUANT. | AU5: TOTAL | AV5: QUANT. | AW5: TOTAL | AX5: QUANT. | AY5: TOTAL | AZ5: QUANT. | BA5: TOTAL | BB5: QUANT. | BC5: TOTAL ACUMULADO | BD5: % MEDIDO | BE5: % SALDO
A6: 1 | K6: 03 | M6: MATERIAL | Q6: =SUM(Q7,Q9,Q12,Q14,Q16,Q18,Q20,Q22,Q24,Q26,Q45,Q48,Q57,Q59,Q137,Q184,Q186,Q188) -> 14442997 | S6: =SUM(S7,S9,S12,S14,S16,S18,S20,S22,S24,S26,S45,S48,S57,S59,S137,S184,S186,S188) -> 0 | U6: =SUM(U7,U9,U12,U14,U16,U18,U20,U22,U24,U26,U45,U48,U57,U59,U137,U184,U186,U188) -> 0 | W6: =SUM(W7,W9,W12,W14,W16,W18,W20,W22,W24,W26,W45,W48,W57,W59,W137,W184,W186,W188) -> 0 | Y6: =SUM(Y7,Y9,Y12,Y14,Y16,Y18,Y20,Y22,Y24,Y26,Y45,Y48,Y57,Y59,Y137,Y184,Y186,Y188) -> 0 | AA6: =SUM(AA7,AA9,AA12,AA14,AA16,AA18,AA20,AA22,AA24,AA26,AA45,AA48,AA57,AA59,AA137,AA184,AA186,AA188) -> 0 | AC6: =SUM(AC7,AC9,AC12,AC14,AC16,AC18,AC20,AC22,AC24,AC26,AC45,AC48,AC57,AC59,AC137,AC184,AC186,AC188) -> 0 | AE6: =SUM(AE7,AE9,AE12,AE14,AE16,AE18,AE20,AE22,AE24,AE26,AE45,AE48,AE57,AE59,AE137,AE184,AE186,AE188) -> 0 | AG6: =SUM(AG7,AG9,AG12,AG14,AG16,AG18,AG20,AG22,AG24,AG26,AG45,AG48,AG57,AG59,AG137,AG184,AG186,AG188) -> 0 | AI6: =SUM(AI7,AI9,AI12,AI14,AI16,AI18,AI20,AI22,AI24,AI26,AI45,AI48,AI57,AI59,AI137,AI184,AI186,AI188) -> 0 | AK6: =SUM(AK7,AK9,AK12,AK14,AK16,AK18,AK20,AK22,AK24,AK26,AK45,AK48,AK57,AK59,AK137,AK184,AK186,AK188) -> 0 | AM6: =SUM(AM7,AM9,AM12,AM14,AM16,AM18,AM20,AM22,AM24,AM26,AM45,AM48,AM57,AM59,AM137,AM184,AM186,AM188) -> 0 | AO6: =SUM(AO7,AO9,AO12,AO14,AO16,AO18,AO20,AO22,AO24,AO26,AO45,AO48,AO57,AO59,AO137,AO184,AO186,AO188) -> 0 | AQ6: =SUM(AQ7,AQ9,AQ12,AQ14,AQ16,AQ18,AQ20,AQ22,AQ24,AQ26,AQ45,AQ48,AQ57,AQ59,AQ137,AQ184,AQ186,AQ188) -> 0 | AS6: =SUM(AS7,AS9,AS12,AS14,AS16,AS18,AS20,AS22,AS24,AS26,AS45,AS48,AS57,AS59,AS137,AS184,AS186,AS188) -> 0 | AU6: =SUM(AU7,AU9,AU12,AU14,AU16,AU18,AU20,AU22,AU24,AU26,AU45,AU48,AU57,AU59,AU137,AU184,AU186,AU188) -> 0 | AW6: =SUM(AW7,AW9,AW12,AW14,AW16,AW18,AW20,AW22,AW24,AW26,AW45,AW48,AW57,AW59,AW137,AW184,AW186,AW188) -> 0 | AY6: =SUM(AY7,AY9,AY12,AY14,AY16,AY18,AY20,AY22,AY24,AY26,AY45,AY48,AY57,AY59,AY137,AY184,AY186,AY188) -> 0 | BA6: =SUM(BA7,BA9,BA12,BA14,BA16,BA18,BA20,BA22,BA24,BA26,BA45,BA48,BA57,BA59,BA137,BA184,BA186,BA188) -> 0 | BC6: =SUM(BC7,BC9,BC12,BC14,BC16,BC18,BC20,BC22,BC24,BC26,BC45,BC48,BC57,BC59,BC137,BC184,BC186,BC188) -> 0
A7: 1.1 | K7: 01730 | M7: ADMINISTRAÇÃO LOCAL | Q7: =SUM(Q8:Q8) -> 28416.96 | S7: =SUM(S8:S8) -> 0 | U7: =SUM(U8:U8) -> 0 | W7: =SUM(W8:W8) -> 0 | Y7: =SUM(Y8:Y8) -> 0 | AA7: =SUM(AA8:AA8) -> 0 | AC7: =SUM(AC8:AC8) -> 0 | AE7: =SUM(AE8:AE8) -> 0 | AG7: =SUM(AG8:AG8) -> 0 | AI7: =SUM(AI8:AI8) -> 0 | AK7: =SUM(AK8:AK8) -> 0 | AM7: =SUM(AM8:AM8) -> 0 | AO7: =SUM(AO8:AO8) -> 0 | AQ7: =SUM(AQ8:AQ8) -> 0 | AS7: =SUM(AS8:AS8) -> 0 | AU7: =SUM(AU8:AU8) -> 0 | AW7: =SUM(AW8:AW8) -> 0 | AY7: =SUM(AY8:AY8) -> 0 | BA7: =SUM(BA8:BA8) -> 0 | BC7: =SUM(BC8:BC8) -> 0
A8: 1.1.1 | B8: RECURSOS MATERIAIS PARA ADMINISTRAÇÃO LOCAL | C8: N/A | D8: N/A | E8: N/A | F8: N/A | G8: N/A | H8: N/A | I8: CANTEIRO | J8: OUTROS | K8: 0173003001001 | L8: MATERIAL | M8: RECURSOS MATERIAIS PARA ADMINISTRAÇÃO LOCAL (MATERIAIS DE CONSUMO, ÁGUA, ENERGIA ELÉTRICA E COMUNICAÇÃO) - TIPO 2 | N8: MES | O8: 18 | P8: 1578.72 | Q8: =ROUND(P8*$O8,2) -> 28416.96 | R8: =IFERROR(SUMIFS('BM MORRO DA CRUZ - VERTICAL'!V$6:V$546,'BM MORRO DA CRUZ - VERTICAL'!$O$6:$O$546,'BM MORRO DA CRUZ'!$K8),0) -> 0 | S8: =ROUND(R8*$P8,2) -> 0 | T8: =IFERROR(SUMIFS('BM MORRO DA CRUZ - VERTICAL'!X$6:X$546,'BM MORRO DA CRUZ - VERTICAL'!$O$6:$O$546,'BM MORRO DA CRUZ'!$K8),0) -> 0 | U8: =ROUND(T8*$P8,2) -> 0 | V8: =IFERROR(SUMIFS('BM MORRO DA CRUZ - VERTICAL'!Z$6:Z$546,'BM MORRO DA CRUZ - VERTICAL'!$O$6:$O$546,'BM MORRO DA CRUZ'!$K8),0) -> 0 | W8: =ROUND(V8*$P8,2) -> 0 | X8: =IFERROR(SUMIFS('BM MORRO DA CRUZ - VERTICAL'!AB$6:AB$546,'BM MORRO DA CRUZ - VERTICAL'!$O$6:$O$546,'BM MORRO DA CRUZ'!$K8),0) -> 0 | Y8: =ROUND(X8*$P8,2) -> 0 | Z8: =IFERROR(SUMIFS('BM MORRO DA CRUZ - VERTICAL'!AD$6:AD$546,'BM MORRO DA CRUZ - VERTICAL'!$O$6:$O$546,'BM MORRO DA CRUZ'!$K8),0) -> 0 | AA8: =ROUND(Z8*$P8,2) -> 0 | AB8: =IFERROR(SUMIFS('BM MORRO DA CRUZ - VERTICAL'!AF$6:AF$546,'BM MORRO DA CRUZ - VERTICAL'!$O$6:$O$546,'BM MORRO DA CRUZ'!$K8),0) -> 0 | AC8: =ROUND(AB8*$P8,2) -> 0 | AD8: =IFERROR(SUMIFS('BM MORRO DA CRUZ - VERTICAL'!AH$6:AH$546,'BM MORRO DA CRUZ - VERTICAL'!$O$6:$O$546,'BM MORRO DA CRUZ'!$K8),0) -> 0 | AE8: =ROUND(AD8*$P8,2) -> 0 | AF8: =IFERROR(SUMIFS('BM MORRO DA CRUZ - VERTICAL'!AJ$6:AJ$546,'BM MORRO DA CRUZ - VERTICAL'!$O$6:$O$546,'BM MORRO DA CRUZ'!$K8),0) -> 0 | AG8: =ROUND(AF8*$P8,2) -> 0 | AH8: =IFERROR(SUMIFS('BM MORRO DA CRUZ - VERTICAL'!AL$6:AL$546,'BM MORRO DA CRUZ - VERTICAL'!$O$6:$O$546,'BM MORRO DA CRUZ'!$K8),0) -> 0 | AI8: =ROUND(AH8*$P8,2) -> 0 | AJ8: =IFERROR(SUMIFS('BM MORRO DA CRUZ - VERTICAL'!AN$6:AN$546,'BM MORRO DA CRUZ - VERTICAL'!$O$6:$O$546,'BM MORRO DA CRUZ'!$K8),0) -> 0 | AK8: =ROUND(AJ8*$P8,2) -> 0 | AL8: =IFERROR(SUMIFS('BM MORRO DA CRUZ - VERTICAL'!AP$6:AP$546,'BM MORRO DA CRUZ - VERTICAL'!$O$6:$O$546,'BM MORRO DA CRUZ'!$K8),0) -> 0 | AM8: =ROUND(AL8*$P8,2) -> 0 | AN8: =IFERROR(SUMIFS('BM MORRO DA CRUZ - VERTICAL'!AR$6:AR$546,'BM MORRO DA CRUZ - VERTICAL'!$O$6:$O$546,'BM MORRO DA CRUZ'!$K8),0) -> 0 | AO8: =ROUND(AN8*$P8,2) -> 0 | AP8: =IFERROR(SUMIFS('BM MORRO DA CRUZ - VERTICAL'!AT$6:AT$546,'BM MORRO DA CRUZ - VERTICAL'!$O$6:$O$546,'BM MORRO DA CRUZ'!$K8),0) -> 0 | AQ8: =ROUND(AP8*$P8,2) -> 0 | AR8: =IFERROR(SUMIFS('BM MORRO DA CRUZ - VERTICAL'!AV$6:AV$546,'BM MORRO DA CRUZ - VERTICAL'!$O$6:$O$546,'BM MORRO DA CRUZ'!$K8),0) -> 0 | AS8: =ROUND(AR8*$P8,2) -> 0 | AT8: =IFERROR(SUMIFS('BM MORRO DA CRUZ - VERTICAL'!AX$6:AX$546,'BM MORRO DA CRUZ - VERTICAL'!$O$6:$O$546,'BM MORRO DA CRUZ'!$K8),0) -> 0 | AU8: =ROUND(AT8*$P8,2) -> 0 | AV8: =IFERROR(SUMIFS('BM MORRO DA CRUZ - VERTICAL'!AZ$6:AZ$546,'BM MORRO DA CRUZ - VERTICAL'!$O$6:$O$546,'BM MORRO DA CRUZ'!$K8),0) -> 0 | AW8: =ROUND(AV8*$P8,2) -> 0 | AX8: =IFERROR(SUMIFS('BM MORRO DA CRUZ - VERTICAL'!BB$6:BB$546,'BM MORRO DA CRUZ - VERTICAL'!$O$6:$O$546,'BM MORRO DA CRUZ'!$K8),0) -> 0 | AY8: =ROUND(AX8*$P8,2) -> 0 | AZ8: =IFERROR(SUMIFS('BM MORRO DA CRUZ - VERTICAL'!BD$6:BD$546,'BM MORRO DA CRUZ - VERTICAL'!$O$6:$O$546,'BM MORRO DA CRUZ'!$K8),0) -> 0 | BA8: =ROUND(AZ8*$P8,2) -> 0 | BB8: =IFERROR(SUMIFS($R8:$BA8,$R$5:$BA$5,$BB$5),0) -> 0 | BC8: =SUMIFS($R8:$BA8,$R$5:$BA$5,$S$5) -> 0 | BD8: =IFERROR(BB8/O8,0) -> 0 | BE8: =IFERROR((O8-BB8)/O8,0) -> 1
A9: 1.2 | K9: 01741 | M9: CONSERVAÇÃO E LIMPEZA | Q9: =SUM(Q10:Q11) -> 1105693.9 | S9: =SUM(S10:S11) -> 0 | U9: =SUM(U10:U11) -> 0 | W9: =SUM(W10:W11) -> 0 | Y9: =SUM(Y10:Y11) -> 0 | AA9: =SUM(AA10:AA11) -> 0 | AC9: =SUM(AC10:AC11) -> 0 | AE9: =SUM(AE10:AE11) -> 0 | AG9: =SUM(AG10:AG11) -> 0 | AI9: =SUM(AI10:AI11) -> 0 | AK9: =SUM(AK10:AK11) -> 0 | AM9: =SUM(AM10:AM11) -> 0 | AO9: =SUM(AO10:AO11) -> 0 | AQ9: =SUM(AQ10:AQ11) -> 0 | AS9: =SUM(AS10:AS11) -> 0 | AU9: =SUM(AU10:AU11) -> 0 | AW9: =SUM(AW10:AW11) -> 0 | AY9: =SUM(AY10:AY11) -> 0 | BA9: =SUM(BA10:BA11) -> 0 | BC9: =SUM(BC10:BC11) -> 0
A10: 1.2.1 | B10: TAXA DISPOSIÇÃO FINAL RCC - NÃO SEGREGADOS | C10: N/A | D10: N/A | E10: N/A | F10: N/A | G10: N/A | H10: N/A | I10: REDES/LIGAÇÕES | J10: DESCARTE | K10: 0174103006001 | L10: MATERIAL | M10: TAXA PARA DISPOSIÇÃO FINAL DE RESÍDUOS DA CONSTRUÇÃO CIVIL NÃO SEGREGADOS, CONFORME RESOLUÇÃO ADASA N° 45/2024, A PARTIR DE 01/01/2025. | N10: T | O10: 204.27 | P10: 28.42 | Q10: =ROUND(P10*$O10,2) -> 5805.35 | R10: =IFERROR(SUMIFS('BM MORRO DA CRUZ - VERTICAL'!V$6:V$546,'BM MORRO DA CRUZ - VERTICAL'!$O$6:$O$546,'BM MORRO DA CRUZ'!$K10),0) -> 0 | S10: =ROUND(R10*$P10,2) -> 0 | T10: =IFERROR(SUMIFS('BM MORRO DA CRUZ - VERTICAL'!X$6:X$546,'BM MORRO DA CRUZ - VERTICAL'!$O$6:$O$546,'BM MORRO DA CRUZ'!$K10),0) -> 0 | U10: =ROUND(T10*$P10,2) -> 0 | V10: =IFERROR(SUMIFS('BM MORRO DA CRUZ - VERTICAL'!Z$6:Z$546,'BM MORRO DA CRUZ - VERTICAL'!$O$6:$O$546,'BM MORRO DA CRUZ'!$K10),0) -> 0 | W10: =ROUND(V10*$P10,2) -> 0 | X10: =IFERROR(SUMIFS('BM MORRO DA CRUZ - VERTICAL'!AB$6:AB$546,'BM MORRO DA CRUZ - VERTICAL'!$O$6:$O$546,'BM MORRO DA CRUZ'!$K10),0) -> 0 | Y10: =ROUND(X10*$P10,2) -> 0 | Z10: =IFERROR(SUMIFS('BM MORRO DA CRUZ - VERTICAL'!AD$6:AD$546,'BM MORRO DA CRUZ - VERTICAL'!$O$6:$O$546,'BM MORRO DA CRUZ'!$K10),0) -> 0 | AA10: =ROUND(Z10*$P10,2) -> 0 | AB10: =IFERROR(SUMIFS('BM MORRO DA CRUZ - VERTICAL'!AF$6:AF$546,'BM MORRO DA CRUZ - VERTICAL'!$O$6:$O$546,'BM MORRO DA CRUZ'!$K10),0) -> 0 | AC10: =ROUND(AB10*$P10,2) -> 0 | AD10: =IFERROR(SUMIFS('BM MORRO DA CRUZ - VERTICAL'!AH$6:AH$546,'BM MORRO DA CRUZ - VERTICAL'!$O$6:$O$546,'BM MORRO DA CRUZ'!$K10),0) -> 0 | AE10: =ROUND(AD10*$P10,2) -> 0 | AF10: =IFERROR(SUMIFS('BM MORRO DA CRUZ - VERTICAL'!AJ$6:AJ$546,'BM MORRO DA CRUZ - VERTICAL'!$O$6:$O$546,'BM MORRO DA CRUZ'!$K10),0) -> 0 | AG10: =ROUND(AF10*$P10,2) -> 0 | AH10: =IFERROR(SUMIFS('BM MORRO DA CRUZ - VERTICAL'!AL$6:AL$546,'BM MORRO DA CRUZ - VERTICAL'!$O$6:$O$546,'BM MORRO DA CRUZ'!$K10),0) -> 0 | AI10: =ROUND(AH10*$P10,2) -> 0 | AJ10: =IFERROR(SUMIFS('BM MORRO DA CRUZ - VERTICAL'!AN$6:AN$546,'BM MORRO DA CRUZ - VERTICAL'!$O$6:$O$546,'BM MORRO DA CRUZ'!$K10),0) -> 0 | AK10: =ROUND(AJ10*$P10,2) -> 0 | AL10: =IFERROR(SUMIFS('BM MORRO DA CRUZ - VERTICAL'!AP$6:AP$546,'BM MORRO DA CRUZ - VERTICAL'!$O$6:$O$546,'BM MORRO DA CRUZ'!$K10),0) -> 0 | AM10: =ROUND(AL10*$P10,2) -> 0 | AN10: =IFERROR(SUMIFS('BM MORRO DA CRUZ - VERTICAL'!AR$6:AR$546,'BM MORRO DA CRUZ - VERTICAL'!$O$6:$O$546,'BM MORRO DA CRUZ'!$K10),0) -> 0 | AO10: =ROUND(AN10*$P10,2) -> 0 | AP10: =IFERROR(SUMIFS('BM MORRO DA CRUZ - VERTICAL'!AT$6:AT$546,'BM MORRO DA CRUZ - VERTICAL'!$O$6:$O$546,'BM MORRO DA CRUZ'!$K10),0) -> 0 | AQ10: =ROUND(AP10*$P10,2) -> 0 | AR10: =IFERROR(SUMIFS('BM MORRO DA CRUZ - VERTICAL'!AV$6:AV$546,'BM MORRO DA CRUZ - VERTICAL'!$O$6:$O$546,'BM MORRO DA CRUZ'!$K10),0) -> 0 | AS10: =ROUND(AR10*$P10,2) -> 0 | AT10: =IFERROR(SUMIFS('BM MORRO DA CRUZ - VERTICAL'!AX$6:AX$546,'BM MORRO DA CRUZ - VERTICAL'!$O$6:$O$546,'BM MORRO DA CRUZ'!$K10),0) -> 0 | AU10: =ROUND(AT10*$P10,2) -> 0 | AV10: =IFERROR(SUMIFS('BM MORRO DA CRUZ - VERTICAL'!AZ$6:AZ$546,'BM MORRO DA CRUZ - VERTICAL'!$O$6:$O$546,'BM MORRO DA CRUZ'!$K10),0) -> 0 | AW10: =ROUND(AV10*$P10,2) -> 0 | AX10: =IFERROR(SUMIFS('BM MORRO DA CRUZ - VERTICAL'!BB$6:BB$546,'BM MORRO DA CRUZ - VERTICAL'!$O$6:$O$546,'BM MORRO DA CRUZ'!$K10),0) -> 0 | AY10: =ROUND(AX10*$P10,2) -> 0 | AZ10: =IFERROR(SUMIFS('BM MORRO DA CRUZ - VERTICAL'!BD$6:BD$546,'BM MORRO DA CRUZ - VERTICAL'!$O$6:$O$546,'BM MORRO DA CRUZ'!$K10),0) -> 0 | BA10: =ROUND(AZ10*$P10,2) -> 0 | BB10: =IFERROR(SUMIFS($R10:$BA10,$R$5:$BA$5,$BB$5),0) -> 0 | BC10: =SUMIFS($R10:$BA10,$R$5:$BA$5,$S$5) -> 0 | BD10: =IFERROR(BB10/O10,0) -> 0 | BE10: =IFERROR((O10-BB10)/O10,0) -> 1
A11: 1.2.2 | B11: TAXA DISPOSIÇÃO FINAL RCC - SEGREGADOS | C11: N/A | D11: N/A | E11: N/A | F11: N/A | G11: N/A | H11: N/A | I11: CANTEIRO/REDES/CAIXAS/INTERLIGAÇÃO | J11: DESCARTE | K11: 0174103006002 | L11: MATERIAL | M11: TAXA PARA DISPOSIÇÃO FINAL DE RESÍDUOS DA CONSTRUÇÃO CIVIL SEGREGADOS, CONFORME RESOLUÇÃO ADASA N° 45/2024, A PARTIR DE 01/01/2025. | N11: T | O11: 64208.32 | P11: 17.13 | Q11: =ROUND(P11*$O11,2) -> 1099888.5 | R11: =IFERROR(SUMIFS('BM MORRO DA CRUZ - VERTICAL'!V$6:V$546,'BM MORRO DA CRUZ - VERTICAL'!$O$6:$O$546,'BM MORRO DA CRUZ'!$K11),0) -> 0 | S11: =ROUND(R11*$P11,2) -> 0 | T11: =IFERROR(SUMIFS('BM MORRO DA CRUZ - VERTICAL'!X$6:X$546,'BM MORRO DA CRUZ - VERTICAL'!$O$6:$O$546,'BM MORRO DA CRUZ'!$K11),0) -> 0 | U11: =ROUND(T11*$P11,2) -> 0 | V11: =IFERROR(SUMIFS('BM MORRO DA CRUZ - VERTICAL'!Z$6:Z$546,'BM MORRO DA CRUZ - VERTICAL'!$O$6:$O$546,'BM MORRO DA CRUZ'!$K11),0) -> 0 | W11: =ROUND(V11*$P11,2) -> 0 | X11: =IFERROR(SUMIFS('BM MORRO DA CRUZ - VERTICAL'!AB$6:AB$546,'BM MORRO DA CRUZ - VERTICAL'!$O$6:$O$546,'BM MORRO DA CRUZ'!$K11),0) -> 0 | Y11: =ROUND(X11*$P11,2) -> 0 | Z11: =IFERROR(SUMIFS('BM MORRO DA CRUZ - VERTICAL'!AD$6:AD$546,'BM MORRO DA CRUZ - VERTICAL'!$O$6:$O$546,'BM MORRO DA CRUZ'!$K11),0) -> 0 | AA11: =ROUND(Z11*$P11,2) -> 0 | AB11: =IFERROR(SUMIFS('BM MORRO DA CRUZ - VERTICAL'!AF$6:AF$546,'BM MORRO DA CRUZ - VERTICAL'!$O$6:$O$546,'BM MORRO DA CRUZ'!$K11),0) -> 0 | AC11: =ROUND(AB11*$P11,2) -> 0 | AD11: =IFERROR(SUMIFS('BM MORRO DA CRUZ - VERTICAL'!AH$6:AH$546,'BM MORRO DA CRUZ - VERTICAL'!$O$6:$O$546,'BM MORRO DA CRUZ'!$K11),0) -> 0 | AE11: =ROUND(AD11*$P11,2) -> 0 | AF11: =IFERROR(SUMIFS('BM MORRO DA CRUZ - VERTICAL'!AJ$6:AJ$546,'BM MORRO DA CRUZ - VERTICAL'!$O$6:$O$546,'BM MORRO DA CRUZ'!$K11),0) -> 0 | AG11: =ROUND(AF11*$P11,2) -> 0 | AH11: =IFERROR(SUMIFS('BM MORRO DA CRUZ - VERTICAL'!AL$6:AL$546,'BM MORRO DA CRUZ - VERTICAL'!$O$6:$O$546,'BM MORRO DA CRUZ'!$K11),0) -> 0 | AI11: =ROUND(AH11*$P11,2) -> 0 | AJ11: =IFERROR(SUMIFS('BM MORRO DA CRUZ - VERTICAL'!AN$6:AN$546,'BM MORRO DA CRUZ - VERTICAL'!$O$6:$O$546,'BM MORRO DA CRUZ'!$K11),0) -> 0 | AK11: =ROUND(AJ11*$P11,2) -> 0 | AL11: =IFERROR(SUMIFS('BM MORRO DA CRUZ - VERTICAL'!AP$6:AP$546,'BM MORRO DA CRUZ - VERTICAL'!$O$6:$O$546,'BM MORRO DA CRUZ'!$K11),0) -> 0 | AM11: =ROUND(AL11*$P11,2) -> 0 | AN11: =IFERROR(SUMIFS('BM MORRO DA CRUZ - VERTICAL'!AR$6:AR$546,'BM MORRO DA CRUZ - VERTICAL'!$O$6:$O$546,'BM MORRO DA CRUZ'!$K11),0) -> 0 | AO11: =ROUND(AN11*$P11,2) -> 0 | AP11: =IFERROR(SUMIFS('BM MORRO DA CRUZ - VERTICAL'!AT$6:AT$546,'BM MORRO DA CRUZ - VERTICAL'!$O$6:$O$546,'BM MORRO DA CRUZ'!$K11),0) -> 0 | AQ11: =ROUND(AP11*$P11,2) -> 0 | AR11: =IFERROR(SUMIFS('BM MORRO DA CRUZ - VERTICAL'!AV$6:AV$546,'BM MORRO DA CRUZ - VERTICAL'!$O$6:$O$546,'BM MORRO DA CRUZ'!$K11),0) -> 0 | AS11: =ROUND(AR11*$P11,2) -> 0 | AT11: =IFERROR(SUMIFS('BM MORRO DA CRUZ - VERTICAL'!AX$6:AX$546,'BM MORRO DA CRUZ - VERTICAL'!$O$6:$O$546,'BM MORRO DA CRUZ'!$K11),0) -> 0 | AU11: =ROUND(AT11*$P11,2) -> 0 | AV11: =IFERROR(SUMIFS('BM MORRO DA CRUZ - VERTICAL'!AZ$6:AZ$546,'BM MORRO DA CRUZ - VERTICAL'!$O$6:$O$546,'BM MORRO DA CRUZ'!$K11),0) -> 0 | AW11: =ROUND(AV11*$P11,2) -> 0 | AX11: =IFERROR(SUMIFS('BM MORRO DA CRUZ - VERTICAL'!BB$6:BB$546,'BM MORRO DA CRUZ - VERTICAL'!$O$6:$O$546,'BM MORRO DA CRUZ'!$K11),0) -> 0 | AY11: =ROUND(AX11*$P11,2) -> 0 | AZ11: =IFERROR(SUMIFS('BM MORRO DA CRUZ - VERTICAL'!BD$6:BD$546,'BM MORRO DA CRUZ - VERTICAL'!$O$6:$O$546,'BM MORRO DA CRUZ'!$K11),0) -> 0 | BA11: =ROUND(AZ11*$P11,2) -> 0 | BB11: =IFERROR(SUMIFS($R11:$BA11,$R$5:$BA$5,$BB$5),0) -> 0 | BC11: =SUMIFS($R11:$BA11,$R$5:$BA$5,$S$5) -> 0 | BD11: =IFERROR(BB11/O11,0) -> 0 | BE11: =IFERROR((O11-BB11)/O11,0) -> 1
A12: 1.3 | K12: 02510 | M12: FORNECIMENTO DE ÁGUA | Q12: =SUM(Q13:Q13) -> 2080260.6 | S12: =SUM(S13:S13) -> 0 | U12: =SUM(U13:U13) -> 0 | W12: =SUM(W13:W13) -> 0 | Y12: =SUM(Y13:Y13) -> 0 | AA12: =SUM(AA13:AA13) -> 0 | AC12: =SUM(AC13:AC13) -> 0 | AE12: =SUM(AE13:AE13) -> 0 | AG12: =SUM(AG13:AG13) -> 0 | AI12: =SUM(AI13:AI13) -> 0 | AK12: =SUM(AK13:AK13) -> 0 | AM12: =SUM(AM13:AM13) -> 0 | AO12: =SUM(AO13:AO13) -> 0 | AQ12: =SUM(AQ13:AQ13) -> 0 | AS12: =SUM(AS13:AS13) -> 0 | AU12: =SUM(AU13:AU13) -> 0 | AW12: =SUM(AW13:AW13) -> 0 | AY12: =SUM(AY13:AY13) -> 0 | BA12: =SUM(BA13:BA13) -> 0 | BC12: =SUM(BC13:BC13) -> 0
A13: 1.3.1 | B13: KIT CAVALETE 3/4" UNIVERSAL | C13: N/A | D13: N/A | E13: KIT CAVALETE | F13: N/A | G13: 3/4" | H13: LATÃO | I13: LIGAÇÕES | J13: OUTROS | K13: 0251003002006 | L13: MATERIAL | M13: KIT CAVALETE 3/4" UNIVERSAL, HÍBRIDO PADRÃO CAESB EM LATÃO FORJADO COM BASE PARA FIXAÇÃO, EXCLUSIVE HIDRÔMETRO. | N13: UN | O13: 11894 | P13: 174.9 | Q13: =ROUND(P13*$O13,2) -> 2080260.6 | R13: =IFERROR(SUMIFS('BM MORRO DA CRUZ - VERTICAL'!V$6:V$546,'BM MORRO DA CRUZ - VERTICAL'!$O$6:$O$546,'BM MORRO DA CRUZ'!$K13),0) -> 0 | S13: =ROUND(R13*$P13,2) -> 0 | T13: =IFERROR(SUMIFS('BM MORRO DA CRUZ - VERTICAL'!X$6:X$546,'BM MORRO DA CRUZ - VERTICAL'!$O$6:$O$546,'BM MORRO DA CRUZ'!$K13),0) -> 0 | U13: =ROUND(T13*$P13,2) -> 0 | V13: =IFERROR(SUMIFS('BM MORRO DA CRUZ - VERTICAL'!Z$6:Z$546,'BM MORRO DA CRUZ - VERTICAL'!$O$6:$O$546,'BM MORRO DA CRUZ'!$K13),0) -> 0 | W13: =ROUND(V13*$P13,2) -> 0 | X13: =IFERROR(SUMIFS('BM MORRO DA CRUZ - VERTICAL'!AB$6:AB$546,'BM MORRO DA CRUZ - VERTICAL'!$O$6:$O$546,'BM MORRO DA CRUZ'!$K13),0) -> 0 | Y13: =ROUND(X13*$P13,2) -> 0 | Z13: =IFERROR(SUMIFS('BM MORRO DA CRUZ - VERTICAL'!AD$6:AD$546,'BM MORRO DA CRUZ - VERTICAL'!$O$6:$O$546,'BM MORRO DA CRUZ'!$K13),0) -> 0 | AA13: =ROUND(Z13*$P13,2) -> 0 | AB13: =IFERROR(SUMIFS('BM MORRO DA CRUZ - VERTICAL'!AF$6:AF$546,'BM MORRO DA CRUZ - VERTICAL'!$O$6:$O$546,'BM MORRO DA CRUZ'!$K13),0) -> 0 | AC13: =ROUND(AB13*$P13,2) -> 0 | AD13: =IFERROR(SUMIFS('BM MORRO DA CRUZ - VERTICAL'!AH$6:AH$546,'BM MORRO DA CRUZ - VERTICAL'!$O$6:$O$546,'BM MORRO DA CRUZ'!$K13),0) -> 0 | AE13: =ROUND(AD13*$P13,2) -> 0 | AF13: =IFERROR(SUMIFS('BM MORRO DA CRUZ - VERTICAL'!AJ$6:AJ$546,'BM MORRO DA CRUZ - VERTICAL'!$O$6:$O$546,'BM MORRO DA CRUZ'!$K13),0) -> 0 | AG13: =ROUND(AF13*$P13,2) -> 0 | AH13: =IFERROR(SUMIFS('BM MORRO DA CRUZ - VERTICAL'!AL$6:AL$546,'BM MORRO DA CRUZ - VERTICAL'!$O$6:$O$546,'BM MORRO DA CRUZ'!$K13),0) -> 0 | AI13: =ROUND(AH13*$P13,2) -> 0 | AJ13: =IFERROR(SUMIFS('BM MORRO DA CRUZ - VERTICAL'!AN$6:AN$546,'BM MORRO DA CRUZ - VERTICAL'!$O$6:$O$546,'BM MORRO DA CRUZ'!$K13),0) -> 0 | AK13: =ROUND(AJ13*$P13,2) -> 0 | AL13: =IFERROR(SUMIFS('BM MORRO DA CRUZ - VERTICAL'!AP$6:AP$546,'BM MORRO DA CRUZ - VERTICAL'!$O$6:$O$546,'BM MORRO DA CRUZ'!$K13),0) -> 0 | AM13: =ROUND(AL13*$P13,2) -> 0 | AN13: =IFERROR(SUMIFS('BM MORRO DA CRUZ - VERTICAL'!AR$6:AR$546,'BM MORRO DA CRUZ - VERTICAL'!$O$6:$O$546,'BM MORRO DA CRUZ'!$K13),0) -> 0 | AO13: =ROUND(AN13*$P13,2) -> 0 | AP13: =IFERROR(SUMIFS('BM MORRO DA CRUZ - VERTICAL'!AT$6:AT$546,'BM MORRO DA CRUZ - VERTICAL'!$O$6:$O$546,'BM MORRO DA CRUZ'!$K13),0) -> 0 | AQ13: =ROUND(AP13*$P13,2) -> 0 | AR13: =IFERROR(SUMIFS('BM MORRO DA CRUZ - VERTICAL'!AV$6:AV$546,'BM MORRO DA CRUZ - VERTICAL'!$O$6:$O$546,'BM MORRO DA CRUZ'!$K13),0) -> 0 | AS13: =ROUND(AR13*$P13,2) -> 0 | AT13: =IFERROR(SUMIFS('BM MORRO DA CRUZ - VERTICAL'!AX$6:AX$546,'BM MORRO DA CRUZ - VERTICAL'!$O$6:$O$546,'BM MORRO DA CRUZ'!$K13),0) -> 0 | AU13: =ROUND(AT13*$P13,2) -> 0 | AV13: =IFERROR(SUMIFS('BM MORRO DA CRUZ - VERTICAL'!AZ$6:AZ$546,'BM MORRO DA CRUZ - VERTICAL'!$O$6:$O$546,'BM MORRO DA CRUZ'!$K13),0) -> 0 | AW13: =ROUND(AV13*$P13,2) -> 0 | AX13: =IFERROR(SUMIFS('BM MORRO DA CRUZ - VERTICAL'!BB$6:BB$546,'BM MORRO DA CRUZ - VERTICAL'!$O$6:$O$546,'BM MORRO DA CRUZ'!$K13),0) -> 0 | AY13: =ROUND(AX13*$P13,2) -> 0 | AZ13: =IFERROR(SUMIFS('BM MORRO DA CRUZ - VERTICAL'!BD$6:BD$546,'BM MORRO DA CRUZ - VERTICAL'!$O$6:$O$546,'BM MORRO DA CRUZ'!$K13),0) -> 0 | BA13: =ROUND(AZ13*$P13,2) -> 0 | BB13: =IFERROR(SUMIFS($R13:$BA13,$R$5:$BA$5,$BB$5),0) -> 0 | BC13: =SUMIFS($R13:$BA13,$R$5:$BA$5,$S$5) -> 0 | BD13: =IFERROR(BB13/O13,0) -> 0 | BE13: =IFERROR((O13-BB13)/O13,0) -> 1
A14: 1.4 | K14: 02630 | M14: DRENAGEM DE ÁGUAS PLUVIAIS | Q14: =SUM(Q15:Q15) -> 18953.72 | S14: =SUM(S15:S15) -> 0 | U14: =SUM(U15:U15) -> 0 | W14: =SUM(W15:W15) -> 0 | Y14: =SUM(Y15:Y15) -> 0 | AA14: =SUM(AA15:AA15) -> 0 | AC14: =SUM(AC15:AC15) -> 0 | AE14: =SUM(AE15:AE15) -> 0 | AG14: =SUM(AG15:AG15) -> 0 | AI14: =SUM(AI15:AI15) -> 0 | AK14: =SUM(AK15:AK15) -> 0 | AM14: =SUM(AM15:AM15) -> 0 | AO14: =SUM(AO15:AO15) -> 0 | AQ14: =SUM(AQ15:AQ15) -> 0 | AS14: =SUM(AS15:AS15) -> 0 | AU14: =SUM(AU15:AU15) -> 0 | AW14: =SUM(AW15:AW15) -> 0 | AY14: =SUM(AY15:AY15) -> 0 | BA14: =SUM(BA15:BA15) -> 0 | BC14: =SUM(BC15:BC15) -> 0
A15: 1.4.1 | B15: TAMPA DE CONCRETO ARMADO PARA CAIXA DE INSPEÇÃO | C15: N/A | D15: N/A | E15: TAMPA | F15: N/A | G15: 600 | H15: CONCRETO | I15: CAIXAS | J15: CONCRETO | K15: 0263003006007 | L15: MATERIAL | M15: TAMPA DE CONCRETO ARMADO PARA CAIXA DE INSPEÇÃO (DIÂMETRO NOMINAL: 600 MM / ESPESSURA: 60 MM) | N15: UN | O15: 146 | P15: 129.82 | Q15: =ROUND(P15*$O15,2) -> 18953.72 | R15: =IFERROR(SUMIFS('BM MORRO DA CRUZ - VERTICAL'!V$6:V$546,'BM MORRO DA CRUZ - VERTICAL'!$O$6:$O$546,'BM MORRO DA CRUZ'!$K15),0) -> 0 | S15: =ROUND(R15*$P15,2) -> 0 | T15: =IFERROR(SUMIFS('BM MORRO DA CRUZ - VERTICAL'!X$6:X$546,'BM MORRO DA CRUZ - VERTICAL'!$O$6:$O$546,'BM MORRO DA CRUZ'!$K15),0) -> 0 | U15: =ROUND(T15*$P15,2) -> 0 | V15: =IFERROR(SUMIFS('BM MORRO DA CRUZ - VERTICAL'!Z$6:Z$546,'BM MORRO DA CRUZ - VERTICAL'!$O$6:$O$546,'BM MORRO DA CRUZ'!$K15),0) -> 0 | W15: =ROUND(V15*$P15,2) -> 0 | X15: =IFERROR(SUMIFS('BM MORRO DA CRUZ - VERTICAL'!AB$6:AB$546,'BM MORRO DA CRUZ - VERTICAL'!$O$6:$O$546,'BM MORRO DA CRUZ'!$K15),0) -> 0 | Y15: =ROUND(X15*$P15,2) -> 0 | Z15: =IFERROR(SUMIFS('BM MORRO DA CRUZ - VERTICAL'!AD$6:AD$546,'BM MORRO DA CRUZ - VERTICAL'!$O$6:$O$546,'BM MORRO DA CRUZ'!$K15),0) -> 0 | AA15: =ROUND(Z15*$P15,2) -> 0 | AB15: =IFERROR(SUMIFS('BM MORRO DA CRUZ - VERTICAL'!AF$6:AF$546,'BM MORRO DA CRUZ - VERTICAL'!$O$6:$O$546,'BM MORRO DA CRUZ'!$K15),0) -> 0 | AC15: =ROUND(AB15*$P15,2) -> 0 | AD15: =IFERROR(SUMIFS('BM MORRO DA CRUZ - VERTICAL'!AH$6:AH$546,'BM MORRO DA CRUZ - VERTICAL'!$O$6:$O$546,'BM MORRO DA CRUZ'!$K15),0) -> 0 | AE15: =ROUND(AD15*$P15,2) -> 0 | AF15: =IFERROR(SUMIFS('BM MORRO DA CRUZ - VERTICAL'!AJ$6:AJ$546,'BM MORRO DA CRUZ - VERTICAL'!$O$6:$O$546,'BM MORRO DA CRUZ'!$K15),0) -> 0 | AG15: =ROUND(AF15*$P15,2) -> 0 | AH15: =IFERROR(SUMIFS('BM MORRO DA CRUZ - VERTICAL'!AL$6:AL$546,'BM MORRO DA CRUZ - VERTICAL'!$O$6:$O$546,'BM MORRO DA CRUZ'!$K15),0) -> 0 | AI15: =ROUND(AH15*$P15,2) -> 0 | AJ15: =IFERROR(SUMIFS('BM MORRO DA CRUZ - VERTICAL'!AN$6:AN$546,'BM MORRO DA CRUZ - VERTICAL'!$O$6:$O$546,'BM MORRO DA CRUZ'!$K15),0) -> 0 | AK15: =ROUND(AJ15*$P15,2) -> 0 | AL15: =IFERROR(SUMIFS('BM MORRO DA CRUZ - VERTICAL'!AP$6:AP$546,'BM MORRO DA CRUZ - VERTICAL'!$O$6:$O$546,'BM MORRO DA CRUZ'!$K15),0) -> 0 | AM15: =ROUND(AL15*$P15,2) -> 0 | AN15: =IFERROR(SUMIFS('BM MORRO DA CRUZ - VERTICAL'!AR$6:AR$546,'BM MORRO DA CRUZ - VERTICAL'!$O$6:$O$546,'BM MORRO DA CRUZ'!$K15),0) -> 0 | AO15: =ROUND(AN15*$P15,2) -> 0 | AP15: =IFERROR(SUMIFS('BM MORRO DA CRUZ - VERTICAL'!AT$6:AT$546,'BM MORRO DA CRUZ - VERTICAL'!$O$6:$O$546,'BM MORRO DA CRUZ'!$K15),0) -> 0 | AQ15: =ROUND(AP15*$P15,2) -> 0 | AR15: =IFERROR(SUMIFS('BM MORRO DA CRUZ - VERTICAL'!AV$6:AV$546,'BM MORRO DA CRUZ - VERTICAL'!$O$6:$O$546,'BM MORRO DA CRUZ'!$K15),0) -> 0 | AS15: =ROUND(AR15*$P15,2) -> 0 | AT15: =IFERROR(SUMIFS('BM MORRO DA CRUZ - VERTICAL'!AX$6:AX$546,'BM MORRO DA CRUZ - VERTICAL'!$O$6:$O$546,'BM MORRO DA CRUZ'!$K15),0) -> 0 | AU15: =ROUND(AT15*$P15,2) -> 0 | AV15: =IFERROR(SUMIFS('BM MORRO DA CRUZ - VERTICAL'!AZ$6:AZ$546,'BM MORRO DA CRUZ - VERTICAL'!$O$6:$O$546,'BM MORRO DA CRUZ'!$K15),0) -> 0 | AW15: =ROUND(AV15*$P15,2) -> 0 | AX15: =IFERROR(SUMIFS('BM MORRO DA CRUZ - VERTICAL'!BB$6:BB$546,'BM MORRO DA CRUZ - VERTICAL'!$O$6:$O$546,'BM MORRO DA CRUZ'!$K15),0) -> 0 | AY15: =ROUND(AX15*$P15,2) -> 0 | AZ15: =IFERROR(SUMIFS('BM MORRO DA CRUZ - VERTICAL'!BD$6:BD$546,'BM MORRO DA CRUZ - VERTICAL'!$O$6:$O$546,'BM MORRO DA CRUZ'!$K15),0) -> 0 | BA15: =ROUND(AZ15*$P15,2) -> 0 | BB15: =IFERROR(SUMIFS($R15:$BA15,$R$5:$BA$5,$BB$5),0) -> 0 | BC15: =SUMIFS($R15:$BA15,$R$5:$BA$5,$S$5) -> 0 | BD15: =IFERROR(BB15/O15,0) -> 0 | BE15: =IFERROR((O15-BB15)/O15,0) -> 1
A16: 1.5 | K16: 03480 | M16: CONCRETOS PRÉ-MOLDADOS | Q16: =SUM(Q17:Q17) -> 6211998.3 | S16: =SUM(S17:S17) -> 0 | U16: =SUM(U17:U17) -> 0 | W16: =SUM(W17:W17) -> 0 | Y16: =SUM(Y17:Y17) -> 0 | AA16: =SUM(AA17:AA17) -> 0 | AC16: =SUM(AC17:AC17) -> 0 | AE16: =SUM(AE17:AE17) -> 0 | AG16: =SUM(AG17:AG17) -> 0 | AI16: =SUM(AI17:AI17) -> 0 | AK16: =SUM(AK17:AK17) -> 0 | AM16: =SUM(AM17:AM17) -> 0 | AO16: =SUM(AO17:AO17) -> 0 | AQ16: =SUM(AQ17:AQ17) -> 0 | AS16: =SUM(AS17:AS17) -> 0 | AU16: =SUM(AU17:AU17) -> 0 | AW16: =SUM(AW17:AW17) -> 0 | AY16: =SUM(AY17:AY17) -> 0 | BA16: =SUM(BA17:BA17) -> 0 | BC16: =SUM(BC17:BC17) -> 0
A17: 1.5.1 | B17: ABRIGO/MURETA PRÉ-MOLDADA P/ 02 HIDRÔMETROS | C17: N/A | D17: N/A | E17: MURETA | F17: N/A | G17: 50 | H17: PVC | I17: LIGAÇÕES | J17: CONCRETO | K17: 0348003003016 | L17: MATERIAL | M17: ABRIGO/MURETA PRÉ-MOLDADA DE CONCRETO ARMADO FCK = 25 MPA PADRÃO CAESB COM CAIXA DE POLICARBONATO PARA DOIS HIDRÔMETROS INSTALADA. MEDIDAS DO REQUADRO: 0,70 X 0,60 X 0,15 M. MEDIDAS DOS PILARES: 0,16 X 0,64 X 0,15 M. MEDIDAS EXTERNAS: 0,70 X 1,24 X 0,15 M. PREVISÃO DE TUBOS DE PVC COM DIÂMETRO DE 50 MM: UM COM COMPRIMENTO DE 0,75 M PARA ENTRADA E DOIS COM COMPRIMENTO DE 0,11 M PARA SAÍDAS | N17: UN | O17: 11894 | P17: 522.28 | Q17: =ROUND(P17*$O17,2) -> 6211998.3 | R17: =IFERROR(SUMIFS('BM MORRO DA CRUZ - VERTICAL'!V$6:V$546,'BM MORRO DA CRUZ - VERTICAL'!$O$6:$O$546,'BM MORRO DA CRUZ'!$K17),0) -> 0 | S17: =ROUND(R17*$P17,2) -> 0 | T17: =IFERROR(SUMIFS('BM MORRO DA CRUZ - VERTICAL'!X$6:X$546,'BM MORRO DA CRUZ - VERTICAL'!$O$6:$O$546,'BM MORRO DA CRUZ'!$K17),0) -> 0 | U17: =ROUND(T17*$P17,2) -> 0 | V17: =IFERROR(SUMIFS('BM MORRO DA CRUZ - VERTICAL'!Z$6:Z$546,'BM MORRO DA CRUZ - VERTICAL'!$O$6:$O$546,'BM MORRO DA CRUZ'!$K17),0) -> 0 | W17: =ROUND(V17*$P17,2) -> 0 | X17: =IFERROR(SUMIFS('BM MORRO DA CRUZ - VERTICAL'!AB$6:AB$546,'BM MORRO DA CRUZ - VERTICAL'!$O$6:$O$546,'BM MORRO DA CRUZ'!$K17),0) -> 0 | Y17: =ROUND(X17*$P17,2) -> 0 | Z17: =IFERROR(SUMIFS('BM MORRO DA CRUZ - VERTICAL'!AD$6:AD$546,'BM MORRO DA CRUZ - VERTICAL'!$O$6:$O$546,'BM MORRO DA CRUZ'!$K17),0) -> 0 | AA17: =ROUND(Z17*$P17,2) -> 0 | AB17: =IFERROR(SUMIFS('BM MORRO DA CRUZ - VERTICAL'!AF$6:AF$546,'BM MORRO DA CRUZ - VERTICAL'!$O$6:$O$546,'BM MORRO DA CRUZ'!$K17),0) -> 0 | AC17: =ROUND(AB17*$P17,2) -> 0 | AD17: =IFERROR(SUMIFS('BM MORRO DA CRUZ - VERTICAL'!AH$6:AH$546,'BM MORRO DA CRUZ - VERTICAL'!$O$6:$O$546,'BM MORRO DA CRUZ'!$K17),0) -> 0 | AE17: =ROUND(AD17*$P17,2) -> 0 | AF17: =IFERROR(SUMIFS('BM MORRO DA CRUZ - VERTICAL'!AJ$6:AJ$546,'BM MORRO DA CRUZ - VERTICAL'!$O$6:$O$546,'BM MORRO DA CRUZ'!$K17),0) -> 0 | AG17: =ROUND(AF17*$P17,2) -> 0 | AH17: =IFERROR(SUMIFS('BM MORRO DA CRUZ - VERTICAL'!AL$6:AL$546,'BM MORRO DA CRUZ - VERTICAL'!$O$6:$O$546,'BM MORRO DA CRUZ'!$K17),0) -> 0 | AI17: =ROUND(AH17*$P17,2) -> 0 | AJ17: =IFERROR(SUMIFS('BM MORRO DA CRUZ - VERTICAL'!AN$6:AN$546,'BM MORRO DA CRUZ - VERTICAL'!$O$6:$O$546,'BM MORRO DA CRUZ'!$K17),0) -> 0 | AK17: =ROUND(AJ17*$P17,2) -> 0 | AL17: =IFERROR(SUMIFS('BM MORRO DA CRUZ - VERTICAL'!AP$6:AP$546,'BM MORRO DA CRUZ - VERTICAL'!$O$6:$O$546,'BM MORRO DA CRUZ'!$K17),0) -> 0 | AM17: =ROUND(AL17*$P17,2) -> 0 | AN17: =IFERROR(SUMIFS('BM MORRO DA CRUZ - VERTICAL'!AR$6:AR$546,'BM MORRO DA CRUZ - VERTICAL'!$O$6:$O$546,'BM MORRO DA CRUZ'!$K17),0) -> 0 | AO17: =ROUND(AN17*$P17,2) -> 0 | AP17: =IFERROR(SUMIFS('BM MORRO DA CRUZ - VERTICAL'!AT$6:AT$546,'BM MORRO DA CRUZ - VERTICAL'!$O$6:$O$546,'BM MORRO DA CRUZ'!$K17),0) -> 0 | AQ17: =ROUND(AP17*$P17,2) -> 0 | AR17: =IFERROR(SUMIFS('BM MORRO DA CRUZ - VERTICAL'!AV$6:AV$546,'BM MORRO DA CRUZ - VERTICAL'!$O$6:$O$546,'BM MORRO DA CRUZ'!$K17),0) -> 0 | AS17: =ROUND(AR17*$P17,2) -> 0 | AT17: =IFERROR(SUMIFS('BM MORRO DA CRUZ - VERTICAL'!AX$6:AX$546,'BM MORRO DA CRUZ - VERTICAL'!$O$6:$O$546,'BM MORRO DA CRUZ'!$K17),0) -> 0 | AU17: =ROUND(AT17*$P17,2) -> 0 | AV17: =IFERROR(SUMIFS('BM MORRO DA CRUZ - VERTICAL'!AZ$6:AZ$546,'BM MORRO DA CRUZ - VERTICAL'!$O$6:$O$546,'BM MORRO DA CRUZ'!$K17),0) -> 0 | AW17: =ROUND(AV17*$P17,2) -> 0 | AX17: =IFERROR(SUMIFS('BM MORRO DA CRUZ - VERTICAL'!BB$6:BB$546,'BM MORRO DA CRUZ - VERTICAL'!$O$6:$O$546,'BM MORRO DA CRUZ'!$K17),0) -> 0 | AY17: =ROUND(AX17*$P17,2) -> 0 | AZ17: =IFERROR(SUMIFS('BM MORRO DA CRUZ - VERTICAL'!BD$6:BD$546,'BM MORRO DA CRUZ - VERTICAL'!$O$6:$O$546,'BM MORRO DA CRUZ'!$K17),0) -> 0 | BA17: =ROUND(AZ17*$P17,2) -> 0 | BB17: =IFERROR(SUMIFS($R17:$BA17,$R$5:$BA$5,$BB$5),0) -> 0 | BC17: =SUMIFS($R17:$BA17,$R$5:$BA$5,$S$5) -> 0 | BD17: =IFERROR(BB17/O17,0) -> 0 | BE17: =IFERROR((O17-BB17)/O17,0) -> 1
A18: 1.6 | K18: 10180 | M18: COBERTURAS | Q18: =SUM(Q19:Q19) -> 5200 | S18: =SUM(S19:S19) -> 0 | U18: =SUM(U19:U19) -> 0 | W18: =SUM(W19:W19) -> 0 | Y18: =SUM(Y19:Y19) -> 0 | AA18: =SUM(AA19:AA19) -> 0 | AC18: =SUM(AC19:AC19) -> 0 | AE18: =SUM(AE19:AE19) -> 0 | AG18: =SUM(AG19:AG19) -> 0 | AI18: =SUM(AI19:AI19) -> 0 | AK18: =SUM(AK19:AK19) -> 0 | AM18: =SUM(AM19:AM19) -> 0 | AO18: =SUM(AO19:AO19) -> 0 | AQ18: =SUM(AQ19:AQ19) -> 0 | AS18: =SUM(AS19:AS19) -> 0 | AU18: =SUM(AU19:AU19) -> 0 | AW18: =SUM(AW19:AW19) -> 0 | AY18: =SUM(AY19:AY19) -> 0 | BA18: =SUM(BA19:BA19) -> 0 | BC18: =SUM(BC19:BC19) -> 0
A19: 1.6.1 | B19: TENDA PIRAMIDAL 3,00 X 3,00 M COM FECHAMENTOS LATERAIS | C19: N/A | D19: N/A | E19: TENDA | F19: N/A | G19: 3,00X3,00 | H19: LONA PVC | I19: CANTEIRO | J19: CANTEIRO | K19: 1018003001001 | L19: MATERIAL | M19: TENDA PIRAMIDAL 3,00 X 3,00 M COM FECHAMENTOS LATERAIS | N19: UN | O19: 2 | P19: 2600 | Q19: =ROUND(P19*$O19,2) -> 5200 | R19: =IFERROR(SUMIFS('BM MORRO DA CRUZ - VERTICAL'!V$6:V$546,'BM MORRO DA CRUZ - VERTICAL'!$O$6:$O$546,'BM MORRO DA CRUZ'!$K19),0) -> 0 | S19: =ROUND(R19*$P19,2) -> 0 | T19: =IFERROR(SUMIFS('BM MORRO DA CRUZ - VERTICAL'!X$6:X$546,'BM MORRO DA CRUZ - VERTICAL'!$O$6:$O$546,'BM MORRO DA CRUZ'!$K19),0) -> 0 | U19: =ROUND(T19*$P19,2) -> 0 | V19: =IFERROR(SUMIFS('BM MORRO DA CRUZ - VERTICAL'!Z$6:Z$546,'BM MORRO DA CRUZ - VERTICAL'!$O$6:$O$546,'BM MORRO DA CRUZ'!$K19),0) -> 0 | W19: =ROUND(V19*$P19,2) -> 0 | X19: =IFERROR(SUMIFS('BM MORRO DA CRUZ - VERTICAL'!AB$6:AB$546,'BM MORRO DA CRUZ - VERTICAL'!$O$6:$O$546,'BM MORRO DA CRUZ'!$K19),0) -> 0 | Y19: =ROUND(X19*$P19,2) -> 0 | Z19: =IFERROR(SUMIFS('BM MORRO DA CRUZ - VERTICAL'!AD$6:AD$546,'BM MORRO DA CRUZ - VERTICAL'!$O$6:$O$546,'BM MORRO DA CRUZ'!$K19),0) -> 0 | AA19: =ROUND(Z19*$P19,2) -> 0 | AB19: =IFERROR(SUMIFS('BM MORRO DA CRUZ - VERTICAL'!AF$6:AF$546,'BM MORRO DA CRUZ - VERTICAL'!$O$6:$O$546,'BM MORRO DA CRUZ'!$K19),0) -> 0 | AC19: =ROUND(AB19*$P19,2) -> 0 | AD19: =IFERROR(SUMIFS('BM MORRO DA CRUZ - VERTICAL'!AH$6:AH$546,'BM MORRO DA CRUZ - VERTICAL'!$O$6:$O$546,'BM MORRO DA CRUZ'!$K19),0) -> 0 | AE19: =ROUND(AD19*$P19,2) -> 0 | AF19: =IFERROR(SUMIFS('BM MORRO DA CRUZ - VERTICAL'!AJ$6:AJ$546,'BM MORRO DA CRUZ - VERTICAL'!$O$6:$O$546,'BM MORRO DA CRUZ'!$K19),0) -> 0 | AG19: =ROUND(AF19*$P19,2) -> 0 | AH19: =IFERROR(SUMIFS('BM MORRO DA CRUZ - VERTICAL'!AL$6:AL$546,'BM MORRO DA CRUZ - VERTICAL'!$O$6:$O$546,'BM MORRO DA CRUZ'!$K19),0) -> 0 | AI19: =ROUND(AH19*$P19,2) -> 0 | AJ19: =IFERROR(SUMIFS('BM MORRO DA CRUZ - VERTICAL'!AN$6:AN$546,'BM MORRO DA CRUZ - VERTICAL'!$O$6:$O$546,'BM MORRO DA CRUZ'!$K19),0) -> 0 | AK19: =ROUND(AJ19*$P19,2) -> 0 | AL19: =IFERROR(SUMIFS('BM MORRO DA CRUZ - VERTICAL'!AP$6:AP$546,'BM MORRO DA CRUZ - VERTICAL'!$O$6:$O$546,'BM MORRO DA CRUZ'!$K19),0) -> 0 | AM19: =ROUND(AL19*$P19,2) -> 0 | AN19: =IFERROR(SUMIFS('BM MORRO DA CRUZ - VERTICAL'!AR$6:AR$546,'BM MORRO DA CRUZ - VERTICAL'!$O$6:$O$546,'BM MORRO DA CRUZ'!$K19),0) -> 0 | AO19: =ROUND(AN19*$P19,2) -> 0 | AP19: =IFERROR(SUMIFS('BM MORRO DA CRUZ - VERTICAL'!AT$6:AT$546,'BM MORRO DA CRUZ - VERTICAL'!$O$6:$O$546,'BM MORRO DA CRUZ'!$K19),0) -> 0 | AQ19: =ROUND(AP19*$P19,2) -> 0 | AR19: =IFERROR(SUMIFS('BM MORRO DA CRUZ - VERTICAL'!AV$6:AV$546,'BM MORRO DA CRUZ - VERTICAL'!$O$6:$O$546,'BM MORRO DA CRUZ'!$K19),0) -> 0 | AS19: =ROUND(AR19*$P19,2) -> 0 | AT19: =IFERROR(SUMIFS('BM MORRO DA CRUZ - VERTICAL'!AX$6:AX$546,'BM MORRO DA CRUZ - VERTICAL'!$O$6:$O$546,'BM MORRO DA CRUZ'!$K19),0) -> 0 | AU19: =ROUND(AT19*$P19,2) -> 0 | AV19: =IFERROR(SUMIFS('BM MORRO DA CRUZ - VERTICAL'!AZ$6:AZ$546,'BM MORRO DA CRUZ - VERTICAL'!$O$6:$O$546,'BM MORRO DA CRUZ'!$K19),0) -> 0 | AW19: =ROUND(AV19*$P19,2) -> 0 | AX19: =IFERROR(SUMIFS('BM MORRO DA CRUZ - VERTICAL'!BB$6:BB$546,'BM MORRO DA CRUZ - VERTICAL'!$O$6:$O$546,'BM MORRO DA CRUZ'!$K19),0) -> 0 | AY19: =ROUND(AX19*$P19,2) -> 0 | AZ19: =IFERROR(SUMIFS('BM MORRO DA CRUZ - VERTICAL'!BD$6:BD$546,'BM MORRO DA CRUZ - VERTICAL'!$O$6:$O$546,'BM MORRO DA CRUZ'!$K19),0) -> 0 | BA19: =ROUND(AZ19*$P19,2) -> 0 | BB19: =IFERROR(SUMIFS($R19:$BA19,$R$5:$BA$5,$BB$5),0) -> 0 | BC19: =SUMIFS($R19:$BA19,$R$5:$BA$5,$S$5) -> 0 | BD19: =IFERROR(BB19/O19,0) -> 0 | BE19: =IFERROR((O19-BB19)/O19,0) -> 1
A20: 1.7 | K20: 12510 | M20: MÓVEIS PARA ESCRITÓRIO | Q20: =SUM(Q21:Q21) -> 8892.18 | S20: =SUM(S21:S21) -> 0 | U20: =SUM(U21:U21) -> 0 | W20: =SUM(W21:W21) -> 0 | Y20: =SUM(Y21:Y21) -> 0 | AA20: =SUM(AA21:AA21) -> 0 | AC20: =SUM(AC21:AC21) -> 0 | AE20: =SUM(AE21:AE21) -> 0 | AG20: =SUM(AG21:AG21) -> 0 | AI20: =SUM(AI21:AI21) -> 0 | AK20: =SUM(AK21:AK21) -> 0 | AM20: =SUM(AM21:AM21) -> 0 | AO20: =SUM(AO21:AO21) -> 0 | AQ20: =SUM(AQ21:AQ21) -> 0 | AS20: =SUM(AS21:AS21) -> 0 | AU20: =SUM(AU21:AU21) -> 0 | AW20: =SUM(AW21:AW21) -> 0 | AY20: =SUM(AY21:AY21) -> 0 | BA20: =SUM(BA21:BA21) -> 0 | BC20: =SUM(BC21:BC21) -> 0
A21: 1.7.1 | B21: INFRAESTRUTURA BÁSICA PARA FISCALIZAÇÃO | C21: N/A | D21: N/A | E21: N/A | F21: N/A | G21: N/A | H21: N/A | I21: CANTEIRO | J21: CANTEIRO | K21: 1251003008004 | L21: MATERIAL | M21: INFRAESTRUTURA BÁSICA PARA FISCALIZAÇÃO INCLUINDO NO MÍNIMO OS ITENS A SEGUIR: MÓVEIS E EQUIPAMENTOS (DUAS MESAS, QUATRO CADEIRAS, UM PURIFICADOR DE ÁGUA, UM APARELHO DE AR CONDICIONADO 7500 BTUS, UM NOTEBOOK INTEL CORE I7, 12GB, SSD 256GB, TELA COM RESOLUÇÃO MÍNIMA 1920X1080P, WINDOWS 10 OU VERSÕES SUPERIORES, COM PACOTE MICROSOFT OFFICE 360 E ACESSO À INTERNET). | N21: MES | O21: 18 | P21: 494.01 | Q21: =ROUND(P21*$O21,2) -> 8892.18 | R21: =IFERROR(SUMIFS('BM MORRO DA CRUZ - VERTICAL'!V$6:V$546,'BM MORRO DA CRUZ - VERTICAL'!$O$6:$O$546,'BM MORRO DA CRUZ'!$K21),0) -> 0 | S21: =ROUND(R21*$P21,2) -> 0 | T21: =IFERROR(SUMIFS('BM MORRO DA CRUZ - VERTICAL'!X$6:X$546,'BM MORRO DA CRUZ - VERTICAL'!$O$6:$O$546,'BM MORRO DA CRUZ'!$K21),0) -> 0 | U21: =ROUND(T21*$P21,2) -> 0 | V21: =IFERROR(SUMIFS('BM MORRO DA CRUZ - VERTICAL'!Z$6:Z$546,'BM MORRO DA CRUZ - VERTICAL'!$O$6:$O$546,'BM MORRO DA CRUZ'!$K21),0) -> 0 | W21: =ROUND(V21*$P21,2) -> 0 | X21: =IFERROR(SUMIFS('BM MORRO DA CRUZ - VERTICAL'!AB$6:AB$546,'BM MORRO DA CRUZ - VERTICAL'!$O$6:$O$546,'BM MORRO DA CRUZ'!$K21),0) -> 0 | Y21: =ROUND(X21*$P21,2) -> 0 | Z21: =IFERROR(SUMIFS('BM MORRO DA CRUZ - VERTICAL'!AD$6:AD$546,'BM MORRO DA CRUZ - VERTICAL'!$O$6:$O$546,'BM MORRO DA CRUZ'!$K21),0) -> 0 | AA21: =ROUND(Z21*$P21,2) -> 0 | AB21: =IFERROR(SUMIFS('BM MORRO DA CRUZ - VERTICAL'!AF$6:AF$546,'BM MORRO DA CRUZ - VERTICAL'!$O$6:$O$546,'BM MORRO DA CRUZ'!$K21),0) -> 0 | AC21: =ROUND(AB21*$P21,2) -> 0 | AD21: =IFERROR(SUMIFS('BM MORRO DA CRUZ - VERTICAL'!AH$6:AH$546,'BM MORRO DA CRUZ - VERTICAL'!$O$6:$O$546,'BM MORRO DA CRUZ'!$K21),0) -> 0 | AE21: =ROUND(AD21*$P21,2) -> 0 | AF21: =IFERROR(SUMIFS('BM MORRO DA CRUZ - VERTICAL'!AJ$6:AJ$546,'BM MORRO DA CRUZ - VERTICAL'!$O$6:$O$546,'BM MORRO DA CRUZ'!$K21),0) -> 0 | AG21: =ROUND(AF21*$P21,2) -> 0 | AH21: =IFERROR(SUMIFS('BM MORRO DA CRUZ - VERTICAL'!AL$6:AL$546,'BM MORRO DA CRUZ - VERTICAL'!$O$6:$O$546,'BM MORRO DA CRUZ'!$K21),0) -> 0 | AI21: =ROUND(AH21*$P21,2) -> 0 | AJ21: =IFERROR(SUMIFS('BM MORRO DA CRUZ - VERTICAL'!AN$6:AN$546,'BM MORRO DA CRUZ - VERTICAL'!$O$6:$O$546,'BM MORRO DA CRUZ'!$K21),0) -> 0 | AK21: =ROUND(AJ21*$P21,2) -> 0 | AL21: =IFERROR(SUMIFS('BM MORRO DA CRUZ - VERTICAL'!AP$6:AP$546,'BM MORRO DA CRUZ - VERTICAL'!$O$6:$O$546,'BM MORRO DA CRUZ'!$K21),0) -> 0 | AM21: =ROUND(AL21*$P21,2) -> 0 | AN21: =IFERROR(SUMIFS('BM MORRO DA CRUZ - VERTICAL'!AR$6:AR$546,'BM MORRO DA CRUZ - VERTICAL'!$O$6:$O$546,'BM MORRO DA CRUZ'!$K21),0) -> 0 | AO21: =ROUND(AN21*$P21,2) -> 0 | AP21: =IFERROR(SUMIFS('BM MORRO DA CRUZ - VERTICAL'!AT$6:AT$546,'BM MORRO DA CRUZ - VERTICAL'!$O$6:$O$546,'BM MORRO DA CRUZ'!$K21),0) -> 0 | AQ21: =ROUND(AP21*$P21,2) -> 0 | AR21: =IFERROR(SUMIFS('BM MORRO DA CRUZ - VERTICAL'!AV$6:AV$546,'BM MORRO DA CRUZ - VERTICAL'!$O$6:$O$546,'BM MORRO DA CRUZ'!$K21),0) -> 0 | AS21: =ROUND(AR21*$P21,2) -> 0 | AT21: =IFERROR(SUMIFS('BM MORRO DA CRUZ - VERTICAL'!AX$6:AX$546,'BM MORRO DA CRUZ - VERTICAL'!$O$6:$O$546,'BM MORRO DA CRUZ'!$K21),0) -> 0 | AU21: =ROUND(AT21*$P21,2) -> 0 | AV21: =IFERROR(SUMIFS('BM MORRO DA CRUZ - VERTICAL'!AZ$6:AZ$546,'BM MORRO DA CRUZ - VERTICAL'!$O$6:$O$546,'BM MORRO DA CRUZ'!$K21),0) -> 0 | AW21: =ROUND(AV21*$P21,2) -> 0 | AX21: =IFERROR(SUMIFS('BM MORRO DA CRUZ - VERTICAL'!BB$6:BB$546,'BM MORRO DA CRUZ - VERTICAL'!$O$6:$O$546,'BM MORRO DA CRUZ'!$K21),0) -> 0 | AY21: =ROUND(AX21*$P21,2) -> 0 | AZ21: =IFERROR(SUMIFS('BM MORRO DA CRUZ - VERTICAL'!BD$6:BD$546,'BM MORRO DA CRUZ - VERTICAL'!$O$6:$O$546,'BM MORRO DA CRUZ'!$K21),0) -> 0 | BA21: =ROUND(AZ21*$P21,2) -> 0 | BB21: =IFERROR(SUMIFS($R21:$BA21,$R$5:$BA$5,$BB$5),0) -> 0 | BC21: =SUMIFS($R21:$BA21,$R$5:$BA$5,$S$5) -> 0 | BD21: =IFERROR(BB21/O21,0) -> 0 | BE21: =IFERROR((O21-BB21)/O21,0) -> 1
A22: 1.8 | K22: 15002 | M22: ACESSÓRIOS PARA TRATAMENTO DE ÁGUA | Q22: =SUM(Q23:Q23) -> 147.3 | S22: =SUM(S23:S23) -> 0 | U22: =SUM(U23:U23) -> 0 | W22: =SUM(W23:W23) -> 0 | Y22: =SUM(Y23:Y23) -> 0 | AA22: =SUM(AA23:AA23) -> 0 | AC22: =SUM(AC23:AC23) -> 0 | AE22: =SUM(AE23:AE23) -> 0 | AG22: =SUM(AG23:AG23) -> 0 | AI22: =SUM(AI23:AI23) -> 0 | AK22: =SUM(AK23:AK23) -> 0 | AM22: =SUM(AM23:AM23) -> 0 | AO22: =SUM(AO23:AO23) -> 0 | AQ22: =SUM(AQ23:AQ23) -> 0 | AS22: =SUM(AS23:AS23) -> 0 | AU22: =SUM(AU23:AU23) -> 0 | AW22: =SUM(AW23:AW23) -> 0 | AY22: =SUM(AY23:AY23) -> 0 | BA22: =SUM(BA23:BA23) -> 0 | BC22: =SUM(BC23:BC23) -> 0
A23: 1.8.1 | B23: ARRUELA BORRACHA S/ ALMA METÁLICA (ABF) | C23: PN10 | D23: N/A | E23: ARRUELA | F23: N/A | G23: 200 | H23: BORRACHA | I23: HIDROMECÂNICO | J23: FOFO | K23: 1500203055014 | L23: MATERIAL | M23: ACESSÓRIO PARA FLANGE: ARRUELA DE BORRACHA SEM ALMA METÁLICA (ABF), COM ELASTÔMERO SBR, EXCLUSIVO PARA ÁGUA (CLASSE DE PRESSÃO: 10 KGF/CM² / DIÂMETRO DA SEÇÃO: 200 MM) | N23: UN | O23: 15 | P23: 9.82 | Q23: =ROUND(P23*$O23,2) -> 147.3 | R23: =IFERROR(SUMIFS('BM MORRO DA CRUZ - VERTICAL'!V$6:V$546,'BM MORRO DA CRUZ - VERTICAL'!$O$6:$O$546,'BM MORRO DA CRUZ'!$K23),0) -> 0 | S23: =ROUND(R23*$P23,2) -> 0 | T23: =IFERROR(SUMIFS('BM MORRO DA CRUZ - VERTICAL'!X$6:X$546,'BM MORRO DA CRUZ - VERTICAL'!$O$6:$O$546,'BM MORRO DA CRUZ'!$K23),0) -> 0 | U23: =ROUND(T23*$P23,2) -> 0 | V23: =IFERROR(SUMIFS('BM MORRO DA CRUZ - VERTICAL'!Z$6:Z$546,'BM MORRO DA CRUZ - VERTICAL'!$O$6:$O$546,'BM MORRO DA CRUZ'!$K23),0) -> 0 | W23: =ROUND(V23*$P23,2) -> 0 | X23: =IFERROR(SUMIFS('BM MORRO DA CRUZ - VERTICAL'!AB$6:AB$546,'BM MORRO DA CRUZ - VERTICAL'!$O$6:$O$546,'BM MORRO DA CRUZ'!$K23),0) -> 0 | Y23: =ROUND(X23*$P23,2) -> 0 | Z23: =IFERROR(SUMIFS('BM MORRO DA CRUZ - VERTICAL'!AD$6:AD$546,'BM MORRO DA CRUZ - VERTICAL'!$O$6:$O$546,'BM MORRO DA CRUZ'!$K23),0) -> 0 | AA23: =ROUND(Z23*$P23,2) -> 0 | AB23: =IFERROR(SUMIFS('BM MORRO DA CRUZ - VERTICAL'!AF$6:AF$546,'BM MORRO DA CRUZ - VERTICAL'!$O$6:$O$546,'BM MORRO DA CRUZ'!$K23),0) -> 0 | AC23: =ROUND(AB23*$P23,2) -> 0 | AD23: =IFERROR(SUMIFS('BM MORRO DA CRUZ - VERTICAL'!AH$6:AH$546,'BM MORRO DA CRUZ - VERTICAL'!$O$6:$O$546,'BM MORRO DA CRUZ'!$K23),0) -> 0 | AE23: =ROUND(AD23*$P23,2) -> 0 | AF23: =IFERROR(SUMIFS('BM MORRO DA CRUZ - VERTICAL'!AJ$6:AJ$546,'BM MORRO DA CRUZ - VERTICAL'!$O$6:$O$546,'BM MORRO DA CRUZ'!$K23),0) -> 0 | AG23: =ROUND(AF23*$P23,2) -> 0 | AH23: =IFERROR(SUMIFS('BM MORRO DA CRUZ - VERTICAL'!AL$6:AL$546,'BM MORRO DA CRUZ - VERTICAL'!$O$6:$O$546,'BM MORRO DA CRUZ'!$K23),0) -> 0 | AI23: =ROUND(AH23*$P23,2) -> 0 | AJ23: =IFERROR(SUMIFS('BM MORRO DA CRUZ - VERTICAL'!AN$6:AN$546,'BM MORRO DA CRUZ - VERTICAL'!$O$6:$O$546,'BM MORRO DA CRUZ'!$K23),0) -> 0 | AK23: =ROUND(AJ23*$P23,2) -> 0 | AL23: =IFERROR(SUMIFS('BM MORRO DA CRUZ - VERTICAL'!AP$6:AP$546,'BM MORRO DA CRUZ - VERTICAL'!$O$6:$O$546,'BM MORRO DA CRUZ'!$K23),0) -> 0 | AM23: =ROUND(AL23*$P23,2) -> 0 | AN23: =IFERROR(SUMIFS('BM MORRO DA CRUZ - VERTICAL'!AR$6:AR$546,'BM MORRO DA CRUZ - VERTICAL'!$O$6:$O$546,'BM MORRO DA CRUZ'!$K23),0) -> 0 | AO23: =ROUND(AN23*$P23,2) -> 0 | AP23: =IFERROR(SUMIFS('BM MORRO DA CRUZ - VERTICAL'!AT$6:AT$546,'BM MORRO DA CRUZ - VERTICAL'!$O$6:$O$546,'BM MORRO DA CRUZ'!$K23),0) -> 0 | AQ23: =ROUND(AP23*$P23,2) -> 0 | AR23: =IFERROR(SUMIFS('BM MORRO DA CRUZ - VERTICAL'!AV$6:AV$546,'BM MORRO DA CRUZ - VERTICAL'!$O$6:$O$546,'BM MORRO DA CRUZ'!$K23),0) -> 0 | AS23: =ROUND(AR23*$P23,2) -> 0 | AT23: =IFERROR(SUMIFS('BM MORRO DA CRUZ - VERTICAL'!AX$6:AX$546,'BM MORRO DA CRUZ - VERTICAL'!$O$6:$O$546,'BM MORRO DA CRUZ'!$K23),0) -> 0 | AU23: =ROUND(AT23*$P23,2) -> 0 | AV23: =IFERROR(SUMIFS('BM MORRO DA CRUZ - VERTICAL'!AZ$6:AZ$546,'BM MORRO DA CRUZ - VERTICAL'!$O$6:$O$546,'BM MORRO DA CRUZ'!$K23),0) -> 0 | AW23: =ROUND(AV23*$P23,2) -> 0 | AX23: =IFERROR(SUMIFS('BM MORRO DA CRUZ - VERTICAL'!BB$6:BB$546,'BM MORRO DA CRUZ - VERTICAL'!$O$6:$O$546,'BM MORRO DA CRUZ'!$K23),0) -> 0 | AY23: =ROUND(AX23*$P23,2) -> 0 | AZ23: =IFERROR(SUMIFS('BM MORRO DA CRUZ - VERTICAL'!BD$6:BD$546,'BM MORRO DA CRUZ - VERTICAL'!$O$6:$O$546,'BM MORRO DA CRUZ'!$K23),0) -> 0 | BA23: =ROUND(AZ23*$P23,2) -> 0 | BB23: =IFERROR(SUMIFS($R23:$BA23,$R$5:$BA$5,$BB$5),0) -> 0 | BC23: =SUMIFS($R23:$BA23,$R$5:$BA$5,$S$5) -> 0 | BD23: =IFERROR(BB23/O23,0) -> 0 | BE23: =IFERROR((O23-BB23)/O23,0) -> 1
A24: 1.9 | K24: 15055 | M24: TAMPÕES E CAIXAS PARA MANUTENÇÃO DE REDES | Q24: =SUM(Q25:Q25) -> 53243.68 | S24: =SUM(S25:S25) -> 0 | U24: =SUM(U25:U25) -> 0 | W24: =SUM(W25:W25) -> 0 | Y24: =SUM(Y25:Y25) -> 0 | AA24: =SUM(AA25:AA25) -> 0 | AC24: =SUM(AC25:AC25) -> 0 | AE24: =SUM(AE25:AE25) -> 0 | AG24: =SUM(AG25:AG25) -> 0 | AI24: =SUM(AI25:AI25) -> 0 | AK24: =SUM(AK25:AK25) -> 0 | AM24: =SUM(AM25:AM25) -> 0 | AO24: =SUM(AO25:AO25) -> 0 | AQ24: =SUM(AQ25:AQ25) -> 0 | AS24: =SUM(AS25:AS25) -> 0 | AU24: =SUM(AU25:AU25) -> 0 | AW24: =SUM(AW25:AW25) -> 0 | AY24: =SUM(AY25:AY25) -> 0 | BA24: =SUM(BA25:BA25) -> 0 | BC24: =SUM(BC25:BC25) -> 0
A25: 1.9.1 | B25: TAMPA FºFº BIARTICULADA - T2RBI | C25: N/A | D25: N/A | E25: TAMPA BIARTICULADA | F25: N/A | G25: 1285X980 | H25: FºFº | I25: HIDROMECÂNICO | J25: TAMPÃO | K25: 1505503002016 | L25: MATERIAL | M25: TAMPA METÁLICA BIARTICULADA, FERRO FUNDIDO, MODELO T2RBI | N25: UN | O25: 28 | P25: 1901.56 | Q25: =ROUND(P25*$O25,2) -> 53243.68 | R25: =IFERROR(SUMIFS('BM MORRO DA CRUZ - VERTICAL'!V$6:V$546,'BM MORRO DA CRUZ - VERTICAL'!$O$6:$O$546,'BM MORRO DA CRUZ'!$K25),0) -> 0 | S25: =ROUND(R25*$P25,2) -> 0 | T25: =IFERROR(SUMIFS('BM MORRO DA CRUZ - VERTICAL'!X$6:X$546,'BM MORRO DA CRUZ - VERTICAL'!$O$6:$O$546,'BM MORRO DA CRUZ'!$K25),0) -> 0 | U25: =ROUND(T25*$P25,2) -> 0 | V25: =IFERROR(SUMIFS('BM MORRO DA CRUZ - VERTICAL'!Z$6:Z$546,'BM MORRO DA CRUZ - VERTICAL'!$O$6:$O$546,'BM MORRO DA CRUZ'!$K25),0) -> 0 | W25: =ROUND(V25*$P25,2) -> 0 | X25: =IFERROR(SUMIFS('BM MORRO DA CRUZ - VERTICAL'!AB$6:AB$546,'BM MORRO DA CRUZ - VERTICAL'!$O$6:$O$546,'BM MORRO DA CRUZ'!$K25),0) -> 0 | Y25: =ROUND(X25*$P25,2) -> 0 | Z25: =IFERROR(SUMIFS('BM MORRO DA CRUZ - VERTICAL'!AD$6:AD$546,'BM MORRO DA CRUZ - VERTICAL'!$O$6:$O$546,'BM MORRO DA CRUZ'!$K25),0) -> 0 | AA25: =ROUND(Z25*$P25,2) -> 0 | AB25: =IFERROR(SUMIFS('BM MORRO DA CRUZ - VERTICAL'!AF$6:AF$546,'BM MORRO DA CRUZ - VERTICAL'!$O$6:$O$546,'BM MORRO DA CRUZ'!$K25),0) -> 0 | AC25: =ROUND(AB25*$P25,2) -> 0 | AD25: =IFERROR(SUMIFS('BM MORRO DA CRUZ - VERTICAL'!AH$6:AH$546,'BM MORRO DA CRUZ - VERTICAL'!$O$6:$O$546,'BM MORRO DA CRUZ'!$K25),0) -> 0 | AE25: =ROUND(AD25*$P25,2) -> 0 | AF25: =IFERROR(SUMIFS('BM MORRO DA CRUZ - VERTICAL'!AJ$6:AJ$546,'BM MORRO DA CRUZ - VERTICAL'!$O$6:$O$546,'BM MORRO DA CRUZ'!$K25),0) -> 0 | AG25: =ROUND(AF25*$P25,2) -> 0 | AH25: =IFERROR(SUMIFS('BM MORRO DA CRUZ - VERTICAL'!AL$6:AL$546,'BM MORRO DA CRUZ - VERTICAL'!$O$6:$O$546,'BM MORRO DA CRUZ'!$K25),0) -> 0 | AI25: =ROUND(AH25*$P25,2) -> 0 | AJ25: =IFERROR(SUMIFS('BM MORRO DA CRUZ - VERTICAL'!AN$6:AN$546,'BM MORRO DA CRUZ - VERTICAL'!$O$6:$O$546,'BM MORRO DA CRUZ'!$K25),0) -> 0 | AK25: =ROUND(AJ25*$P25,2) -> 0 | AL25: =IFERROR(SUMIFS('BM MORRO DA CRUZ - VERTICAL'!AP$6:AP$546,'BM MORRO DA CRUZ - VERTICAL'!$O$6:$O$546,'BM MORRO DA CRUZ'!$K25),0) -> 0 | AM25: =ROUND(AL25*$P25,2) -> 0 | AN25: =IFERROR(SUMIFS('BM MORRO DA CRUZ - VERTICAL'!AR$6:AR$546,'BM MORRO DA CRUZ - VERTICAL'!$O$6:$O$546,'BM MORRO DA CRUZ'!$K25),0) -> 0 | AO25: =ROUND(AN25*$P25,2) -> 0 | AP25: =IFERROR(SUMIFS('BM MORRO DA CRUZ - VERTICAL'!AT$6:AT$546,'BM MORRO DA CRUZ - VERTICAL'!$O$6:$O$546,'BM MORRO DA CRUZ'!$K25),0) -> 0 | AQ25: =ROUND(AP25*$P25,2) -> 0 | AR25: =IFERROR(SUMIFS('BM MORRO DA CRUZ - VERTICAL'!AV$6:AV$546,'BM MORRO DA CRUZ - VERTICAL'!$O$6:$O$546,'BM MORRO DA CRUZ'!$K25),0) -> 0 | AS25: =ROUND(AR25*$P25,2) -> 0 | AT25: =IFERROR(SUMIFS('BM MORRO DA CRUZ - VERTICAL'!AX$6:AX$546,'BM MORRO DA CRUZ - VERTICAL'!$O$6:$O$546,'BM MORRO DA CRUZ'!$K25),0) -> 0 | AU25: =ROUND(AT25*$P25,2) -> 0 | AV25: =IFERROR(SUMIFS('BM MORRO DA CRUZ - VERTICAL'!AZ$6:AZ$546,'BM MORRO DA CRUZ - VERTICAL'!$O$6:$O$546,'BM MORRO DA CRUZ'!$K25),0) -> 0 | AW25: =ROUND(AV25*$P25,2) -> 0 | AX25: =IFERROR(SUMIFS('BM MORRO DA CRUZ - VERTICAL'!BB$6:BB$546,'BM MORRO DA CRUZ - VERTICAL'!$O$6:$O$546,'BM MORRO DA CRUZ'!$K25),0) -> 0 | AY25: =ROUND(AX25*$P25,2) -> 0 | AZ25: =IFERROR(SUMIFS('BM MORRO DA CRUZ - VERTICAL'!BD$6:BD$546,'BM MORRO DA CRUZ - VERTICAL'!$O$6:$O$546,'BM MORRO DA CRUZ'!$K25),0) -> 0 | BA25: =ROUND(AZ25*$P25,2) -> 0 | BB25: =IFERROR(SUMIFS($R25:$BA25,$R$5:$BA$5,$BB$5),0) -> 0 | BC25: =SUMIFS($R25:$BA25,$R$5:$BA$5,$S$5) -> 0 | BD25: =IFERROR(BB25/O25,0) -> 0 | BE25: =IFERROR((O25-BB25)/O25,0) -> 1
A26: 1.10 | K26: 15110 | M26: REGISTROS, VÁLVULAS E ACESSÓRIOS | Q26: =SUM(Q27:Q44) -> 446602.52 | S26: =SUM(S27:S44) -> 0 | U26: =SUM(U27:U44) -> 0 | W26: =SUM(W27:W44) -> 0 | Y26: =SUM(Y27:Y44) -> 0 | AA26: =SUM(AA27:AA44) -> 0 | AC26: =SUM(AC27:AC44) -> 0 | AE26: =SUM(AE27:AE44) -> 0 | AG26: =SUM(AG27:AG44) -> 0 | AI26: =SUM(AI27:AI44) -> 0 | AK26: =SUM(AK27:AK44) -> 0 | AM26: =SUM(AM27:AM44) -> 0 | AO26: =SUM(AO27:AO44) -> 0 | AQ26: =SUM(AQ27:AQ44) -> 0 | AS26: =SUM(AS27:AS44) -> 0 | AU26: =SUM(AU27:AU44) -> 0 | AW26: =SUM(AW27:AW44) -> 0 | AY26: =SUM(AY27:AY44) -> 0 | BA26: =SUM(BA27:BA44) -> 0 | BC26: =SUM(BC27:BC44) -> 0
A27: 1.10.1 | B27: TAMPA P/ ACIONAMENTO DE REGISTRO | C27: N/A | D27: N/A | E27: TAMPA ACIONAMENTO | F27: N/A | G27: 100 | H27: FºFº | I27: HIDROMECÂNICO | J27: TAMPÃO | K27: 1511003106005 | L27: MATERIAL | M27: TAMPA PARA ACIONAMENTO DE REGISTRO DE FERRO FUNDIDO (DIÂMETRO: 100 MM) | N27: UN | O27: 6 | P27: 189.06 | Q27: =ROUND(P27*$O27,2) -> 1134.36 | R27: =IFERROR(SUMIFS('BM MORRO DA CRUZ - VERTICAL'!V$6:V$546,'BM MORRO DA CRUZ - VERTICAL'!$O$6:$O$546,'BM MORRO DA CRUZ'!$K27),0) -> 0 | S27: =ROUND(R27*$P27,2) -> 0 | T27: =IFERROR(SUMIFS('BM MORRO DA CRUZ - VERTICAL'!X$6:X$546,'BM MORRO DA CRUZ - VERTICAL'!$O$6:$O$546,'BM MORRO DA CRUZ'!$K27),0) -> 0 | U27: =ROUND(T27*$P27,2) -> 0 | V27: =IFERROR(SUMIFS('BM MORRO DA CRUZ - VERTICAL'!Z$6:Z$546,'BM MORRO DA CRUZ - VERTICAL'!$O$6:$O$546,'BM MORRO DA CRUZ'!$K27),0) -> 0 | W27: =ROUND(V27*$P27,2) -> 0 | X27: =IFERROR(SUMIFS('BM MORRO DA CRUZ - VERTICAL'!AB$6:AB$546,'BM MORRO DA CRUZ - VERTICAL'!$O$6:$O$546,'BM MORRO DA CRUZ'!$K27),0) -> 0 | Y27: =ROUND(X27*$P27,2) -> 0 | Z27: =IFERROR(SUMIFS('BM MORRO DA CRUZ - VERTICAL'!AD$6:AD$546,'BM MORRO DA CRUZ - VERTICAL'!$O$6:$O$546,'BM MORRO DA CRUZ'!$K27),0) -> 0 | AA27: =ROUND(Z27*$P27,2) -> 0 | AB27: =IFERROR(SUMIFS('BM MORRO DA CRUZ - VERTICAL'!AF$6:AF$546,'BM MORRO DA CRUZ - VERTICAL'!$O$6:$O$546,'BM MORRO DA CRUZ'!$K27),0) -> 0 | AC27: =ROUND(AB27*$P27,2) -> 0 | AD27: =IFERROR(SUMIFS('BM MORRO DA CRUZ - VERTICAL'!AH$6:AH$546,'BM MORRO DA CRUZ - VERTICAL'!$O$6:$O$546,'BM MORRO DA CRUZ'!$K27),0) -> 0 | AE27: =ROUND(AD27*$P27,2) -> 0 | AF27: =IFERROR(SUMIFS('BM MORRO DA CRUZ - VERTICAL'!AJ$6:AJ$546,'BM MORRO DA CRUZ - VERTICAL'!$O$6:$O$546,'BM MORRO DA CRUZ'!$K27),0) -> 0 | AG27: =ROUND(AF27*$P27,2) -> 0 | AH27: =IFERROR(SUMIFS('BM MORRO DA CRUZ - VERTICAL'!AL$6:AL$546,'BM MORRO DA CRUZ - VERTICAL'!$O$6:$O$546,'BM MORRO DA CRUZ'!$K27),0) -> 0 | AI27: =ROUND(AH27*$P27,2) -> 0 | AJ27: =IFERROR(SUMIFS('BM MORRO DA CRUZ - VERTICAL'!AN$6:AN$546,'BM MORRO DA CRUZ - VERTICAL'!$O$6:$O$546,'BM MORRO DA CRUZ'!$K27),0) -> 0 | AK27: =ROUND(AJ27*$P27,2) -> 0 | AL27: =IFERROR(SUMIFS('BM MORRO DA CRUZ - VERTICAL'!AP$6:AP$546,'BM MORRO DA CRUZ - VERTICAL'!$O$6:$O$546,'BM MORRO DA CRUZ'!$K27),0) -> 0 | AM27: =ROUND(AL27*$P27,2) -> 0 | AN27: =IFERROR(SUMIFS('BM MORRO DA CRUZ - VERTICAL'!AR$6:AR$546,'BM MORRO DA CRUZ - VERTICAL'!$O$6:$O$546,'BM MORRO DA CRUZ'!$K27),0) -> 0 | AO27: =ROUND(AN27*$P27,2) -> 0 | AP27: =IFERROR(SUMIFS('BM MORRO DA CRUZ - VERTICAL'!AT$6:AT$546,'BM MORRO DA CRUZ - VERTICAL'!$O$6:$O$546,'BM MORRO DA CRUZ'!$K27),0) -> 0 | AQ27: =ROUND(AP27*$P27,2) -> 0 | AR27: =IFERROR(SUMIFS('BM MORRO DA CRUZ - VERTICAL'!AV$6:AV$546,'BM MORRO DA CRUZ - VERTICAL'!$O$6:$O$546,'BM MORRO DA CRUZ'!$K27),0) -> 0 | AS27: =ROUND(AR27*$P27,2) -> 0 | AT27: =IFERROR(SUMIFS('BM MORRO DA CRUZ - VERTICAL'!AX$6:AX$546,'BM MORRO DA CRUZ - VERTICAL'!$O$6:$O$546,'BM MORRO DA CRUZ'!$K27),0) -> 0 | AU27: =ROUND(AT27*$P27,2) -> 0 | AV27: =IFERROR(SUMIFS('BM MORRO DA CRUZ - VERTICAL'!AZ$6:AZ$546,'BM MORRO DA CRUZ - VERTICAL'!$O$6:$O$546,'BM MORRO DA CRUZ'!$K27),0) -> 0 | AW27: =ROUND(AV27*$P27,2) -> 0 | AX27: =IFERROR(SUMIFS('BM MORRO DA CRUZ - VERTICAL'!BB$6:BB$546,'BM MORRO DA CRUZ - VERTICAL'!$O$6:$O$546,'BM MORRO DA CRUZ'!$K27),0) -> 0 | AY27: =ROUND(AX27*$P27,2) -> 0 | AZ27: =IFERROR(SUMIFS('BM MORRO DA CRUZ - VERTICAL'!BD$6:BD$546,'BM MORRO DA CRUZ - VERTICAL'!$O$6:$O$546,'BM MORRO DA CRUZ'!$K27),0) -> 0 | BA27: =ROUND(AZ27*$P27,2) -> 0 | BB27: =IFERROR(SUMIFS($R27:$BA27,$R$5:$BA$5,$BB$5),0) -> 0 | BC27: =SUMIFS($R27:$BA27,$R$5:$BA$5,$S$5) -> 0 | BD27: =IFERROR(BB27/O27,0) -> 0 | BE27: =IFERROR((O27-BB27)/O27,0) -> 1
A28: 1.10.2 | B28: VÁLVULA BORBOLETA FF CC - ACIONAMENTO CABEÇOTE | C28: PN10 | D28: N/A | E28: VÁLVULA BORBOLETA | F28: N/A | G28: 200 | H28: FºFº | I28: HIDROMECÂNICO | J28: VÁLVULA | K28: 1511003139041 | L28: MATERIAL | M28: VÁLVULA BORBOLETA FLANGEADA DE FERRO FUNDIDO DÚCTIL COM CORPO CURTO, MECANISMO DE REDUÇÃO TIPO C E ACIONAMENTO COM CABEÇOTE (CLASSE DE PRESSÃO: 10 KGF/CM² / DIÂMETRO DA SEÇÃO: 200 MM) | N28: UN | O28: 4 | P28: 17589.88 | Q28: =ROUND(P28*$O28,2) -> 70359.52 | R28: =IFERROR(SUMIFS('BM MORRO DA CRUZ - VERTICAL'!V$6:V$546,'BM MORRO DA CRUZ - VERTICAL'!$O$6:$O$546,'BM MORRO DA CRUZ'!$K28),0) -> 0 | S28: =ROUND(R28*$P28,2) -> 0 | T28: =IFERROR(SUMIFS('BM MORRO DA CRUZ - VERTICAL'!X$6:X$546,'BM MORRO DA CRUZ - VERTICAL'!$O$6:$O$546,'BM MORRO DA CRUZ'!$K28),0) -> 0 | U28: =ROUND(T28*$P28,2) -> 0 | V28: =IFERROR(SUMIFS('BM MORRO DA CRUZ - VERTICAL'!Z$6:Z$546,'BM MORRO DA CRUZ - VERTICAL'!$O$6:$O$546,'BM MORRO DA CRUZ'!$K28),0) -> 0 | W28: =ROUND(V28*$P28,2) -> 0 | X28: =IFERROR(SUMIFS('BM MORRO DA CRUZ - VERTICAL'!AB$6:AB$546,'BM MORRO DA CRUZ - VERTICAL'!$O$6:$O$546,'BM MORRO DA CRUZ'!$K28),0) -> 0 | Y28: =ROUND(X28*$P28,2) -> 0 | Z28: =IFERROR(SUMIFS('BM MORRO DA CRUZ - VERTICAL'!AD$6:AD$546,'BM MORRO DA CRUZ - VERTICAL'!$O$6:$O$546,'BM MORRO DA CRUZ'!$K28),0) -> 0 | AA28: =ROUND(Z28*$P28,2) -> 0 | AB28: =IFERROR(SUMIFS('BM MORRO DA CRUZ - VERTICAL'!AF$6:AF$546,'BM MORRO DA CRUZ - VERTICAL'!$O$6:$O$546,'BM MORRO DA CRUZ'!$K28),0) -> 0 | AC28: =ROUND(AB28*$P28,2) -> 0 | AD28: =IFERROR(SUMIFS('BM MORRO DA CRUZ - VERTICAL'!AH$6:AH$546,'BM MORRO DA CRUZ - VERTICAL'!$O$6:$O$546,'BM MORRO DA CRUZ'!$K28),0) -> 0 | AE28: =ROUND(AD28*$P28,2) -> 0 | AF28: =IFERROR(SUMIFS('BM MORRO DA CRUZ - VERTICAL'!AJ$6:AJ$546,'BM MORRO DA CRUZ - VERTICAL'!$O$6:$O$546,'BM MORRO DA CRUZ'!$K28),0) -> 0 | AG28: =ROUND(AF28*$P28,2) -> 0 | AH28: =IFERROR(SUMIFS('BM MORRO DA CRUZ - VERTICAL'!AL$6:AL$546,'BM MORRO DA CRUZ - VERTICAL'!$O$6:$O$546,'BM MORRO DA CRUZ'!$K28),0) -> 0 | AI28: =ROUND(AH28*$P28,2) -> 0 | AJ28: =IFERROR(SUMIFS('BM MORRO DA CRUZ - VERTICAL'!AN$6:AN$546,'BM MORRO DA CRUZ - VERTICAL'!$O$6:$O$546,'BM MORRO DA CRUZ'!$K28),0) -> 0 | AK28: =ROUND(AJ28*$P28,2) -> 0 | AL28: =IFERROR(SUMIFS('BM MORRO DA CRUZ - VERTICAL'!AP$6:AP$546,'BM MORRO DA CRUZ - VERTICAL'!$O$6:$O$546,'BM MORRO DA CRUZ'!$K28),0) -> 0 | AM28: =ROUND(AL28*$P28,2) -> 0 | AN28: =IFERROR(SUMIFS('BM MORRO DA CRUZ - VERTICAL'!AR$6:AR$546,'BM MORRO DA CRUZ - VERTICAL'!$O$6:$O$546,'BM MORRO DA CRUZ'!$K28),0) -> 0 | AO28: =ROUND(AN28*$P28,2) -> 0 | AP28: =IFERROR(SUMIFS('BM MORRO DA CRUZ - VERTICAL'!AT$6:AT$546,'BM MORRO DA CRUZ - VERTICAL'!$O$6:$O$546,'BM MORRO DA CRUZ'!$K28),0) -> 0 | AQ28: =ROUND(AP28*$P28,2) -> 0 | AR28: =IFERROR(SUMIFS('BM MORRO DA CRUZ - VERTICAL'!AV$6:AV$546,'BM MORRO DA CRUZ - VERTICAL'!$O$6:$O$546,'BM MORRO DA CRUZ'!$K28),0) -> 0 | AS28: =ROUND(AR28*$P28,2) -> 0 | AT28: =IFERROR(SUMIFS('BM MORRO DA CRUZ - VERTICAL'!AX$6:AX$546,'BM MORRO DA CRUZ - VERTICAL'!$O$6:$O$546,'BM MORRO DA CRUZ'!$K28),0) -> 0 | AU28: =ROUND(AT28*$P28,2) -> 0 | AV28: =IFERROR(SUMIFS('BM MORRO DA CRUZ - VERTICAL'!AZ$6:AZ$546,'BM MORRO DA CRUZ - VERTICAL'!$O$6:$O$546,'BM MORRO DA CRUZ'!$K28),0) -> 0 | AW28: =ROUND(AV28*$P28,2) -> 0 | AX28: =IFERROR(SUMIFS('BM MORRO DA CRUZ - VERTICAL'!BB$6:BB$546,'BM MORRO DA CRUZ - VERTICAL'!$O$6:$O$546,'BM MORRO DA CRUZ'!$K28),0) -> 0 | AY28: =ROUND(AX28*$P28,2) -> 0 | AZ28: =IFERROR(SUMIFS('BM MORRO DA CRUZ - VERTICAL'!BD$6:BD$546,'BM MORRO DA CRUZ - VERTICAL'!$O$6:$O$546,'BM MORRO DA CRUZ'!$K28),0) -> 0 | BA28: =ROUND(AZ28*$P28,2) -> 0 | BB28: =IFERROR(SUMIFS($R28:$BA28,$R$5:$BA$5,$BB$5),0) -> 0 | BC28: =SUMIFS($R28:$BA28,$R$5:$BA$5,$S$5) -> 0 | BD28: =IFERROR(BB28/O28,0) -> 0 | BE28: =IFERROR((O28-BB28)/O28,0) -> 1
